W0719 00:20:03.065000 56508 /system/conda/miniconda3/envs/cloudspace/lib/python3.10/site-packages/torch/_inductor/utils.py:1250] [0/0] Not enough SMs to use max_autotune_gemm mode
step 0: train loss 10.8462, val loss 10.8439
iter 0: loss 10.8460, time 38286.75ms, mfu -100.00%
iter 10: loss 10.7765, time 1615.84ms, mfu 13.52%
iter 20: loss 10.6538, time 1637.60ms, mfu 13.50%
iter 30: loss 10.5574, time 1654.06ms, mfu 13.47%
iter 40: loss 10.5056, time 1632.99ms, mfu 13.46%
step 50: train loss 10.4317, val loss 10.4440
saving checkpoint to out
iter 50: loss 10.4405, time 2240.54ms, mfu 13.09%
Traceback (most recent call last):
  File "/teamspace/studios/this_studio/nanoGPT/train.py", line 344, in <module>
    scaler.scale(loss).backward()
  File "/home/zeus/miniconda3/envs/cloudspace/lib/python3.10/site-packages/torch/_tensor.py", line 648, in backward
    torch.autograd.backward(
  File "/home/zeus/miniconda3/envs/cloudspace/lib/python3.10/site-packages/torch/autograd/__init__.py", line 353, in backward
    _engine_run_backward(
  File "/home/zeus/miniconda3/envs/cloudspace/lib/python3.10/site-packages/torch/autograd/graph.py", line 824, in _engine_run_backward
    return Variable._execution_engine.run_backward(  # Calls into the C++ engine to run the backward pass
KeyboardInterrupt
Traceback (most recent call last):
  File "/teamspace/studios/this_studio/nanoGPT/train.py", line 344, in <module>
    scaler.scale(loss).backward()
  File "/home/zeus/miniconda3/envs/cloudspace/lib/python3.10/site-packages/torch/_tensor.py", line 648, in backward
    torch.autograd.backward(
  File "/home/zeus/miniconda3/envs/cloudspace/lib/python3.10/site-packages/torch/autograd/__init__.py", line 353, in backward
    _engine_run_backward(
  File "/home/zeus/miniconda3/envs/cloudspace/lib/python3.10/site-packages/torch/autograd/graph.py", line 824, in _engine_run_backward
    return Variable._execution_engine.run_backward(  # Calls into the C++ engine to run the backward pass
KeyboardInterrupt
Exception ignored in atexit callback: <function _start_and_connect_service.<locals>.teardown_atexit at 0x70d8ac7ffac0>
Traceback (most recent call last):
  File "/home/zeus/miniconda3/envs/cloudspace/lib/python3.10/site-packages/wandb/sdk/lib/service/service_connection.py", line 54, in teardown_atexit
    conn.teardown(hooks.exit_code)
  File "/home/zeus/miniconda3/envs/cloudspace/lib/python3.10/site-packages/wandb/sdk/lib/service/service_connection.py", line 182, in teardown
    self._router.join()
  File "/home/zeus/miniconda3/envs/cloudspace/lib/python3.10/site-packages/wandb/sdk/interface/router.py", line 75, in join
    self._thread.join()
  File "/home/zeus/miniconda3/envs/cloudspace/lib/python3.10/threading.py", line 1096, in join
    self._wait_for_tstate_lock()
  File "/home/zeus/miniconda3/envs/cloudspace/lib/python3.10/threading.py", line 1116, in _wait_for_tstate_lock
    if lock.acquire(block, timeout):
KeyboardInterrupt:
Exception ignored in atexit callback: <function shutdown_compile_workers at 0x70d8c2c76170>
Traceback (most recent call last):
  File "/home/zeus/miniconda3/envs/cloudspace/lib/python3.10/site-packages/torch/_inductor/async_compile.py", line 113, in shutdown_compile_workers
    pool.shutdown()
  File "/home/zeus/miniconda3/envs/cloudspace/lib/python3.10/site-packages/torch/_inductor/compile_worker/subproc_pool.py", line 239, in shutdown
    self.process.wait(300)
  File "/home/zeus/miniconda3/envs/cloudspace/lib/python3.10/subprocess.py", line 1209, in wait
    return self._wait(timeout=timeout)
  File "/home/zeus/miniconda3/envs/cloudspace/lib/python3.10/subprocess.py", line 1937, in _wait
    time.sleep(delay)
KeyboardInterrupt:
