2025-07-19 00:00:58,789 INFO    MainThread:37156 [wandb_setup.py:_flush():80] Current SDK version is 0.21.0
2025-07-19 00:00:58,789 INFO    MainThread:37156 [wandb_setup.py:_flush():80] Configure stats pid to 37156
2025-07-19 00:00:58,789 INFO    MainThread:37156 [wandb_setup.py:_flush():80] Loading settings from /teamspace/studios/this_studio/.config/wandb/settings
2025-07-19 00:00:58,790 INFO    MainThread:37156 [wandb_setup.py:_flush():80] Loading settings from /teamspace/studios/this_studio/nanoGPT/wandb/settings
2025-07-19 00:00:58,790 INFO    MainThread:37156 [wandb_setup.py:_flush():80] Loading settings from environment variables
2025-07-19 00:00:58,790 INFO    MainThread:37156 [wandb_init.py:setup_run_log_directory():703] Logging user logs to /teamspace/studios/this_studio/nanoGPT/wandb/run-20250719_000058-xtsstgrc/logs/debug.log
2025-07-19 00:00:58,790 INFO    MainThread:37156 [wandb_init.py:setup_run_log_directory():704] Logging internal logs to /teamspace/studios/this_studio/nanoGPT/wandb/run-20250719_000058-xtsstgrc/logs/debug-internal.log
2025-07-19 00:00:58,790 INFO    MainThread:37156 [wandb_init.py:init():830] calling init triggers
2025-07-19 00:00:58,790 INFO    MainThread:37156 [wandb_init.py:init():835] wandb.init called with sweep_config: {}
config: {'out_dir': 'out', 'eval_interval': 50, 'log_interval': 10, 'eval_iters': 1, 'eval_only': False, 'always_save_checkpoint': True, 'init_from': 'scratch', 'log_dir': 'logs', 'file_logging': True, 'wandb_log': True, 'wandb_project': 'owt', 'wandb_run_name': 'gpt2-124M', 'dataset': 'fineweb10B', 'gradient_accumulation_steps': 5, 'batch_size': 12, 'block_size': 1024, 'n_layer': 12, 'n_head': 12, 'n_embd': 192, 'dropout': 0.0, 'bias': False, 'use_rotary_embeddings': True, 'rotary_base': 10000.0, 'rotary_max_position_embeddings': 2048, 'learning_rate': 0.0006, 'max_iters': 600000, 'weight_decay': 0.1, 'beta1': 0.9, 'beta2': 0.95, 'grad_clip': 1.0, 'decay_lr': True, 'warmup_iters': 2000, 'lr_decay_iters': 600000, 'min_lr': 6e-05, 'backend': 'nccl', 'device': 'cuda', 'dtype': 'bfloat16', 'compile': True, '_wandb': {}}
2025-07-19 00:00:58,790 INFO    MainThread:37156 [wandb_init.py:init():871] starting backend
2025-07-19 00:00:58,998 INFO    MainThread:37156 [wandb_init.py:init():874] sending inform_init request
2025-07-19 00:00:59,003 INFO    MainThread:37156 [wandb_init.py:init():882] backend started and connected
2025-07-19 00:00:59,005 INFO    MainThread:37156 [wandb_init.py:init():953] updated telemetry
2025-07-19 00:00:59,016 INFO    MainThread:37156 [wandb_init.py:init():977] communicating run to backend with 90.0 second timeout
2025-07-19 00:00:59,331 INFO    MainThread:37156 [wandb_init.py:init():1029] starting run threads in backend
2025-07-19 00:00:59,550 INFO    MainThread:37156 [wandb_run.py:_console_start():2458] atexit reg
2025-07-19 00:00:59,550 INFO    MainThread:37156 [wandb_run.py:_redirect():2306] redirect: wrap_raw
2025-07-19 00:00:59,550 INFO    MainThread:37156 [wandb_run.py:_redirect():2375] Wrapping output streams.
2025-07-19 00:00:59,550 INFO    MainThread:37156 [wandb_run.py:_redirect():2398] Redirects installed.
2025-07-19 00:00:59,553 INFO    MainThread:37156 [wandb_init.py:init():1075] run started, returning control to user process
2025-07-19 00:18:55,609 INFO    MsgRouterThr:37156 [mailbox.py:close():129] [no run ID] Closing mailbox, abandoning 1 handles.
2025-07-19 00:18:55,940 ERROR   MainThread:37156 [redirect.py:_on_write():664] [all runs] error in stderr callback
Traceback (most recent call last):
  File "/home/zeus/miniconda3/envs/cloudspace/lib/python3.10/site-packages/wandb/sdk/lib/redirect.py", line 662, in _on_write
    cb(written_data)
  File "/home/zeus/miniconda3/envs/cloudspace/lib/python3.10/site-packages/wandb/sdk/wandb_run.py", line 2385, in <lambda>
    lambda data: self._console_raw_callback("stderr", data),
  File "/home/zeus/miniconda3/envs/cloudspace/lib/python3.10/site-packages/wandb/sdk/wandb_run.py", line 398, in wrapper
    return func(self, *args, **kwargs)
  File "/home/zeus/miniconda3/envs/cloudspace/lib/python3.10/site-packages/wandb/sdk/wandb_run.py", line 456, in wrapper_fn
    return func(self, *args, **kwargs)
  File "/home/zeus/miniconda3/envs/cloudspace/lib/python3.10/site-packages/wandb/sdk/wandb_run.py", line 1566, in _console_raw_callback
    self._backend.interface.publish_output_raw(name, data)
  File "/home/zeus/miniconda3/envs/cloudspace/lib/python3.10/site-packages/wandb/sdk/interface/interface.py", line 771, in publish_output_raw
    self._publish_output_raw(o)
  File "/home/zeus/miniconda3/envs/cloudspace/lib/python3.10/site-packages/wandb/sdk/interface/interface_shared.py", line 38, in _publish_output_raw
    self._publish(rec)
  File "/home/zeus/miniconda3/envs/cloudspace/lib/python3.10/site-packages/wandb/sdk/interface/interface_sock.py", line 39, in _publish
    self._sock_client.send_record_publish(record)
  File "/home/zeus/miniconda3/envs/cloudspace/lib/python3.10/site-packages/wandb/sdk/lib/sock_client.py", line 170, in send_record_publish
    self.send_server_request(server_req)
  File "/home/zeus/miniconda3/envs/cloudspace/lib/python3.10/site-packages/wandb/sdk/lib/sock_client.py", line 150, in send_server_request
    self._send_message(msg)
  File "/home/zeus/miniconda3/envs/cloudspace/lib/python3.10/site-packages/wandb/sdk/lib/sock_client.py", line 147, in _send_message
    self._sendall_with_error_handle(header + data)
  File "/home/zeus/miniconda3/envs/cloudspace/lib/python3.10/site-packages/wandb/sdk/lib/sock_client.py", line 126, in _sendall_with_error_handle
    sent = self._sock.send(data)
BrokenPipeError: [Errno 32] Broken pipe
2025-07-19 00:18:55,944 ERROR   MainThread:37156 [redirect.py:_on_write():664] [all runs] error in stderr callback
Traceback (most recent call last):
  File "/home/zeus/miniconda3/envs/cloudspace/lib/python3.10/site-packages/wandb/sdk/lib/redirect.py", line 662, in _on_write
    cb(written_data)
  File "/home/zeus/miniconda3/envs/cloudspace/lib/python3.10/site-packages/wandb/sdk/wandb_run.py", line 2385, in <lambda>
    lambda data: self._console_raw_callback("stderr", data),
  File "/home/zeus/miniconda3/envs/cloudspace/lib/python3.10/site-packages/wandb/sdk/wandb_run.py", line 398, in wrapper
    return func(self, *args, **kwargs)
  File "/home/zeus/miniconda3/envs/cloudspace/lib/python3.10/site-packages/wandb/sdk/wandb_run.py", line 456, in wrapper_fn
    return func(self, *args, **kwargs)
  File "/home/zeus/miniconda3/envs/cloudspace/lib/python3.10/site-packages/wandb/sdk/wandb_run.py", line 1566, in _console_raw_callback
    self._backend.interface.publish_output_raw(name, data)
  File "/home/zeus/miniconda3/envs/cloudspace/lib/python3.10/site-packages/wandb/sdk/interface/interface.py", line 771, in publish_output_raw
    self._publish_output_raw(o)
  File "/home/zeus/miniconda3/envs/cloudspace/lib/python3.10/site-packages/wandb/sdk/interface/interface_shared.py", line 38, in _publish_output_raw
    self._publish(rec)
  File "/home/zeus/miniconda3/envs/cloudspace/lib/python3.10/site-packages/wandb/sdk/interface/interface_sock.py", line 39, in _publish
    self._sock_client.send_record_publish(record)
  File "/home/zeus/miniconda3/envs/cloudspace/lib/python3.10/site-packages/wandb/sdk/lib/sock_client.py", line 170, in send_record_publish
    self.send_server_request(server_req)
  File "/home/zeus/miniconda3/envs/cloudspace/lib/python3.10/site-packages/wandb/sdk/lib/sock_client.py", line 150, in send_server_request
    self._send_message(msg)
  File "/home/zeus/miniconda3/envs/cloudspace/lib/python3.10/site-packages/wandb/sdk/lib/sock_client.py", line 147, in _send_message
    self._sendall_with_error_handle(header + data)
  File "/home/zeus/miniconda3/envs/cloudspace/lib/python3.10/site-packages/wandb/sdk/lib/sock_client.py", line 126, in _sendall_with_error_handle
    sent = self._sock.send(data)
BrokenPipeError: [Errno 32] Broken pipe
2025-07-19 00:18:55,945 ERROR   MainThread:37156 [redirect.py:_on_write():664] [all runs] error in stderr callback
Traceback (most recent call last):
  File "/home/zeus/miniconda3/envs/cloudspace/lib/python3.10/site-packages/wandb/sdk/lib/redirect.py", line 662, in _on_write
    cb(written_data)
  File "/home/zeus/miniconda3/envs/cloudspace/lib/python3.10/site-packages/wandb/sdk/wandb_run.py", line 2385, in <lambda>
    lambda data: self._console_raw_callback("stderr", data),
  File "/home/zeus/miniconda3/envs/cloudspace/lib/python3.10/site-packages/wandb/sdk/wandb_run.py", line 398, in wrapper
    return func(self, *args, **kwargs)
  File "/home/zeus/miniconda3/envs/cloudspace/lib/python3.10/site-packages/wandb/sdk/wandb_run.py", line 456, in wrapper_fn
    return func(self, *args, **kwargs)
  File "/home/zeus/miniconda3/envs/cloudspace/lib/python3.10/site-packages/wandb/sdk/wandb_run.py", line 1566, in _console_raw_callback
    self._backend.interface.publish_output_raw(name, data)
  File "/home/zeus/miniconda3/envs/cloudspace/lib/python3.10/site-packages/wandb/sdk/interface/interface.py", line 771, in publish_output_raw
    self._publish_output_raw(o)
  File "/home/zeus/miniconda3/envs/cloudspace/lib/python3.10/site-packages/wandb/sdk/interface/interface_shared.py", line 38, in _publish_output_raw
    self._publish(rec)
  File "/home/zeus/miniconda3/envs/cloudspace/lib/python3.10/site-packages/wandb/sdk/interface/interface_sock.py", line 39, in _publish
    self._sock_client.send_record_publish(record)
  File "/home/zeus/miniconda3/envs/cloudspace/lib/python3.10/site-packages/wandb/sdk/lib/sock_client.py", line 170, in send_record_publish
    self.send_server_request(server_req)
  File "/home/zeus/miniconda3/envs/cloudspace/lib/python3.10/site-packages/wandb/sdk/lib/sock_client.py", line 150, in send_server_request
    self._send_message(msg)
  File "/home/zeus/miniconda3/envs/cloudspace/lib/python3.10/site-packages/wandb/sdk/lib/sock_client.py", line 147, in _send_message
    self._sendall_with_error_handle(header + data)
  File "/home/zeus/miniconda3/envs/cloudspace/lib/python3.10/site-packages/wandb/sdk/lib/sock_client.py", line 126, in _sendall_with_error_handle
    sent = self._sock.send(data)
BrokenPipeError: [Errno 32] Broken pipe
2025-07-19 00:18:55,945 ERROR   MainThread:37156 [redirect.py:_on_write():664] [all runs] error in stderr callback
Traceback (most recent call last):
  File "/home/zeus/miniconda3/envs/cloudspace/lib/python3.10/site-packages/wandb/sdk/lib/redirect.py", line 662, in _on_write
    cb(written_data)
  File "/home/zeus/miniconda3/envs/cloudspace/lib/python3.10/site-packages/wandb/sdk/wandb_run.py", line 2385, in <lambda>
    lambda data: self._console_raw_callback("stderr", data),
  File "/home/zeus/miniconda3/envs/cloudspace/lib/python3.10/site-packages/wandb/sdk/wandb_run.py", line 398, in wrapper
    return func(self, *args, **kwargs)
  File "/home/zeus/miniconda3/envs/cloudspace/lib/python3.10/site-packages/wandb/sdk/wandb_run.py", line 456, in wrapper_fn
    return func(self, *args, **kwargs)
  File "/home/zeus/miniconda3/envs/cloudspace/lib/python3.10/site-packages/wandb/sdk/wandb_run.py", line 1566, in _console_raw_callback
    self._backend.interface.publish_output_raw(name, data)
  File "/home/zeus/miniconda3/envs/cloudspace/lib/python3.10/site-packages/wandb/sdk/interface/interface.py", line 771, in publish_output_raw
    self._publish_output_raw(o)
  File "/home/zeus/miniconda3/envs/cloudspace/lib/python3.10/site-packages/wandb/sdk/interface/interface_shared.py", line 38, in _publish_output_raw
    self._publish(rec)
  File "/home/zeus/miniconda3/envs/cloudspace/lib/python3.10/site-packages/wandb/sdk/interface/interface_sock.py", line 39, in _publish
    self._sock_client.send_record_publish(record)
  File "/home/zeus/miniconda3/envs/cloudspace/lib/python3.10/site-packages/wandb/sdk/lib/sock_client.py", line 170, in send_record_publish
    self.send_server_request(server_req)
  File "/home/zeus/miniconda3/envs/cloudspace/lib/python3.10/site-packages/wandb/sdk/lib/sock_client.py", line 150, in send_server_request
    self._send_message(msg)
  File "/home/zeus/miniconda3/envs/cloudspace/lib/python3.10/site-packages/wandb/sdk/lib/sock_client.py", line 147, in _send_message
    self._sendall_with_error_handle(header + data)
  File "/home/zeus/miniconda3/envs/cloudspace/lib/python3.10/site-packages/wandb/sdk/lib/sock_client.py", line 126, in _sendall_with_error_handle
    sent = self._sock.send(data)
BrokenPipeError: [Errno 32] Broken pipe
2025-07-19 00:18:55,945 ERROR   MainThread:37156 [redirect.py:_on_write():664] [all runs] error in stderr callback
Traceback (most recent call last):
  File "/home/zeus/miniconda3/envs/cloudspace/lib/python3.10/site-packages/wandb/sdk/lib/redirect.py", line 662, in _on_write
    cb(written_data)
  File "/home/zeus/miniconda3/envs/cloudspace/lib/python3.10/site-packages/wandb/sdk/wandb_run.py", line 2385, in <lambda>
    lambda data: self._console_raw_callback("stderr", data),
  File "/home/zeus/miniconda3/envs/cloudspace/lib/python3.10/site-packages/wandb/sdk/wandb_run.py", line 398, in wrapper
    return func(self, *args, **kwargs)
  File "/home/zeus/miniconda3/envs/cloudspace/lib/python3.10/site-packages/wandb/sdk/wandb_run.py", line 456, in wrapper_fn
    return func(self, *args, **kwargs)
  File "/home/zeus/miniconda3/envs/cloudspace/lib/python3.10/site-packages/wandb/sdk/wandb_run.py", line 1566, in _console_raw_callback
    self._backend.interface.publish_output_raw(name, data)
  File "/home/zeus/miniconda3/envs/cloudspace/lib/python3.10/site-packages/wandb/sdk/interface/interface.py", line 771, in publish_output_raw
    self._publish_output_raw(o)
  File "/home/zeus/miniconda3/envs/cloudspace/lib/python3.10/site-packages/wandb/sdk/interface/interface_shared.py", line 38, in _publish_output_raw
    self._publish(rec)
  File "/home/zeus/miniconda3/envs/cloudspace/lib/python3.10/site-packages/wandb/sdk/interface/interface_sock.py", line 39, in _publish
    self._sock_client.send_record_publish(record)
  File "/home/zeus/miniconda3/envs/cloudspace/lib/python3.10/site-packages/wandb/sdk/lib/sock_client.py", line 170, in send_record_publish
    self.send_server_request(server_req)
  File "/home/zeus/miniconda3/envs/cloudspace/lib/python3.10/site-packages/wandb/sdk/lib/sock_client.py", line 150, in send_server_request
    self._send_message(msg)
  File "/home/zeus/miniconda3/envs/cloudspace/lib/python3.10/site-packages/wandb/sdk/lib/sock_client.py", line 147, in _send_message
    self._sendall_with_error_handle(header + data)
  File "/home/zeus/miniconda3/envs/cloudspace/lib/python3.10/site-packages/wandb/sdk/lib/sock_client.py", line 126, in _sendall_with_error_handle
    sent = self._sock.send(data)
BrokenPipeError: [Errno 32] Broken pipe
2025-07-19 00:18:55,946 ERROR   MainThread:37156 [redirect.py:_on_write():664] [all runs] error in stderr callback
Traceback (most recent call last):
  File "/home/zeus/miniconda3/envs/cloudspace/lib/python3.10/site-packages/wandb/sdk/lib/redirect.py", line 662, in _on_write
    cb(written_data)
  File "/home/zeus/miniconda3/envs/cloudspace/lib/python3.10/site-packages/wandb/sdk/wandb_run.py", line 2385, in <lambda>
    lambda data: self._console_raw_callback("stderr", data),
  File "/home/zeus/miniconda3/envs/cloudspace/lib/python3.10/site-packages/wandb/sdk/wandb_run.py", line 398, in wrapper
    return func(self, *args, **kwargs)
  File "/home/zeus/miniconda3/envs/cloudspace/lib/python3.10/site-packages/wandb/sdk/wandb_run.py", line 456, in wrapper_fn
    return func(self, *args, **kwargs)
  File "/home/zeus/miniconda3/envs/cloudspace/lib/python3.10/site-packages/wandb/sdk/wandb_run.py", line 1566, in _console_raw_callback
    self._backend.interface.publish_output_raw(name, data)
  File "/home/zeus/miniconda3/envs/cloudspace/lib/python3.10/site-packages/wandb/sdk/interface/interface.py", line 771, in publish_output_raw
    self._publish_output_raw(o)
  File "/home/zeus/miniconda3/envs/cloudspace/lib/python3.10/site-packages/wandb/sdk/interface/interface_shared.py", line 38, in _publish_output_raw
    self._publish(rec)
  File "/home/zeus/miniconda3/envs/cloudspace/lib/python3.10/site-packages/wandb/sdk/interface/interface_sock.py", line 39, in _publish
    self._sock_client.send_record_publish(record)
  File "/home/zeus/miniconda3/envs/cloudspace/lib/python3.10/site-packages/wandb/sdk/lib/sock_client.py", line 170, in send_record_publish
    self.send_server_request(server_req)
  File "/home/zeus/miniconda3/envs/cloudspace/lib/python3.10/site-packages/wandb/sdk/lib/sock_client.py", line 150, in send_server_request
    self._send_message(msg)
  File "/home/zeus/miniconda3/envs/cloudspace/lib/python3.10/site-packages/wandb/sdk/lib/sock_client.py", line 147, in _send_message
    self._sendall_with_error_handle(header + data)
  File "/home/zeus/miniconda3/envs/cloudspace/lib/python3.10/site-packages/wandb/sdk/lib/sock_client.py", line 126, in _sendall_with_error_handle
    sent = self._sock.send(data)
BrokenPipeError: [Errno 32] Broken pipe
2025-07-19 00:18:55,947 ERROR   MainThread:37156 [redirect.py:_on_write():664] [all runs] error in stderr callback
Traceback (most recent call last):
  File "/home/zeus/miniconda3/envs/cloudspace/lib/python3.10/site-packages/wandb/sdk/lib/redirect.py", line 662, in _on_write
    cb(written_data)
  File "/home/zeus/miniconda3/envs/cloudspace/lib/python3.10/site-packages/wandb/sdk/wandb_run.py", line 2385, in <lambda>
    lambda data: self._console_raw_callback("stderr", data),
  File "/home/zeus/miniconda3/envs/cloudspace/lib/python3.10/site-packages/wandb/sdk/wandb_run.py", line 398, in wrapper
    return func(self, *args, **kwargs)
  File "/home/zeus/miniconda3/envs/cloudspace/lib/python3.10/site-packages/wandb/sdk/wandb_run.py", line 456, in wrapper_fn
    return func(self, *args, **kwargs)
  File "/home/zeus/miniconda3/envs/cloudspace/lib/python3.10/site-packages/wandb/sdk/wandb_run.py", line 1566, in _console_raw_callback
    self._backend.interface.publish_output_raw(name, data)
  File "/home/zeus/miniconda3/envs/cloudspace/lib/python3.10/site-packages/wandb/sdk/interface/interface.py", line 771, in publish_output_raw
    self._publish_output_raw(o)
  File "/home/zeus/miniconda3/envs/cloudspace/lib/python3.10/site-packages/wandb/sdk/interface/interface_shared.py", line 38, in _publish_output_raw
    self._publish(rec)
  File "/home/zeus/miniconda3/envs/cloudspace/lib/python3.10/site-packages/wandb/sdk/interface/interface_sock.py", line 39, in _publish
    self._sock_client.send_record_publish(record)
  File "/home/zeus/miniconda3/envs/cloudspace/lib/python3.10/site-packages/wandb/sdk/lib/sock_client.py", line 170, in send_record_publish
    self.send_server_request(server_req)
  File "/home/zeus/miniconda3/envs/cloudspace/lib/python3.10/site-packages/wandb/sdk/lib/sock_client.py", line 150, in send_server_request
    self._send_message(msg)
  File "/home/zeus/miniconda3/envs/cloudspace/lib/python3.10/site-packages/wandb/sdk/lib/sock_client.py", line 147, in _send_message
    self._sendall_with_error_handle(header + data)
  File "/home/zeus/miniconda3/envs/cloudspace/lib/python3.10/site-packages/wandb/sdk/lib/sock_client.py", line 126, in _sendall_with_error_handle
    sent = self._sock.send(data)
BrokenPipeError: [Errno 32] Broken pipe
2025-07-19 00:18:55,947 ERROR   MainThread:37156 [redirect.py:_on_write():664] [all runs] error in stderr callback
Traceback (most recent call last):
  File "/home/zeus/miniconda3/envs/cloudspace/lib/python3.10/site-packages/wandb/sdk/lib/redirect.py", line 662, in _on_write
    cb(written_data)
  File "/home/zeus/miniconda3/envs/cloudspace/lib/python3.10/site-packages/wandb/sdk/wandb_run.py", line 2385, in <lambda>
    lambda data: self._console_raw_callback("stderr", data),
  File "/home/zeus/miniconda3/envs/cloudspace/lib/python3.10/site-packages/wandb/sdk/wandb_run.py", line 398, in wrapper
    return func(self, *args, **kwargs)
  File "/home/zeus/miniconda3/envs/cloudspace/lib/python3.10/site-packages/wandb/sdk/wandb_run.py", line 456, in wrapper_fn
    return func(self, *args, **kwargs)
  File "/home/zeus/miniconda3/envs/cloudspace/lib/python3.10/site-packages/wandb/sdk/wandb_run.py", line 1566, in _console_raw_callback
    self._backend.interface.publish_output_raw(name, data)
  File "/home/zeus/miniconda3/envs/cloudspace/lib/python3.10/site-packages/wandb/sdk/interface/interface.py", line 771, in publish_output_raw
    self._publish_output_raw(o)
  File "/home/zeus/miniconda3/envs/cloudspace/lib/python3.10/site-packages/wandb/sdk/interface/interface_shared.py", line 38, in _publish_output_raw
    self._publish(rec)
  File "/home/zeus/miniconda3/envs/cloudspace/lib/python3.10/site-packages/wandb/sdk/interface/interface_sock.py", line 39, in _publish
    self._sock_client.send_record_publish(record)
  File "/home/zeus/miniconda3/envs/cloudspace/lib/python3.10/site-packages/wandb/sdk/lib/sock_client.py", line 170, in send_record_publish
    self.send_server_request(server_req)
  File "/home/zeus/miniconda3/envs/cloudspace/lib/python3.10/site-packages/wandb/sdk/lib/sock_client.py", line 150, in send_server_request
    self._send_message(msg)
  File "/home/zeus/miniconda3/envs/cloudspace/lib/python3.10/site-packages/wandb/sdk/lib/sock_client.py", line 147, in _send_message
    self._sendall_with_error_handle(header + data)
  File "/home/zeus/miniconda3/envs/cloudspace/lib/python3.10/site-packages/wandb/sdk/lib/sock_client.py", line 126, in _sendall_with_error_handle
    sent = self._sock.send(data)
BrokenPipeError: [Errno 32] Broken pipe
2025-07-19 00:18:55,948 ERROR   MainThread:37156 [redirect.py:_on_write():664] [all runs] error in stderr callback
Traceback (most recent call last):
  File "/home/zeus/miniconda3/envs/cloudspace/lib/python3.10/site-packages/wandb/sdk/lib/redirect.py", line 662, in _on_write
    cb(written_data)
  File "/home/zeus/miniconda3/envs/cloudspace/lib/python3.10/site-packages/wandb/sdk/wandb_run.py", line 2385, in <lambda>
    lambda data: self._console_raw_callback("stderr", data),
  File "/home/zeus/miniconda3/envs/cloudspace/lib/python3.10/site-packages/wandb/sdk/wandb_run.py", line 398, in wrapper
    return func(self, *args, **kwargs)
  File "/home/zeus/miniconda3/envs/cloudspace/lib/python3.10/site-packages/wandb/sdk/wandb_run.py", line 456, in wrapper_fn
    return func(self, *args, **kwargs)
  File "/home/zeus/miniconda3/envs/cloudspace/lib/python3.10/site-packages/wandb/sdk/wandb_run.py", line 1566, in _console_raw_callback
    self._backend.interface.publish_output_raw(name, data)
  File "/home/zeus/miniconda3/envs/cloudspace/lib/python3.10/site-packages/wandb/sdk/interface/interface.py", line 771, in publish_output_raw
    self._publish_output_raw(o)
  File "/home/zeus/miniconda3/envs/cloudspace/lib/python3.10/site-packages/wandb/sdk/interface/interface_shared.py", line 38, in _publish_output_raw
    self._publish(rec)
  File "/home/zeus/miniconda3/envs/cloudspace/lib/python3.10/site-packages/wandb/sdk/interface/interface_sock.py", line 39, in _publish
    self._sock_client.send_record_publish(record)
  File "/home/zeus/miniconda3/envs/cloudspace/lib/python3.10/site-packages/wandb/sdk/lib/sock_client.py", line 170, in send_record_publish
    self.send_server_request(server_req)
  File "/home/zeus/miniconda3/envs/cloudspace/lib/python3.10/site-packages/wandb/sdk/lib/sock_client.py", line 150, in send_server_request
    self._send_message(msg)
  File "/home/zeus/miniconda3/envs/cloudspace/lib/python3.10/site-packages/wandb/sdk/lib/sock_client.py", line 147, in _send_message
    self._sendall_with_error_handle(header + data)
  File "/home/zeus/miniconda3/envs/cloudspace/lib/python3.10/site-packages/wandb/sdk/lib/sock_client.py", line 126, in _sendall_with_error_handle
    sent = self._sock.send(data)
BrokenPipeError: [Errno 32] Broken pipe
2025-07-19 00:18:55,948 ERROR   MainThread:37156 [redirect.py:_on_write():664] [all runs] error in stderr callback
Traceback (most recent call last):
  File "/home/zeus/miniconda3/envs/cloudspace/lib/python3.10/site-packages/wandb/sdk/lib/redirect.py", line 662, in _on_write
    cb(written_data)
  File "/home/zeus/miniconda3/envs/cloudspace/lib/python3.10/site-packages/wandb/sdk/wandb_run.py", line 2385, in <lambda>
    lambda data: self._console_raw_callback("stderr", data),
  File "/home/zeus/miniconda3/envs/cloudspace/lib/python3.10/site-packages/wandb/sdk/wandb_run.py", line 398, in wrapper
    return func(self, *args, **kwargs)
  File "/home/zeus/miniconda3/envs/cloudspace/lib/python3.10/site-packages/wandb/sdk/wandb_run.py", line 456, in wrapper_fn
    return func(self, *args, **kwargs)
  File "/home/zeus/miniconda3/envs/cloudspace/lib/python3.10/site-packages/wandb/sdk/wandb_run.py", line 1566, in _console_raw_callback
    self._backend.interface.publish_output_raw(name, data)
  File "/home/zeus/miniconda3/envs/cloudspace/lib/python3.10/site-packages/wandb/sdk/interface/interface.py", line 771, in publish_output_raw
    self._publish_output_raw(o)
  File "/home/zeus/miniconda3/envs/cloudspace/lib/python3.10/site-packages/wandb/sdk/interface/interface_shared.py", line 38, in _publish_output_raw
    self._publish(rec)
  File "/home/zeus/miniconda3/envs/cloudspace/lib/python3.10/site-packages/wandb/sdk/interface/interface_sock.py", line 39, in _publish
    self._sock_client.send_record_publish(record)
  File "/home/zeus/miniconda3/envs/cloudspace/lib/python3.10/site-packages/wandb/sdk/lib/sock_client.py", line 170, in send_record_publish
    self.send_server_request(server_req)
  File "/home/zeus/miniconda3/envs/cloudspace/lib/python3.10/site-packages/wandb/sdk/lib/sock_client.py", line 150, in send_server_request
    self._send_message(msg)
  File "/home/zeus/miniconda3/envs/cloudspace/lib/python3.10/site-packages/wandb/sdk/lib/sock_client.py", line 147, in _send_message
    self._sendall_with_error_handle(header + data)
  File "/home/zeus/miniconda3/envs/cloudspace/lib/python3.10/site-packages/wandb/sdk/lib/sock_client.py", line 126, in _sendall_with_error_handle
    sent = self._sock.send(data)
BrokenPipeError: [Errno 32] Broken pipe
2025-07-19 00:18:55,949 ERROR   MainThread:37156 [redirect.py:_on_write():664] [all runs] error in stderr callback
Traceback (most recent call last):
  File "/home/zeus/miniconda3/envs/cloudspace/lib/python3.10/site-packages/wandb/sdk/lib/redirect.py", line 662, in _on_write
    cb(written_data)
  File "/home/zeus/miniconda3/envs/cloudspace/lib/python3.10/site-packages/wandb/sdk/wandb_run.py", line 2385, in <lambda>
    lambda data: self._console_raw_callback("stderr", data),
  File "/home/zeus/miniconda3/envs/cloudspace/lib/python3.10/site-packages/wandb/sdk/wandb_run.py", line 398, in wrapper
    return func(self, *args, **kwargs)
  File "/home/zeus/miniconda3/envs/cloudspace/lib/python3.10/site-packages/wandb/sdk/wandb_run.py", line 456, in wrapper_fn
    return func(self, *args, **kwargs)
  File "/home/zeus/miniconda3/envs/cloudspace/lib/python3.10/site-packages/wandb/sdk/wandb_run.py", line 1566, in _console_raw_callback
    self._backend.interface.publish_output_raw(name, data)
  File "/home/zeus/miniconda3/envs/cloudspace/lib/python3.10/site-packages/wandb/sdk/interface/interface.py", line 771, in publish_output_raw
    self._publish_output_raw(o)
  File "/home/zeus/miniconda3/envs/cloudspace/lib/python3.10/site-packages/wandb/sdk/interface/interface_shared.py", line 38, in _publish_output_raw
    self._publish(rec)
  File "/home/zeus/miniconda3/envs/cloudspace/lib/python3.10/site-packages/wandb/sdk/interface/interface_sock.py", line 39, in _publish
    self._sock_client.send_record_publish(record)
  File "/home/zeus/miniconda3/envs/cloudspace/lib/python3.10/site-packages/wandb/sdk/lib/sock_client.py", line 170, in send_record_publish
    self.send_server_request(server_req)
  File "/home/zeus/miniconda3/envs/cloudspace/lib/python3.10/site-packages/wandb/sdk/lib/sock_client.py", line 150, in send_server_request
    self._send_message(msg)
  File "/home/zeus/miniconda3/envs/cloudspace/lib/python3.10/site-packages/wandb/sdk/lib/sock_client.py", line 147, in _send_message
    self._sendall_with_error_handle(header + data)
  File "/home/zeus/miniconda3/envs/cloudspace/lib/python3.10/site-packages/wandb/sdk/lib/sock_client.py", line 126, in _sendall_with_error_handle
    sent = self._sock.send(data)
BrokenPipeError: [Errno 32] Broken pipe
2025-07-19 00:18:55,949 ERROR   MainThread:37156 [redirect.py:_on_write():664] [all runs] error in stderr callback
Traceback (most recent call last):
  File "/home/zeus/miniconda3/envs/cloudspace/lib/python3.10/site-packages/wandb/sdk/lib/redirect.py", line 662, in _on_write
    cb(written_data)
  File "/home/zeus/miniconda3/envs/cloudspace/lib/python3.10/site-packages/wandb/sdk/wandb_run.py", line 2385, in <lambda>
    lambda data: self._console_raw_callback("stderr", data),
  File "/home/zeus/miniconda3/envs/cloudspace/lib/python3.10/site-packages/wandb/sdk/wandb_run.py", line 398, in wrapper
    return func(self, *args, **kwargs)
  File "/home/zeus/miniconda3/envs/cloudspace/lib/python3.10/site-packages/wandb/sdk/wandb_run.py", line 456, in wrapper_fn
    return func(self, *args, **kwargs)
  File "/home/zeus/miniconda3/envs/cloudspace/lib/python3.10/site-packages/wandb/sdk/wandb_run.py", line 1566, in _console_raw_callback
    self._backend.interface.publish_output_raw(name, data)
  File "/home/zeus/miniconda3/envs/cloudspace/lib/python3.10/site-packages/wandb/sdk/interface/interface.py", line 771, in publish_output_raw
    self._publish_output_raw(o)
  File "/home/zeus/miniconda3/envs/cloudspace/lib/python3.10/site-packages/wandb/sdk/interface/interface_shared.py", line 38, in _publish_output_raw
    self._publish(rec)
  File "/home/zeus/miniconda3/envs/cloudspace/lib/python3.10/site-packages/wandb/sdk/interface/interface_sock.py", line 39, in _publish
    self._sock_client.send_record_publish(record)
  File "/home/zeus/miniconda3/envs/cloudspace/lib/python3.10/site-packages/wandb/sdk/lib/sock_client.py", line 170, in send_record_publish
    self.send_server_request(server_req)
  File "/home/zeus/miniconda3/envs/cloudspace/lib/python3.10/site-packages/wandb/sdk/lib/sock_client.py", line 150, in send_server_request
    self._send_message(msg)
  File "/home/zeus/miniconda3/envs/cloudspace/lib/python3.10/site-packages/wandb/sdk/lib/sock_client.py", line 147, in _send_message
    self._sendall_with_error_handle(header + data)
  File "/home/zeus/miniconda3/envs/cloudspace/lib/python3.10/site-packages/wandb/sdk/lib/sock_client.py", line 126, in _sendall_with_error_handle
    sent = self._sock.send(data)
BrokenPipeError: [Errno 32] Broken pipe
2025-07-19 00:18:55,950 ERROR   MainThread:37156 [redirect.py:_on_write():664] [all runs] error in stderr callback
Traceback (most recent call last):
  File "/home/zeus/miniconda3/envs/cloudspace/lib/python3.10/site-packages/wandb/sdk/lib/redirect.py", line 662, in _on_write
    cb(written_data)
  File "/home/zeus/miniconda3/envs/cloudspace/lib/python3.10/site-packages/wandb/sdk/wandb_run.py", line 2385, in <lambda>
    lambda data: self._console_raw_callback("stderr", data),
  File "/home/zeus/miniconda3/envs/cloudspace/lib/python3.10/site-packages/wandb/sdk/wandb_run.py", line 398, in wrapper
    return func(self, *args, **kwargs)
  File "/home/zeus/miniconda3/envs/cloudspace/lib/python3.10/site-packages/wandb/sdk/wandb_run.py", line 456, in wrapper_fn
    return func(self, *args, **kwargs)
  File "/home/zeus/miniconda3/envs/cloudspace/lib/python3.10/site-packages/wandb/sdk/wandb_run.py", line 1566, in _console_raw_callback
    self._backend.interface.publish_output_raw(name, data)
  File "/home/zeus/miniconda3/envs/cloudspace/lib/python3.10/site-packages/wandb/sdk/interface/interface.py", line 771, in publish_output_raw
    self._publish_output_raw(o)
  File "/home/zeus/miniconda3/envs/cloudspace/lib/python3.10/site-packages/wandb/sdk/interface/interface_shared.py", line 38, in _publish_output_raw
    self._publish(rec)
  File "/home/zeus/miniconda3/envs/cloudspace/lib/python3.10/site-packages/wandb/sdk/interface/interface_sock.py", line 39, in _publish
    self._sock_client.send_record_publish(record)
  File "/home/zeus/miniconda3/envs/cloudspace/lib/python3.10/site-packages/wandb/sdk/lib/sock_client.py", line 170, in send_record_publish
    self.send_server_request(server_req)
  File "/home/zeus/miniconda3/envs/cloudspace/lib/python3.10/site-packages/wandb/sdk/lib/sock_client.py", line 150, in send_server_request
    self._send_message(msg)
  File "/home/zeus/miniconda3/envs/cloudspace/lib/python3.10/site-packages/wandb/sdk/lib/sock_client.py", line 147, in _send_message
    self._sendall_with_error_handle(header + data)
  File "/home/zeus/miniconda3/envs/cloudspace/lib/python3.10/site-packages/wandb/sdk/lib/sock_client.py", line 126, in _sendall_with_error_handle
    sent = self._sock.send(data)
BrokenPipeError: [Errno 32] Broken pipe
2025-07-19 00:18:55,950 ERROR   MainThread:37156 [redirect.py:_on_write():664] [all runs] error in stderr callback
Traceback (most recent call last):
  File "/home/zeus/miniconda3/envs/cloudspace/lib/python3.10/site-packages/wandb/sdk/lib/redirect.py", line 662, in _on_write
    cb(written_data)
  File "/home/zeus/miniconda3/envs/cloudspace/lib/python3.10/site-packages/wandb/sdk/wandb_run.py", line 2385, in <lambda>
    lambda data: self._console_raw_callback("stderr", data),
  File "/home/zeus/miniconda3/envs/cloudspace/lib/python3.10/site-packages/wandb/sdk/wandb_run.py", line 398, in wrapper
    return func(self, *args, **kwargs)
  File "/home/zeus/miniconda3/envs/cloudspace/lib/python3.10/site-packages/wandb/sdk/wandb_run.py", line 456, in wrapper_fn
    return func(self, *args, **kwargs)
  File "/home/zeus/miniconda3/envs/cloudspace/lib/python3.10/site-packages/wandb/sdk/wandb_run.py", line 1566, in _console_raw_callback
    self._backend.interface.publish_output_raw(name, data)
  File "/home/zeus/miniconda3/envs/cloudspace/lib/python3.10/site-packages/wandb/sdk/interface/interface.py", line 771, in publish_output_raw
    self._publish_output_raw(o)
  File "/home/zeus/miniconda3/envs/cloudspace/lib/python3.10/site-packages/wandb/sdk/interface/interface_shared.py", line 38, in _publish_output_raw
    self._publish(rec)
  File "/home/zeus/miniconda3/envs/cloudspace/lib/python3.10/site-packages/wandb/sdk/interface/interface_sock.py", line 39, in _publish
    self._sock_client.send_record_publish(record)
  File "/home/zeus/miniconda3/envs/cloudspace/lib/python3.10/site-packages/wandb/sdk/lib/sock_client.py", line 170, in send_record_publish
    self.send_server_request(server_req)
  File "/home/zeus/miniconda3/envs/cloudspace/lib/python3.10/site-packages/wandb/sdk/lib/sock_client.py", line 150, in send_server_request
    self._send_message(msg)
  File "/home/zeus/miniconda3/envs/cloudspace/lib/python3.10/site-packages/wandb/sdk/lib/sock_client.py", line 147, in _send_message
    self._sendall_with_error_handle(header + data)
  File "/home/zeus/miniconda3/envs/cloudspace/lib/python3.10/site-packages/wandb/sdk/lib/sock_client.py", line 126, in _sendall_with_error_handle
    sent = self._sock.send(data)
BrokenPipeError: [Errno 32] Broken pipe
2025-07-19 00:18:55,951 ERROR   MainThread:37156 [redirect.py:_on_write():664] [all runs] error in stderr callback
Traceback (most recent call last):
  File "/home/zeus/miniconda3/envs/cloudspace/lib/python3.10/site-packages/wandb/sdk/lib/redirect.py", line 662, in _on_write
    cb(written_data)
  File "/home/zeus/miniconda3/envs/cloudspace/lib/python3.10/site-packages/wandb/sdk/wandb_run.py", line 2385, in <lambda>
    lambda data: self._console_raw_callback("stderr", data),
  File "/home/zeus/miniconda3/envs/cloudspace/lib/python3.10/site-packages/wandb/sdk/wandb_run.py", line 398, in wrapper
    return func(self, *args, **kwargs)
  File "/home/zeus/miniconda3/envs/cloudspace/lib/python3.10/site-packages/wandb/sdk/wandb_run.py", line 456, in wrapper_fn
    return func(self, *args, **kwargs)
  File "/home/zeus/miniconda3/envs/cloudspace/lib/python3.10/site-packages/wandb/sdk/wandb_run.py", line 1566, in _console_raw_callback
    self._backend.interface.publish_output_raw(name, data)
  File "/home/zeus/miniconda3/envs/cloudspace/lib/python3.10/site-packages/wandb/sdk/interface/interface.py", line 771, in publish_output_raw
    self._publish_output_raw(o)
  File "/home/zeus/miniconda3/envs/cloudspace/lib/python3.10/site-packages/wandb/sdk/interface/interface_shared.py", line 38, in _publish_output_raw
    self._publish(rec)
  File "/home/zeus/miniconda3/envs/cloudspace/lib/python3.10/site-packages/wandb/sdk/interface/interface_sock.py", line 39, in _publish
    self._sock_client.send_record_publish(record)
  File "/home/zeus/miniconda3/envs/cloudspace/lib/python3.10/site-packages/wandb/sdk/lib/sock_client.py", line 170, in send_record_publish
    self.send_server_request(server_req)
  File "/home/zeus/miniconda3/envs/cloudspace/lib/python3.10/site-packages/wandb/sdk/lib/sock_client.py", line 150, in send_server_request
    self._send_message(msg)
  File "/home/zeus/miniconda3/envs/cloudspace/lib/python3.10/site-packages/wandb/sdk/lib/sock_client.py", line 147, in _send_message
    self._sendall_with_error_handle(header + data)
  File "/home/zeus/miniconda3/envs/cloudspace/lib/python3.10/site-packages/wandb/sdk/lib/sock_client.py", line 126, in _sendall_with_error_handle
    sent = self._sock.send(data)
BrokenPipeError: [Errno 32] Broken pipe
2025-07-19 00:18:55,951 ERROR   MainThread:37156 [redirect.py:_on_write():664] [all runs] error in stderr callback
Traceback (most recent call last):
  File "/home/zeus/miniconda3/envs/cloudspace/lib/python3.10/site-packages/wandb/sdk/lib/redirect.py", line 662, in _on_write
    cb(written_data)
  File "/home/zeus/miniconda3/envs/cloudspace/lib/python3.10/site-packages/wandb/sdk/wandb_run.py", line 2385, in <lambda>
    lambda data: self._console_raw_callback("stderr", data),
  File "/home/zeus/miniconda3/envs/cloudspace/lib/python3.10/site-packages/wandb/sdk/wandb_run.py", line 398, in wrapper
    return func(self, *args, **kwargs)
  File "/home/zeus/miniconda3/envs/cloudspace/lib/python3.10/site-packages/wandb/sdk/wandb_run.py", line 456, in wrapper_fn
    return func(self, *args, **kwargs)
  File "/home/zeus/miniconda3/envs/cloudspace/lib/python3.10/site-packages/wandb/sdk/wandb_run.py", line 1566, in _console_raw_callback
    self._backend.interface.publish_output_raw(name, data)
  File "/home/zeus/miniconda3/envs/cloudspace/lib/python3.10/site-packages/wandb/sdk/interface/interface.py", line 771, in publish_output_raw
    self._publish_output_raw(o)
  File "/home/zeus/miniconda3/envs/cloudspace/lib/python3.10/site-packages/wandb/sdk/interface/interface_shared.py", line 38, in _publish_output_raw
    self._publish(rec)
  File "/home/zeus/miniconda3/envs/cloudspace/lib/python3.10/site-packages/wandb/sdk/interface/interface_sock.py", line 39, in _publish
    self._sock_client.send_record_publish(record)
  File "/home/zeus/miniconda3/envs/cloudspace/lib/python3.10/site-packages/wandb/sdk/lib/sock_client.py", line 170, in send_record_publish
    self.send_server_request(server_req)
  File "/home/zeus/miniconda3/envs/cloudspace/lib/python3.10/site-packages/wandb/sdk/lib/sock_client.py", line 150, in send_server_request
    self._send_message(msg)
  File "/home/zeus/miniconda3/envs/cloudspace/lib/python3.10/site-packages/wandb/sdk/lib/sock_client.py", line 147, in _send_message
    self._sendall_with_error_handle(header + data)
  File "/home/zeus/miniconda3/envs/cloudspace/lib/python3.10/site-packages/wandb/sdk/lib/sock_client.py", line 126, in _sendall_with_error_handle
    sent = self._sock.send(data)
BrokenPipeError: [Errno 32] Broken pipe
2025-07-19 00:18:55,952 ERROR   MainThread:37156 [redirect.py:_on_write():664] [all runs] error in stderr callback
Traceback (most recent call last):
  File "/home/zeus/miniconda3/envs/cloudspace/lib/python3.10/site-packages/wandb/sdk/lib/redirect.py", line 662, in _on_write
    cb(written_data)
  File "/home/zeus/miniconda3/envs/cloudspace/lib/python3.10/site-packages/wandb/sdk/wandb_run.py", line 2385, in <lambda>
    lambda data: self._console_raw_callback("stderr", data),
  File "/home/zeus/miniconda3/envs/cloudspace/lib/python3.10/site-packages/wandb/sdk/wandb_run.py", line 398, in wrapper
    return func(self, *args, **kwargs)
  File "/home/zeus/miniconda3/envs/cloudspace/lib/python3.10/site-packages/wandb/sdk/wandb_run.py", line 456, in wrapper_fn
    return func(self, *args, **kwargs)
  File "/home/zeus/miniconda3/envs/cloudspace/lib/python3.10/site-packages/wandb/sdk/wandb_run.py", line 1566, in _console_raw_callback
    self._backend.interface.publish_output_raw(name, data)
  File "/home/zeus/miniconda3/envs/cloudspace/lib/python3.10/site-packages/wandb/sdk/interface/interface.py", line 771, in publish_output_raw
    self._publish_output_raw(o)
  File "/home/zeus/miniconda3/envs/cloudspace/lib/python3.10/site-packages/wandb/sdk/interface/interface_shared.py", line 38, in _publish_output_raw
    self._publish(rec)
  File "/home/zeus/miniconda3/envs/cloudspace/lib/python3.10/site-packages/wandb/sdk/interface/interface_sock.py", line 39, in _publish
    self._sock_client.send_record_publish(record)
  File "/home/zeus/miniconda3/envs/cloudspace/lib/python3.10/site-packages/wandb/sdk/lib/sock_client.py", line 170, in send_record_publish
    self.send_server_request(server_req)
  File "/home/zeus/miniconda3/envs/cloudspace/lib/python3.10/site-packages/wandb/sdk/lib/sock_client.py", line 150, in send_server_request
    self._send_message(msg)
  File "/home/zeus/miniconda3/envs/cloudspace/lib/python3.10/site-packages/wandb/sdk/lib/sock_client.py", line 147, in _send_message
    self._sendall_with_error_handle(header + data)
  File "/home/zeus/miniconda3/envs/cloudspace/lib/python3.10/site-packages/wandb/sdk/lib/sock_client.py", line 126, in _sendall_with_error_handle
    sent = self._sock.send(data)
BrokenPipeError: [Errno 32] Broken pipe
2025-07-19 00:18:55,952 ERROR   MainThread:37156 [redirect.py:_on_write():664] [all runs] error in stderr callback
Traceback (most recent call last):
  File "/home/zeus/miniconda3/envs/cloudspace/lib/python3.10/site-packages/wandb/sdk/lib/redirect.py", line 662, in _on_write
    cb(written_data)
  File "/home/zeus/miniconda3/envs/cloudspace/lib/python3.10/site-packages/wandb/sdk/wandb_run.py", line 2385, in <lambda>
    lambda data: self._console_raw_callback("stderr", data),
  File "/home/zeus/miniconda3/envs/cloudspace/lib/python3.10/site-packages/wandb/sdk/wandb_run.py", line 398, in wrapper
    return func(self, *args, **kwargs)
  File "/home/zeus/miniconda3/envs/cloudspace/lib/python3.10/site-packages/wandb/sdk/wandb_run.py", line 456, in wrapper_fn
    return func(self, *args, **kwargs)
  File "/home/zeus/miniconda3/envs/cloudspace/lib/python3.10/site-packages/wandb/sdk/wandb_run.py", line 1566, in _console_raw_callback
    self._backend.interface.publish_output_raw(name, data)
  File "/home/zeus/miniconda3/envs/cloudspace/lib/python3.10/site-packages/wandb/sdk/interface/interface.py", line 771, in publish_output_raw
    self._publish_output_raw(o)
  File "/home/zeus/miniconda3/envs/cloudspace/lib/python3.10/site-packages/wandb/sdk/interface/interface_shared.py", line 38, in _publish_output_raw
    self._publish(rec)
  File "/home/zeus/miniconda3/envs/cloudspace/lib/python3.10/site-packages/wandb/sdk/interface/interface_sock.py", line 39, in _publish
    self._sock_client.send_record_publish(record)
  File "/home/zeus/miniconda3/envs/cloudspace/lib/python3.10/site-packages/wandb/sdk/lib/sock_client.py", line 170, in send_record_publish
    self.send_server_request(server_req)
  File "/home/zeus/miniconda3/envs/cloudspace/lib/python3.10/site-packages/wandb/sdk/lib/sock_client.py", line 150, in send_server_request
    self._send_message(msg)
  File "/home/zeus/miniconda3/envs/cloudspace/lib/python3.10/site-packages/wandb/sdk/lib/sock_client.py", line 147, in _send_message
    self._sendall_with_error_handle(header + data)
  File "/home/zeus/miniconda3/envs/cloudspace/lib/python3.10/site-packages/wandb/sdk/lib/sock_client.py", line 126, in _sendall_with_error_handle
    sent = self._sock.send(data)
BrokenPipeError: [Errno 32] Broken pipe
2025-07-19 00:18:55,953 ERROR   MainThread:37156 [redirect.py:_on_write():664] [all runs] error in stderr callback
Traceback (most recent call last):
  File "/home/zeus/miniconda3/envs/cloudspace/lib/python3.10/site-packages/wandb/sdk/lib/redirect.py", line 662, in _on_write
    cb(written_data)
  File "/home/zeus/miniconda3/envs/cloudspace/lib/python3.10/site-packages/wandb/sdk/wandb_run.py", line 2385, in <lambda>
    lambda data: self._console_raw_callback("stderr", data),
  File "/home/zeus/miniconda3/envs/cloudspace/lib/python3.10/site-packages/wandb/sdk/wandb_run.py", line 398, in wrapper
    return func(self, *args, **kwargs)
  File "/home/zeus/miniconda3/envs/cloudspace/lib/python3.10/site-packages/wandb/sdk/wandb_run.py", line 456, in wrapper_fn
    return func(self, *args, **kwargs)
  File "/home/zeus/miniconda3/envs/cloudspace/lib/python3.10/site-packages/wandb/sdk/wandb_run.py", line 1566, in _console_raw_callback
    self._backend.interface.publish_output_raw(name, data)
  File "/home/zeus/miniconda3/envs/cloudspace/lib/python3.10/site-packages/wandb/sdk/interface/interface.py", line 771, in publish_output_raw
    self._publish_output_raw(o)
  File "/home/zeus/miniconda3/envs/cloudspace/lib/python3.10/site-packages/wandb/sdk/interface/interface_shared.py", line 38, in _publish_output_raw
    self._publish(rec)
  File "/home/zeus/miniconda3/envs/cloudspace/lib/python3.10/site-packages/wandb/sdk/interface/interface_sock.py", line 39, in _publish
    self._sock_client.send_record_publish(record)
  File "/home/zeus/miniconda3/envs/cloudspace/lib/python3.10/site-packages/wandb/sdk/lib/sock_client.py", line 170, in send_record_publish
    self.send_server_request(server_req)
  File "/home/zeus/miniconda3/envs/cloudspace/lib/python3.10/site-packages/wandb/sdk/lib/sock_client.py", line 150, in send_server_request
    self._send_message(msg)
  File "/home/zeus/miniconda3/envs/cloudspace/lib/python3.10/site-packages/wandb/sdk/lib/sock_client.py", line 147, in _send_message
    self._sendall_with_error_handle(header + data)
  File "/home/zeus/miniconda3/envs/cloudspace/lib/python3.10/site-packages/wandb/sdk/lib/sock_client.py", line 126, in _sendall_with_error_handle
    sent = self._sock.send(data)
BrokenPipeError: [Errno 32] Broken pipe
2025-07-19 00:18:55,957 ERROR   MainThread:37156 [redirect.py:_on_write():664] [all runs] error in stderr callback
Traceback (most recent call last):
  File "/home/zeus/miniconda3/envs/cloudspace/lib/python3.10/site-packages/wandb/sdk/lib/redirect.py", line 662, in _on_write
    cb(written_data)
  File "/home/zeus/miniconda3/envs/cloudspace/lib/python3.10/site-packages/wandb/sdk/wandb_run.py", line 2385, in <lambda>
    lambda data: self._console_raw_callback("stderr", data),
  File "/home/zeus/miniconda3/envs/cloudspace/lib/python3.10/site-packages/wandb/sdk/wandb_run.py", line 398, in wrapper
    return func(self, *args, **kwargs)
  File "/home/zeus/miniconda3/envs/cloudspace/lib/python3.10/site-packages/wandb/sdk/wandb_run.py", line 456, in wrapper_fn
    return func(self, *args, **kwargs)
  File "/home/zeus/miniconda3/envs/cloudspace/lib/python3.10/site-packages/wandb/sdk/wandb_run.py", line 1566, in _console_raw_callback
    self._backend.interface.publish_output_raw(name, data)
  File "/home/zeus/miniconda3/envs/cloudspace/lib/python3.10/site-packages/wandb/sdk/interface/interface.py", line 771, in publish_output_raw
    self._publish_output_raw(o)
  File "/home/zeus/miniconda3/envs/cloudspace/lib/python3.10/site-packages/wandb/sdk/interface/interface_shared.py", line 38, in _publish_output_raw
    self._publish(rec)
  File "/home/zeus/miniconda3/envs/cloudspace/lib/python3.10/site-packages/wandb/sdk/interface/interface_sock.py", line 39, in _publish
    self._sock_client.send_record_publish(record)
  File "/home/zeus/miniconda3/envs/cloudspace/lib/python3.10/site-packages/wandb/sdk/lib/sock_client.py", line 170, in send_record_publish
    self.send_server_request(server_req)
  File "/home/zeus/miniconda3/envs/cloudspace/lib/python3.10/site-packages/wandb/sdk/lib/sock_client.py", line 150, in send_server_request
    self._send_message(msg)
  File "/home/zeus/miniconda3/envs/cloudspace/lib/python3.10/site-packages/wandb/sdk/lib/sock_client.py", line 147, in _send_message
    self._sendall_with_error_handle(header + data)
  File "/home/zeus/miniconda3/envs/cloudspace/lib/python3.10/site-packages/wandb/sdk/lib/sock_client.py", line 126, in _sendall_with_error_handle
    sent = self._sock.send(data)
BrokenPipeError: [Errno 32] Broken pipe
2025-07-19 00:18:55,957 ERROR   MainThread:37156 [redirect.py:_on_write():664] [all runs] error in stderr callback
Traceback (most recent call last):
  File "/home/zeus/miniconda3/envs/cloudspace/lib/python3.10/site-packages/wandb/sdk/lib/redirect.py", line 662, in _on_write
    cb(written_data)
  File "/home/zeus/miniconda3/envs/cloudspace/lib/python3.10/site-packages/wandb/sdk/wandb_run.py", line 2385, in <lambda>
    lambda data: self._console_raw_callback("stderr", data),
  File "/home/zeus/miniconda3/envs/cloudspace/lib/python3.10/site-packages/wandb/sdk/wandb_run.py", line 398, in wrapper
    return func(self, *args, **kwargs)
  File "/home/zeus/miniconda3/envs/cloudspace/lib/python3.10/site-packages/wandb/sdk/wandb_run.py", line 456, in wrapper_fn
    return func(self, *args, **kwargs)
  File "/home/zeus/miniconda3/envs/cloudspace/lib/python3.10/site-packages/wandb/sdk/wandb_run.py", line 1566, in _console_raw_callback
    self._backend.interface.publish_output_raw(name, data)
  File "/home/zeus/miniconda3/envs/cloudspace/lib/python3.10/site-packages/wandb/sdk/interface/interface.py", line 771, in publish_output_raw
    self._publish_output_raw(o)
  File "/home/zeus/miniconda3/envs/cloudspace/lib/python3.10/site-packages/wandb/sdk/interface/interface_shared.py", line 38, in _publish_output_raw
    self._publish(rec)
  File "/home/zeus/miniconda3/envs/cloudspace/lib/python3.10/site-packages/wandb/sdk/interface/interface_sock.py", line 39, in _publish
    self._sock_client.send_record_publish(record)
  File "/home/zeus/miniconda3/envs/cloudspace/lib/python3.10/site-packages/wandb/sdk/lib/sock_client.py", line 170, in send_record_publish
    self.send_server_request(server_req)
  File "/home/zeus/miniconda3/envs/cloudspace/lib/python3.10/site-packages/wandb/sdk/lib/sock_client.py", line 150, in send_server_request
    self._send_message(msg)
  File "/home/zeus/miniconda3/envs/cloudspace/lib/python3.10/site-packages/wandb/sdk/lib/sock_client.py", line 147, in _send_message
    self._sendall_with_error_handle(header + data)
  File "/home/zeus/miniconda3/envs/cloudspace/lib/python3.10/site-packages/wandb/sdk/lib/sock_client.py", line 126, in _sendall_with_error_handle
    sent = self._sock.send(data)
BrokenPipeError: [Errno 32] Broken pipe
2025-07-19 00:18:55,958 ERROR   MainThread:37156 [redirect.py:_on_write():664] [all runs] error in stderr callback
Traceback (most recent call last):
  File "/home/zeus/miniconda3/envs/cloudspace/lib/python3.10/site-packages/wandb/sdk/lib/redirect.py", line 662, in _on_write
    cb(written_data)
  File "/home/zeus/miniconda3/envs/cloudspace/lib/python3.10/site-packages/wandb/sdk/wandb_run.py", line 2385, in <lambda>
    lambda data: self._console_raw_callback("stderr", data),
  File "/home/zeus/miniconda3/envs/cloudspace/lib/python3.10/site-packages/wandb/sdk/wandb_run.py", line 398, in wrapper
    return func(self, *args, **kwargs)
  File "/home/zeus/miniconda3/envs/cloudspace/lib/python3.10/site-packages/wandb/sdk/wandb_run.py", line 456, in wrapper_fn
    return func(self, *args, **kwargs)
  File "/home/zeus/miniconda3/envs/cloudspace/lib/python3.10/site-packages/wandb/sdk/wandb_run.py", line 1566, in _console_raw_callback
    self._backend.interface.publish_output_raw(name, data)
  File "/home/zeus/miniconda3/envs/cloudspace/lib/python3.10/site-packages/wandb/sdk/interface/interface.py", line 771, in publish_output_raw
    self._publish_output_raw(o)
  File "/home/zeus/miniconda3/envs/cloudspace/lib/python3.10/site-packages/wandb/sdk/interface/interface_shared.py", line 38, in _publish_output_raw
    self._publish(rec)
  File "/home/zeus/miniconda3/envs/cloudspace/lib/python3.10/site-packages/wandb/sdk/interface/interface_sock.py", line 39, in _publish
    self._sock_client.send_record_publish(record)
  File "/home/zeus/miniconda3/envs/cloudspace/lib/python3.10/site-packages/wandb/sdk/lib/sock_client.py", line 170, in send_record_publish
    self.send_server_request(server_req)
  File "/home/zeus/miniconda3/envs/cloudspace/lib/python3.10/site-packages/wandb/sdk/lib/sock_client.py", line 150, in send_server_request
    self._send_message(msg)
  File "/home/zeus/miniconda3/envs/cloudspace/lib/python3.10/site-packages/wandb/sdk/lib/sock_client.py", line 147, in _send_message
    self._sendall_with_error_handle(header + data)
  File "/home/zeus/miniconda3/envs/cloudspace/lib/python3.10/site-packages/wandb/sdk/lib/sock_client.py", line 126, in _sendall_with_error_handle
    sent = self._sock.send(data)
BrokenPipeError: [Errno 32] Broken pipe
2025-07-19 00:18:55,959 ERROR   MainThread:37156 [redirect.py:_on_write():664] [all runs] error in stderr callback
Traceback (most recent call last):
  File "/home/zeus/miniconda3/envs/cloudspace/lib/python3.10/site-packages/wandb/sdk/lib/redirect.py", line 662, in _on_write
    cb(written_data)
  File "/home/zeus/miniconda3/envs/cloudspace/lib/python3.10/site-packages/wandb/sdk/wandb_run.py", line 2385, in <lambda>
    lambda data: self._console_raw_callback("stderr", data),
  File "/home/zeus/miniconda3/envs/cloudspace/lib/python3.10/site-packages/wandb/sdk/wandb_run.py", line 398, in wrapper
    return func(self, *args, **kwargs)
  File "/home/zeus/miniconda3/envs/cloudspace/lib/python3.10/site-packages/wandb/sdk/wandb_run.py", line 456, in wrapper_fn
    return func(self, *args, **kwargs)
  File "/home/zeus/miniconda3/envs/cloudspace/lib/python3.10/site-packages/wandb/sdk/wandb_run.py", line 1566, in _console_raw_callback
    self._backend.interface.publish_output_raw(name, data)
  File "/home/zeus/miniconda3/envs/cloudspace/lib/python3.10/site-packages/wandb/sdk/interface/interface.py", line 771, in publish_output_raw
    self._publish_output_raw(o)
  File "/home/zeus/miniconda3/envs/cloudspace/lib/python3.10/site-packages/wandb/sdk/interface/interface_shared.py", line 38, in _publish_output_raw
    self._publish(rec)
  File "/home/zeus/miniconda3/envs/cloudspace/lib/python3.10/site-packages/wandb/sdk/interface/interface_sock.py", line 39, in _publish
    self._sock_client.send_record_publish(record)
  File "/home/zeus/miniconda3/envs/cloudspace/lib/python3.10/site-packages/wandb/sdk/lib/sock_client.py", line 170, in send_record_publish
    self.send_server_request(server_req)
  File "/home/zeus/miniconda3/envs/cloudspace/lib/python3.10/site-packages/wandb/sdk/lib/sock_client.py", line 150, in send_server_request
    self._send_message(msg)
  File "/home/zeus/miniconda3/envs/cloudspace/lib/python3.10/site-packages/wandb/sdk/lib/sock_client.py", line 147, in _send_message
    self._sendall_with_error_handle(header + data)
  File "/home/zeus/miniconda3/envs/cloudspace/lib/python3.10/site-packages/wandb/sdk/lib/sock_client.py", line 126, in _sendall_with_error_handle
    sent = self._sock.send(data)
BrokenPipeError: [Errno 32] Broken pipe
2025-07-19 00:18:55,959 ERROR   MainThread:37156 [redirect.py:_on_write():664] [all runs] error in stderr callback
Traceback (most recent call last):
  File "/home/zeus/miniconda3/envs/cloudspace/lib/python3.10/site-packages/wandb/sdk/lib/redirect.py", line 662, in _on_write
    cb(written_data)
  File "/home/zeus/miniconda3/envs/cloudspace/lib/python3.10/site-packages/wandb/sdk/wandb_run.py", line 2385, in <lambda>
    lambda data: self._console_raw_callback("stderr", data),
  File "/home/zeus/miniconda3/envs/cloudspace/lib/python3.10/site-packages/wandb/sdk/wandb_run.py", line 398, in wrapper
    return func(self, *args, **kwargs)
  File "/home/zeus/miniconda3/envs/cloudspace/lib/python3.10/site-packages/wandb/sdk/wandb_run.py", line 456, in wrapper_fn
    return func(self, *args, **kwargs)
  File "/home/zeus/miniconda3/envs/cloudspace/lib/python3.10/site-packages/wandb/sdk/wandb_run.py", line 1566, in _console_raw_callback
    self._backend.interface.publish_output_raw(name, data)
  File "/home/zeus/miniconda3/envs/cloudspace/lib/python3.10/site-packages/wandb/sdk/interface/interface.py", line 771, in publish_output_raw
    self._publish_output_raw(o)
  File "/home/zeus/miniconda3/envs/cloudspace/lib/python3.10/site-packages/wandb/sdk/interface/interface_shared.py", line 38, in _publish_output_raw
    self._publish(rec)
  File "/home/zeus/miniconda3/envs/cloudspace/lib/python3.10/site-packages/wandb/sdk/interface/interface_sock.py", line 39, in _publish
    self._sock_client.send_record_publish(record)
  File "/home/zeus/miniconda3/envs/cloudspace/lib/python3.10/site-packages/wandb/sdk/lib/sock_client.py", line 170, in send_record_publish
    self.send_server_request(server_req)
  File "/home/zeus/miniconda3/envs/cloudspace/lib/python3.10/site-packages/wandb/sdk/lib/sock_client.py", line 150, in send_server_request
    self._send_message(msg)
  File "/home/zeus/miniconda3/envs/cloudspace/lib/python3.10/site-packages/wandb/sdk/lib/sock_client.py", line 147, in _send_message
    self._sendall_with_error_handle(header + data)
  File "/home/zeus/miniconda3/envs/cloudspace/lib/python3.10/site-packages/wandb/sdk/lib/sock_client.py", line 126, in _sendall_with_error_handle
    sent = self._sock.send(data)
BrokenPipeError: [Errno 32] Broken pipe
2025-07-19 00:18:55,960 ERROR   MainThread:37156 [redirect.py:_on_write():664] [all runs] error in stderr callback
Traceback (most recent call last):
  File "/home/zeus/miniconda3/envs/cloudspace/lib/python3.10/site-packages/wandb/sdk/lib/redirect.py", line 662, in _on_write
    cb(written_data)
  File "/home/zeus/miniconda3/envs/cloudspace/lib/python3.10/site-packages/wandb/sdk/wandb_run.py", line 2385, in <lambda>
    lambda data: self._console_raw_callback("stderr", data),
  File "/home/zeus/miniconda3/envs/cloudspace/lib/python3.10/site-packages/wandb/sdk/wandb_run.py", line 398, in wrapper
    return func(self, *args, **kwargs)
  File "/home/zeus/miniconda3/envs/cloudspace/lib/python3.10/site-packages/wandb/sdk/wandb_run.py", line 456, in wrapper_fn
    return func(self, *args, **kwargs)
  File "/home/zeus/miniconda3/envs/cloudspace/lib/python3.10/site-packages/wandb/sdk/wandb_run.py", line 1566, in _console_raw_callback
    self._backend.interface.publish_output_raw(name, data)
  File "/home/zeus/miniconda3/envs/cloudspace/lib/python3.10/site-packages/wandb/sdk/interface/interface.py", line 771, in publish_output_raw
    self._publish_output_raw(o)
  File "/home/zeus/miniconda3/envs/cloudspace/lib/python3.10/site-packages/wandb/sdk/interface/interface_shared.py", line 38, in _publish_output_raw
    self._publish(rec)
  File "/home/zeus/miniconda3/envs/cloudspace/lib/python3.10/site-packages/wandb/sdk/interface/interface_sock.py", line 39, in _publish
    self._sock_client.send_record_publish(record)
  File "/home/zeus/miniconda3/envs/cloudspace/lib/python3.10/site-packages/wandb/sdk/lib/sock_client.py", line 170, in send_record_publish
    self.send_server_request(server_req)
  File "/home/zeus/miniconda3/envs/cloudspace/lib/python3.10/site-packages/wandb/sdk/lib/sock_client.py", line 150, in send_server_request
    self._send_message(msg)
  File "/home/zeus/miniconda3/envs/cloudspace/lib/python3.10/site-packages/wandb/sdk/lib/sock_client.py", line 147, in _send_message
    self._sendall_with_error_handle(header + data)
  File "/home/zeus/miniconda3/envs/cloudspace/lib/python3.10/site-packages/wandb/sdk/lib/sock_client.py", line 126, in _sendall_with_error_handle
    sent = self._sock.send(data)
BrokenPipeError: [Errno 32] Broken pipe
2025-07-19 00:18:55,960 ERROR   MainThread:37156 [redirect.py:_on_write():664] [all runs] error in stderr callback
Traceback (most recent call last):
  File "/home/zeus/miniconda3/envs/cloudspace/lib/python3.10/site-packages/wandb/sdk/lib/redirect.py", line 662, in _on_write
    cb(written_data)
  File "/home/zeus/miniconda3/envs/cloudspace/lib/python3.10/site-packages/wandb/sdk/wandb_run.py", line 2385, in <lambda>
    lambda data: self._console_raw_callback("stderr", data),
  File "/home/zeus/miniconda3/envs/cloudspace/lib/python3.10/site-packages/wandb/sdk/wandb_run.py", line 398, in wrapper
    return func(self, *args, **kwargs)
  File "/home/zeus/miniconda3/envs/cloudspace/lib/python3.10/site-packages/wandb/sdk/wandb_run.py", line 456, in wrapper_fn
    return func(self, *args, **kwargs)
  File "/home/zeus/miniconda3/envs/cloudspace/lib/python3.10/site-packages/wandb/sdk/wandb_run.py", line 1566, in _console_raw_callback
    self._backend.interface.publish_output_raw(name, data)
  File "/home/zeus/miniconda3/envs/cloudspace/lib/python3.10/site-packages/wandb/sdk/interface/interface.py", line 771, in publish_output_raw
    self._publish_output_raw(o)
  File "/home/zeus/miniconda3/envs/cloudspace/lib/python3.10/site-packages/wandb/sdk/interface/interface_shared.py", line 38, in _publish_output_raw
    self._publish(rec)
  File "/home/zeus/miniconda3/envs/cloudspace/lib/python3.10/site-packages/wandb/sdk/interface/interface_sock.py", line 39, in _publish
    self._sock_client.send_record_publish(record)
  File "/home/zeus/miniconda3/envs/cloudspace/lib/python3.10/site-packages/wandb/sdk/lib/sock_client.py", line 170, in send_record_publish
    self.send_server_request(server_req)
  File "/home/zeus/miniconda3/envs/cloudspace/lib/python3.10/site-packages/wandb/sdk/lib/sock_client.py", line 150, in send_server_request
    self._send_message(msg)
  File "/home/zeus/miniconda3/envs/cloudspace/lib/python3.10/site-packages/wandb/sdk/lib/sock_client.py", line 147, in _send_message
    self._sendall_with_error_handle(header + data)
  File "/home/zeus/miniconda3/envs/cloudspace/lib/python3.10/site-packages/wandb/sdk/lib/sock_client.py", line 126, in _sendall_with_error_handle
    sent = self._sock.send(data)
BrokenPipeError: [Errno 32] Broken pipe
2025-07-19 00:18:55,961 ERROR   MainThread:37156 [redirect.py:_on_write():664] [all runs] error in stderr callback
Traceback (most recent call last):
  File "/home/zeus/miniconda3/envs/cloudspace/lib/python3.10/site-packages/wandb/sdk/lib/redirect.py", line 662, in _on_write
    cb(written_data)
  File "/home/zeus/miniconda3/envs/cloudspace/lib/python3.10/site-packages/wandb/sdk/wandb_run.py", line 2385, in <lambda>
    lambda data: self._console_raw_callback("stderr", data),
  File "/home/zeus/miniconda3/envs/cloudspace/lib/python3.10/site-packages/wandb/sdk/wandb_run.py", line 398, in wrapper
    return func(self, *args, **kwargs)
  File "/home/zeus/miniconda3/envs/cloudspace/lib/python3.10/site-packages/wandb/sdk/wandb_run.py", line 456, in wrapper_fn
    return func(self, *args, **kwargs)
  File "/home/zeus/miniconda3/envs/cloudspace/lib/python3.10/site-packages/wandb/sdk/wandb_run.py", line 1566, in _console_raw_callback
    self._backend.interface.publish_output_raw(name, data)
  File "/home/zeus/miniconda3/envs/cloudspace/lib/python3.10/site-packages/wandb/sdk/interface/interface.py", line 771, in publish_output_raw
    self._publish_output_raw(o)
  File "/home/zeus/miniconda3/envs/cloudspace/lib/python3.10/site-packages/wandb/sdk/interface/interface_shared.py", line 38, in _publish_output_raw
    self._publish(rec)
  File "/home/zeus/miniconda3/envs/cloudspace/lib/python3.10/site-packages/wandb/sdk/interface/interface_sock.py", line 39, in _publish
    self._sock_client.send_record_publish(record)
  File "/home/zeus/miniconda3/envs/cloudspace/lib/python3.10/site-packages/wandb/sdk/lib/sock_client.py", line 170, in send_record_publish
    self.send_server_request(server_req)
  File "/home/zeus/miniconda3/envs/cloudspace/lib/python3.10/site-packages/wandb/sdk/lib/sock_client.py", line 150, in send_server_request
    self._send_message(msg)
  File "/home/zeus/miniconda3/envs/cloudspace/lib/python3.10/site-packages/wandb/sdk/lib/sock_client.py", line 147, in _send_message
    self._sendall_with_error_handle(header + data)
  File "/home/zeus/miniconda3/envs/cloudspace/lib/python3.10/site-packages/wandb/sdk/lib/sock_client.py", line 126, in _sendall_with_error_handle
    sent = self._sock.send(data)
BrokenPipeError: [Errno 32] Broken pipe
2025-07-19 00:18:55,962 ERROR   MainThread:37156 [redirect.py:_on_write():664] [all runs] error in stderr callback
Traceback (most recent call last):
  File "/home/zeus/miniconda3/envs/cloudspace/lib/python3.10/site-packages/wandb/sdk/lib/redirect.py", line 662, in _on_write
    cb(written_data)
  File "/home/zeus/miniconda3/envs/cloudspace/lib/python3.10/site-packages/wandb/sdk/wandb_run.py", line 2385, in <lambda>
    lambda data: self._console_raw_callback("stderr", data),
  File "/home/zeus/miniconda3/envs/cloudspace/lib/python3.10/site-packages/wandb/sdk/wandb_run.py", line 398, in wrapper
    return func(self, *args, **kwargs)
  File "/home/zeus/miniconda3/envs/cloudspace/lib/python3.10/site-packages/wandb/sdk/wandb_run.py", line 456, in wrapper_fn
    return func(self, *args, **kwargs)
  File "/home/zeus/miniconda3/envs/cloudspace/lib/python3.10/site-packages/wandb/sdk/wandb_run.py", line 1566, in _console_raw_callback
    self._backend.interface.publish_output_raw(name, data)
  File "/home/zeus/miniconda3/envs/cloudspace/lib/python3.10/site-packages/wandb/sdk/interface/interface.py", line 771, in publish_output_raw
    self._publish_output_raw(o)
  File "/home/zeus/miniconda3/envs/cloudspace/lib/python3.10/site-packages/wandb/sdk/interface/interface_shared.py", line 38, in _publish_output_raw
    self._publish(rec)
  File "/home/zeus/miniconda3/envs/cloudspace/lib/python3.10/site-packages/wandb/sdk/interface/interface_sock.py", line 39, in _publish
    self._sock_client.send_record_publish(record)
  File "/home/zeus/miniconda3/envs/cloudspace/lib/python3.10/site-packages/wandb/sdk/lib/sock_client.py", line 170, in send_record_publish
    self.send_server_request(server_req)
  File "/home/zeus/miniconda3/envs/cloudspace/lib/python3.10/site-packages/wandb/sdk/lib/sock_client.py", line 150, in send_server_request
    self._send_message(msg)
  File "/home/zeus/miniconda3/envs/cloudspace/lib/python3.10/site-packages/wandb/sdk/lib/sock_client.py", line 147, in _send_message
    self._sendall_with_error_handle(header + data)
  File "/home/zeus/miniconda3/envs/cloudspace/lib/python3.10/site-packages/wandb/sdk/lib/sock_client.py", line 126, in _sendall_with_error_handle
    sent = self._sock.send(data)
BrokenPipeError: [Errno 32] Broken pipe
2025-07-19 00:18:55,962 ERROR   MainThread:37156 [redirect.py:_on_write():664] [all runs] error in stderr callback
Traceback (most recent call last):
  File "/home/zeus/miniconda3/envs/cloudspace/lib/python3.10/site-packages/wandb/sdk/lib/redirect.py", line 662, in _on_write
    cb(written_data)
  File "/home/zeus/miniconda3/envs/cloudspace/lib/python3.10/site-packages/wandb/sdk/wandb_run.py", line 2385, in <lambda>
    lambda data: self._console_raw_callback("stderr", data),
  File "/home/zeus/miniconda3/envs/cloudspace/lib/python3.10/site-packages/wandb/sdk/wandb_run.py", line 398, in wrapper
    return func(self, *args, **kwargs)
  File "/home/zeus/miniconda3/envs/cloudspace/lib/python3.10/site-packages/wandb/sdk/wandb_run.py", line 456, in wrapper_fn
    return func(self, *args, **kwargs)
  File "/home/zeus/miniconda3/envs/cloudspace/lib/python3.10/site-packages/wandb/sdk/wandb_run.py", line 1566, in _console_raw_callback
    self._backend.interface.publish_output_raw(name, data)
  File "/home/zeus/miniconda3/envs/cloudspace/lib/python3.10/site-packages/wandb/sdk/interface/interface.py", line 771, in publish_output_raw
    self._publish_output_raw(o)
  File "/home/zeus/miniconda3/envs/cloudspace/lib/python3.10/site-packages/wandb/sdk/interface/interface_shared.py", line 38, in _publish_output_raw
    self._publish(rec)
  File "/home/zeus/miniconda3/envs/cloudspace/lib/python3.10/site-packages/wandb/sdk/interface/interface_sock.py", line 39, in _publish
    self._sock_client.send_record_publish(record)
  File "/home/zeus/miniconda3/envs/cloudspace/lib/python3.10/site-packages/wandb/sdk/lib/sock_client.py", line 170, in send_record_publish
    self.send_server_request(server_req)
  File "/home/zeus/miniconda3/envs/cloudspace/lib/python3.10/site-packages/wandb/sdk/lib/sock_client.py", line 150, in send_server_request
    self._send_message(msg)
  File "/home/zeus/miniconda3/envs/cloudspace/lib/python3.10/site-packages/wandb/sdk/lib/sock_client.py", line 147, in _send_message
    self._sendall_with_error_handle(header + data)
  File "/home/zeus/miniconda3/envs/cloudspace/lib/python3.10/site-packages/wandb/sdk/lib/sock_client.py", line 126, in _sendall_with_error_handle
    sent = self._sock.send(data)
BrokenPipeError: [Errno 32] Broken pipe
2025-07-19 00:18:55,963 ERROR   MainThread:37156 [redirect.py:_on_write():664] [all runs] error in stderr callback
Traceback (most recent call last):
  File "/home/zeus/miniconda3/envs/cloudspace/lib/python3.10/site-packages/wandb/sdk/lib/redirect.py", line 662, in _on_write
    cb(written_data)
  File "/home/zeus/miniconda3/envs/cloudspace/lib/python3.10/site-packages/wandb/sdk/wandb_run.py", line 2385, in <lambda>
    lambda data: self._console_raw_callback("stderr", data),
  File "/home/zeus/miniconda3/envs/cloudspace/lib/python3.10/site-packages/wandb/sdk/wandb_run.py", line 398, in wrapper
    return func(self, *args, **kwargs)
  File "/home/zeus/miniconda3/envs/cloudspace/lib/python3.10/site-packages/wandb/sdk/wandb_run.py", line 456, in wrapper_fn
    return func(self, *args, **kwargs)
  File "/home/zeus/miniconda3/envs/cloudspace/lib/python3.10/site-packages/wandb/sdk/wandb_run.py", line 1566, in _console_raw_callback
    self._backend.interface.publish_output_raw(name, data)
  File "/home/zeus/miniconda3/envs/cloudspace/lib/python3.10/site-packages/wandb/sdk/interface/interface.py", line 771, in publish_output_raw
    self._publish_output_raw(o)
  File "/home/zeus/miniconda3/envs/cloudspace/lib/python3.10/site-packages/wandb/sdk/interface/interface_shared.py", line 38, in _publish_output_raw
    self._publish(rec)
  File "/home/zeus/miniconda3/envs/cloudspace/lib/python3.10/site-packages/wandb/sdk/interface/interface_sock.py", line 39, in _publish
    self._sock_client.send_record_publish(record)
  File "/home/zeus/miniconda3/envs/cloudspace/lib/python3.10/site-packages/wandb/sdk/lib/sock_client.py", line 170, in send_record_publish
    self.send_server_request(server_req)
  File "/home/zeus/miniconda3/envs/cloudspace/lib/python3.10/site-packages/wandb/sdk/lib/sock_client.py", line 150, in send_server_request
    self._send_message(msg)
  File "/home/zeus/miniconda3/envs/cloudspace/lib/python3.10/site-packages/wandb/sdk/lib/sock_client.py", line 147, in _send_message
    self._sendall_with_error_handle(header + data)
  File "/home/zeus/miniconda3/envs/cloudspace/lib/python3.10/site-packages/wandb/sdk/lib/sock_client.py", line 126, in _sendall_with_error_handle
    sent = self._sock.send(data)
BrokenPipeError: [Errno 32] Broken pipe
2025-07-19 00:18:55,963 ERROR   MainThread:37156 [redirect.py:_on_write():664] [all runs] error in stderr callback
Traceback (most recent call last):
  File "/home/zeus/miniconda3/envs/cloudspace/lib/python3.10/site-packages/wandb/sdk/lib/redirect.py", line 662, in _on_write
    cb(written_data)
  File "/home/zeus/miniconda3/envs/cloudspace/lib/python3.10/site-packages/wandb/sdk/wandb_run.py", line 2385, in <lambda>
    lambda data: self._console_raw_callback("stderr", data),
  File "/home/zeus/miniconda3/envs/cloudspace/lib/python3.10/site-packages/wandb/sdk/wandb_run.py", line 398, in wrapper
    return func(self, *args, **kwargs)
  File "/home/zeus/miniconda3/envs/cloudspace/lib/python3.10/site-packages/wandb/sdk/wandb_run.py", line 456, in wrapper_fn
    return func(self, *args, **kwargs)
  File "/home/zeus/miniconda3/envs/cloudspace/lib/python3.10/site-packages/wandb/sdk/wandb_run.py", line 1566, in _console_raw_callback
    self._backend.interface.publish_output_raw(name, data)
  File "/home/zeus/miniconda3/envs/cloudspace/lib/python3.10/site-packages/wandb/sdk/interface/interface.py", line 771, in publish_output_raw
    self._publish_output_raw(o)
  File "/home/zeus/miniconda3/envs/cloudspace/lib/python3.10/site-packages/wandb/sdk/interface/interface_shared.py", line 38, in _publish_output_raw
    self._publish(rec)
  File "/home/zeus/miniconda3/envs/cloudspace/lib/python3.10/site-packages/wandb/sdk/interface/interface_sock.py", line 39, in _publish
    self._sock_client.send_record_publish(record)
  File "/home/zeus/miniconda3/envs/cloudspace/lib/python3.10/site-packages/wandb/sdk/lib/sock_client.py", line 170, in send_record_publish
    self.send_server_request(server_req)
  File "/home/zeus/miniconda3/envs/cloudspace/lib/python3.10/site-packages/wandb/sdk/lib/sock_client.py", line 150, in send_server_request
    self._send_message(msg)
  File "/home/zeus/miniconda3/envs/cloudspace/lib/python3.10/site-packages/wandb/sdk/lib/sock_client.py", line 147, in _send_message
    self._sendall_with_error_handle(header + data)
  File "/home/zeus/miniconda3/envs/cloudspace/lib/python3.10/site-packages/wandb/sdk/lib/sock_client.py", line 126, in _sendall_with_error_handle
    sent = self._sock.send(data)
BrokenPipeError: [Errno 32] Broken pipe
2025-07-19 00:18:55,964 ERROR   MainThread:37156 [redirect.py:_on_write():664] [all runs] error in stderr callback
Traceback (most recent call last):
  File "/home/zeus/miniconda3/envs/cloudspace/lib/python3.10/site-packages/wandb/sdk/lib/redirect.py", line 662, in _on_write
    cb(written_data)
  File "/home/zeus/miniconda3/envs/cloudspace/lib/python3.10/site-packages/wandb/sdk/wandb_run.py", line 2385, in <lambda>
    lambda data: self._console_raw_callback("stderr", data),
  File "/home/zeus/miniconda3/envs/cloudspace/lib/python3.10/site-packages/wandb/sdk/wandb_run.py", line 398, in wrapper
    return func(self, *args, **kwargs)
  File "/home/zeus/miniconda3/envs/cloudspace/lib/python3.10/site-packages/wandb/sdk/wandb_run.py", line 456, in wrapper_fn
    return func(self, *args, **kwargs)
  File "/home/zeus/miniconda3/envs/cloudspace/lib/python3.10/site-packages/wandb/sdk/wandb_run.py", line 1566, in _console_raw_callback
    self._backend.interface.publish_output_raw(name, data)
  File "/home/zeus/miniconda3/envs/cloudspace/lib/python3.10/site-packages/wandb/sdk/interface/interface.py", line 771, in publish_output_raw
    self._publish_output_raw(o)
  File "/home/zeus/miniconda3/envs/cloudspace/lib/python3.10/site-packages/wandb/sdk/interface/interface_shared.py", line 38, in _publish_output_raw
    self._publish(rec)
  File "/home/zeus/miniconda3/envs/cloudspace/lib/python3.10/site-packages/wandb/sdk/interface/interface_sock.py", line 39, in _publish
    self._sock_client.send_record_publish(record)
  File "/home/zeus/miniconda3/envs/cloudspace/lib/python3.10/site-packages/wandb/sdk/lib/sock_client.py", line 170, in send_record_publish
    self.send_server_request(server_req)
  File "/home/zeus/miniconda3/envs/cloudspace/lib/python3.10/site-packages/wandb/sdk/lib/sock_client.py", line 150, in send_server_request
    self._send_message(msg)
  File "/home/zeus/miniconda3/envs/cloudspace/lib/python3.10/site-packages/wandb/sdk/lib/sock_client.py", line 147, in _send_message
    self._sendall_with_error_handle(header + data)
  File "/home/zeus/miniconda3/envs/cloudspace/lib/python3.10/site-packages/wandb/sdk/lib/sock_client.py", line 126, in _sendall_with_error_handle
    sent = self._sock.send(data)
BrokenPipeError: [Errno 32] Broken pipe
2025-07-19 00:18:55,964 ERROR   MainThread:37156 [redirect.py:_on_write():664] [all runs] error in stderr callback
Traceback (most recent call last):
  File "/home/zeus/miniconda3/envs/cloudspace/lib/python3.10/site-packages/wandb/sdk/lib/redirect.py", line 662, in _on_write
    cb(written_data)
  File "/home/zeus/miniconda3/envs/cloudspace/lib/python3.10/site-packages/wandb/sdk/wandb_run.py", line 2385, in <lambda>
    lambda data: self._console_raw_callback("stderr", data),
  File "/home/zeus/miniconda3/envs/cloudspace/lib/python3.10/site-packages/wandb/sdk/wandb_run.py", line 398, in wrapper
    return func(self, *args, **kwargs)
  File "/home/zeus/miniconda3/envs/cloudspace/lib/python3.10/site-packages/wandb/sdk/wandb_run.py", line 456, in wrapper_fn
    return func(self, *args, **kwargs)
  File "/home/zeus/miniconda3/envs/cloudspace/lib/python3.10/site-packages/wandb/sdk/wandb_run.py", line 1566, in _console_raw_callback
    self._backend.interface.publish_output_raw(name, data)
  File "/home/zeus/miniconda3/envs/cloudspace/lib/python3.10/site-packages/wandb/sdk/interface/interface.py", line 771, in publish_output_raw
    self._publish_output_raw(o)
  File "/home/zeus/miniconda3/envs/cloudspace/lib/python3.10/site-packages/wandb/sdk/interface/interface_shared.py", line 38, in _publish_output_raw
    self._publish(rec)
  File "/home/zeus/miniconda3/envs/cloudspace/lib/python3.10/site-packages/wandb/sdk/interface/interface_sock.py", line 39, in _publish
    self._sock_client.send_record_publish(record)
  File "/home/zeus/miniconda3/envs/cloudspace/lib/python3.10/site-packages/wandb/sdk/lib/sock_client.py", line 170, in send_record_publish
    self.send_server_request(server_req)
  File "/home/zeus/miniconda3/envs/cloudspace/lib/python3.10/site-packages/wandb/sdk/lib/sock_client.py", line 150, in send_server_request
    self._send_message(msg)
  File "/home/zeus/miniconda3/envs/cloudspace/lib/python3.10/site-packages/wandb/sdk/lib/sock_client.py", line 147, in _send_message
    self._sendall_with_error_handle(header + data)
  File "/home/zeus/miniconda3/envs/cloudspace/lib/python3.10/site-packages/wandb/sdk/lib/sock_client.py", line 126, in _sendall_with_error_handle
    sent = self._sock.send(data)
BrokenPipeError: [Errno 32] Broken pipe
2025-07-19 00:18:56,681 ERROR   MainThread:37156 [redirect.py:_on_write():664] [all runs] error in stderr callback
Traceback (most recent call last):
  File "/home/zeus/miniconda3/envs/cloudspace/lib/python3.10/site-packages/wandb/sdk/lib/redirect.py", line 662, in _on_write
    cb(written_data)
  File "/home/zeus/miniconda3/envs/cloudspace/lib/python3.10/site-packages/wandb/sdk/wandb_run.py", line 2385, in <lambda>
    lambda data: self._console_raw_callback("stderr", data),
  File "/home/zeus/miniconda3/envs/cloudspace/lib/python3.10/site-packages/wandb/sdk/wandb_run.py", line 398, in wrapper
    return func(self, *args, **kwargs)
  File "/home/zeus/miniconda3/envs/cloudspace/lib/python3.10/site-packages/wandb/sdk/wandb_run.py", line 456, in wrapper_fn
    return func(self, *args, **kwargs)
  File "/home/zeus/miniconda3/envs/cloudspace/lib/python3.10/site-packages/wandb/sdk/wandb_run.py", line 1566, in _console_raw_callback
    self._backend.interface.publish_output_raw(name, data)
  File "/home/zeus/miniconda3/envs/cloudspace/lib/python3.10/site-packages/wandb/sdk/interface/interface.py", line 771, in publish_output_raw
    self._publish_output_raw(o)
  File "/home/zeus/miniconda3/envs/cloudspace/lib/python3.10/site-packages/wandb/sdk/interface/interface_shared.py", line 38, in _publish_output_raw
    self._publish(rec)
  File "/home/zeus/miniconda3/envs/cloudspace/lib/python3.10/site-packages/wandb/sdk/interface/interface_sock.py", line 39, in _publish
    self._sock_client.send_record_publish(record)
  File "/home/zeus/miniconda3/envs/cloudspace/lib/python3.10/site-packages/wandb/sdk/lib/sock_client.py", line 170, in send_record_publish
    self.send_server_request(server_req)
  File "/home/zeus/miniconda3/envs/cloudspace/lib/python3.10/site-packages/wandb/sdk/lib/sock_client.py", line 150, in send_server_request
    self._send_message(msg)
  File "/home/zeus/miniconda3/envs/cloudspace/lib/python3.10/site-packages/wandb/sdk/lib/sock_client.py", line 147, in _send_message
    self._sendall_with_error_handle(header + data)
  File "/home/zeus/miniconda3/envs/cloudspace/lib/python3.10/site-packages/wandb/sdk/lib/sock_client.py", line 126, in _sendall_with_error_handle
    sent = self._sock.send(data)
BrokenPipeError: [Errno 32] Broken pipe
2025-07-19 00:18:56,682 ERROR   MainThread:37156 [redirect.py:_on_write():664] [all runs] error in stderr callback
Traceback (most recent call last):
  File "/home/zeus/miniconda3/envs/cloudspace/lib/python3.10/site-packages/wandb/sdk/lib/redirect.py", line 662, in _on_write
    cb(written_data)
  File "/home/zeus/miniconda3/envs/cloudspace/lib/python3.10/site-packages/wandb/sdk/wandb_run.py", line 2385, in <lambda>
    lambda data: self._console_raw_callback("stderr", data),
  File "/home/zeus/miniconda3/envs/cloudspace/lib/python3.10/site-packages/wandb/sdk/wandb_run.py", line 398, in wrapper
    return func(self, *args, **kwargs)
  File "/home/zeus/miniconda3/envs/cloudspace/lib/python3.10/site-packages/wandb/sdk/wandb_run.py", line 456, in wrapper_fn
    return func(self, *args, **kwargs)
  File "/home/zeus/miniconda3/envs/cloudspace/lib/python3.10/site-packages/wandb/sdk/wandb_run.py", line 1566, in _console_raw_callback
    self._backend.interface.publish_output_raw(name, data)
  File "/home/zeus/miniconda3/envs/cloudspace/lib/python3.10/site-packages/wandb/sdk/interface/interface.py", line 771, in publish_output_raw
    self._publish_output_raw(o)
  File "/home/zeus/miniconda3/envs/cloudspace/lib/python3.10/site-packages/wandb/sdk/interface/interface_shared.py", line 38, in _publish_output_raw
    self._publish(rec)
  File "/home/zeus/miniconda3/envs/cloudspace/lib/python3.10/site-packages/wandb/sdk/interface/interface_sock.py", line 39, in _publish
    self._sock_client.send_record_publish(record)
  File "/home/zeus/miniconda3/envs/cloudspace/lib/python3.10/site-packages/wandb/sdk/lib/sock_client.py", line 170, in send_record_publish
    self.send_server_request(server_req)
  File "/home/zeus/miniconda3/envs/cloudspace/lib/python3.10/site-packages/wandb/sdk/lib/sock_client.py", line 150, in send_server_request
    self._send_message(msg)
  File "/home/zeus/miniconda3/envs/cloudspace/lib/python3.10/site-packages/wandb/sdk/lib/sock_client.py", line 147, in _send_message
    self._sendall_with_error_handle(header + data)
  File "/home/zeus/miniconda3/envs/cloudspace/lib/python3.10/site-packages/wandb/sdk/lib/sock_client.py", line 126, in _sendall_with_error_handle
    sent = self._sock.send(data)
BrokenPipeError: [Errno 32] Broken pipe
2025-07-19 00:18:56,682 ERROR   MainThread:37156 [redirect.py:_on_write():664] [all runs] error in stderr callback
Traceback (most recent call last):
  File "/home/zeus/miniconda3/envs/cloudspace/lib/python3.10/site-packages/wandb/sdk/lib/redirect.py", line 662, in _on_write
    cb(written_data)
  File "/home/zeus/miniconda3/envs/cloudspace/lib/python3.10/site-packages/wandb/sdk/wandb_run.py", line 2385, in <lambda>
    lambda data: self._console_raw_callback("stderr", data),
  File "/home/zeus/miniconda3/envs/cloudspace/lib/python3.10/site-packages/wandb/sdk/wandb_run.py", line 398, in wrapper
    return func(self, *args, **kwargs)
  File "/home/zeus/miniconda3/envs/cloudspace/lib/python3.10/site-packages/wandb/sdk/wandb_run.py", line 456, in wrapper_fn
    return func(self, *args, **kwargs)
  File "/home/zeus/miniconda3/envs/cloudspace/lib/python3.10/site-packages/wandb/sdk/wandb_run.py", line 1566, in _console_raw_callback
    self._backend.interface.publish_output_raw(name, data)
  File "/home/zeus/miniconda3/envs/cloudspace/lib/python3.10/site-packages/wandb/sdk/interface/interface.py", line 771, in publish_output_raw
    self._publish_output_raw(o)
  File "/home/zeus/miniconda3/envs/cloudspace/lib/python3.10/site-packages/wandb/sdk/interface/interface_shared.py", line 38, in _publish_output_raw
    self._publish(rec)
  File "/home/zeus/miniconda3/envs/cloudspace/lib/python3.10/site-packages/wandb/sdk/interface/interface_sock.py", line 39, in _publish
    self._sock_client.send_record_publish(record)
  File "/home/zeus/miniconda3/envs/cloudspace/lib/python3.10/site-packages/wandb/sdk/lib/sock_client.py", line 170, in send_record_publish
    self.send_server_request(server_req)
  File "/home/zeus/miniconda3/envs/cloudspace/lib/python3.10/site-packages/wandb/sdk/lib/sock_client.py", line 150, in send_server_request
    self._send_message(msg)
  File "/home/zeus/miniconda3/envs/cloudspace/lib/python3.10/site-packages/wandb/sdk/lib/sock_client.py", line 147, in _send_message
    self._sendall_with_error_handle(header + data)
  File "/home/zeus/miniconda3/envs/cloudspace/lib/python3.10/site-packages/wandb/sdk/lib/sock_client.py", line 126, in _sendall_with_error_handle
    sent = self._sock.send(data)
BrokenPipeError: [Errno 32] Broken pipe
2025-07-19 00:18:56,683 ERROR   MainThread:37156 [redirect.py:_on_write():664] [all runs] error in stderr callback
Traceback (most recent call last):
  File "/home/zeus/miniconda3/envs/cloudspace/lib/python3.10/site-packages/wandb/sdk/lib/redirect.py", line 662, in _on_write
    cb(written_data)
  File "/home/zeus/miniconda3/envs/cloudspace/lib/python3.10/site-packages/wandb/sdk/wandb_run.py", line 2385, in <lambda>
    lambda data: self._console_raw_callback("stderr", data),
  File "/home/zeus/miniconda3/envs/cloudspace/lib/python3.10/site-packages/wandb/sdk/wandb_run.py", line 398, in wrapper
    return func(self, *args, **kwargs)
  File "/home/zeus/miniconda3/envs/cloudspace/lib/python3.10/site-packages/wandb/sdk/wandb_run.py", line 456, in wrapper_fn
    return func(self, *args, **kwargs)
  File "/home/zeus/miniconda3/envs/cloudspace/lib/python3.10/site-packages/wandb/sdk/wandb_run.py", line 1566, in _console_raw_callback
    self._backend.interface.publish_output_raw(name, data)
  File "/home/zeus/miniconda3/envs/cloudspace/lib/python3.10/site-packages/wandb/sdk/interface/interface.py", line 771, in publish_output_raw
    self._publish_output_raw(o)
  File "/home/zeus/miniconda3/envs/cloudspace/lib/python3.10/site-packages/wandb/sdk/interface/interface_shared.py", line 38, in _publish_output_raw
    self._publish(rec)
  File "/home/zeus/miniconda3/envs/cloudspace/lib/python3.10/site-packages/wandb/sdk/interface/interface_sock.py", line 39, in _publish
    self._sock_client.send_record_publish(record)
  File "/home/zeus/miniconda3/envs/cloudspace/lib/python3.10/site-packages/wandb/sdk/lib/sock_client.py", line 170, in send_record_publish
    self.send_server_request(server_req)
  File "/home/zeus/miniconda3/envs/cloudspace/lib/python3.10/site-packages/wandb/sdk/lib/sock_client.py", line 150, in send_server_request
    self._send_message(msg)
  File "/home/zeus/miniconda3/envs/cloudspace/lib/python3.10/site-packages/wandb/sdk/lib/sock_client.py", line 147, in _send_message
    self._sendall_with_error_handle(header + data)
  File "/home/zeus/miniconda3/envs/cloudspace/lib/python3.10/site-packages/wandb/sdk/lib/sock_client.py", line 126, in _sendall_with_error_handle
    sent = self._sock.send(data)
BrokenPipeError: [Errno 32] Broken pipe
2025-07-19 00:18:56,683 ERROR   MainThread:37156 [redirect.py:_on_write():664] [all runs] error in stderr callback
Traceback (most recent call last):
  File "/home/zeus/miniconda3/envs/cloudspace/lib/python3.10/site-packages/wandb/sdk/lib/redirect.py", line 662, in _on_write
    cb(written_data)
  File "/home/zeus/miniconda3/envs/cloudspace/lib/python3.10/site-packages/wandb/sdk/wandb_run.py", line 2385, in <lambda>
    lambda data: self._console_raw_callback("stderr", data),
  File "/home/zeus/miniconda3/envs/cloudspace/lib/python3.10/site-packages/wandb/sdk/wandb_run.py", line 398, in wrapper
    return func(self, *args, **kwargs)
  File "/home/zeus/miniconda3/envs/cloudspace/lib/python3.10/site-packages/wandb/sdk/wandb_run.py", line 456, in wrapper_fn
    return func(self, *args, **kwargs)
  File "/home/zeus/miniconda3/envs/cloudspace/lib/python3.10/site-packages/wandb/sdk/wandb_run.py", line 1566, in _console_raw_callback
    self._backend.interface.publish_output_raw(name, data)
  File "/home/zeus/miniconda3/envs/cloudspace/lib/python3.10/site-packages/wandb/sdk/interface/interface.py", line 771, in publish_output_raw
    self._publish_output_raw(o)
  File "/home/zeus/miniconda3/envs/cloudspace/lib/python3.10/site-packages/wandb/sdk/interface/interface_shared.py", line 38, in _publish_output_raw
    self._publish(rec)
  File "/home/zeus/miniconda3/envs/cloudspace/lib/python3.10/site-packages/wandb/sdk/interface/interface_sock.py", line 39, in _publish
    self._sock_client.send_record_publish(record)
  File "/home/zeus/miniconda3/envs/cloudspace/lib/python3.10/site-packages/wandb/sdk/lib/sock_client.py", line 170, in send_record_publish
    self.send_server_request(server_req)
  File "/home/zeus/miniconda3/envs/cloudspace/lib/python3.10/site-packages/wandb/sdk/lib/sock_client.py", line 150, in send_server_request
    self._send_message(msg)
  File "/home/zeus/miniconda3/envs/cloudspace/lib/python3.10/site-packages/wandb/sdk/lib/sock_client.py", line 147, in _send_message
    self._sendall_with_error_handle(header + data)
  File "/home/zeus/miniconda3/envs/cloudspace/lib/python3.10/site-packages/wandb/sdk/lib/sock_client.py", line 126, in _sendall_with_error_handle
    sent = self._sock.send(data)
BrokenPipeError: [Errno 32] Broken pipe
2025-07-19 00:18:56,684 ERROR   MainThread:37156 [redirect.py:_on_write():664] [all runs] error in stderr callback
Traceback (most recent call last):
  File "/home/zeus/miniconda3/envs/cloudspace/lib/python3.10/site-packages/wandb/sdk/lib/redirect.py", line 662, in _on_write
    cb(written_data)
  File "/home/zeus/miniconda3/envs/cloudspace/lib/python3.10/site-packages/wandb/sdk/wandb_run.py", line 2385, in <lambda>
    lambda data: self._console_raw_callback("stderr", data),
  File "/home/zeus/miniconda3/envs/cloudspace/lib/python3.10/site-packages/wandb/sdk/wandb_run.py", line 398, in wrapper
    return func(self, *args, **kwargs)
  File "/home/zeus/miniconda3/envs/cloudspace/lib/python3.10/site-packages/wandb/sdk/wandb_run.py", line 456, in wrapper_fn
    return func(self, *args, **kwargs)
  File "/home/zeus/miniconda3/envs/cloudspace/lib/python3.10/site-packages/wandb/sdk/wandb_run.py", line 1566, in _console_raw_callback
    self._backend.interface.publish_output_raw(name, data)
  File "/home/zeus/miniconda3/envs/cloudspace/lib/python3.10/site-packages/wandb/sdk/interface/interface.py", line 771, in publish_output_raw
    self._publish_output_raw(o)
  File "/home/zeus/miniconda3/envs/cloudspace/lib/python3.10/site-packages/wandb/sdk/interface/interface_shared.py", line 38, in _publish_output_raw
    self._publish(rec)
  File "/home/zeus/miniconda3/envs/cloudspace/lib/python3.10/site-packages/wandb/sdk/interface/interface_sock.py", line 39, in _publish
    self._sock_client.send_record_publish(record)
  File "/home/zeus/miniconda3/envs/cloudspace/lib/python3.10/site-packages/wandb/sdk/lib/sock_client.py", line 170, in send_record_publish
    self.send_server_request(server_req)
  File "/home/zeus/miniconda3/envs/cloudspace/lib/python3.10/site-packages/wandb/sdk/lib/sock_client.py", line 150, in send_server_request
    self._send_message(msg)
  File "/home/zeus/miniconda3/envs/cloudspace/lib/python3.10/site-packages/wandb/sdk/lib/sock_client.py", line 147, in _send_message
    self._sendall_with_error_handle(header + data)
  File "/home/zeus/miniconda3/envs/cloudspace/lib/python3.10/site-packages/wandb/sdk/lib/sock_client.py", line 126, in _sendall_with_error_handle
    sent = self._sock.send(data)
BrokenPipeError: [Errno 32] Broken pipe
2025-07-19 00:18:56,684 ERROR   MainThread:37156 [redirect.py:_on_write():664] [all runs] error in stderr callback
Traceback (most recent call last):
  File "/home/zeus/miniconda3/envs/cloudspace/lib/python3.10/site-packages/wandb/sdk/lib/redirect.py", line 662, in _on_write
    cb(written_data)
  File "/home/zeus/miniconda3/envs/cloudspace/lib/python3.10/site-packages/wandb/sdk/wandb_run.py", line 2385, in <lambda>
    lambda data: self._console_raw_callback("stderr", data),
  File "/home/zeus/miniconda3/envs/cloudspace/lib/python3.10/site-packages/wandb/sdk/wandb_run.py", line 398, in wrapper
    return func(self, *args, **kwargs)
  File "/home/zeus/miniconda3/envs/cloudspace/lib/python3.10/site-packages/wandb/sdk/wandb_run.py", line 456, in wrapper_fn
    return func(self, *args, **kwargs)
  File "/home/zeus/miniconda3/envs/cloudspace/lib/python3.10/site-packages/wandb/sdk/wandb_run.py", line 1566, in _console_raw_callback
    self._backend.interface.publish_output_raw(name, data)
  File "/home/zeus/miniconda3/envs/cloudspace/lib/python3.10/site-packages/wandb/sdk/interface/interface.py", line 771, in publish_output_raw
    self._publish_output_raw(o)
  File "/home/zeus/miniconda3/envs/cloudspace/lib/python3.10/site-packages/wandb/sdk/interface/interface_shared.py", line 38, in _publish_output_raw
    self._publish(rec)
  File "/home/zeus/miniconda3/envs/cloudspace/lib/python3.10/site-packages/wandb/sdk/interface/interface_sock.py", line 39, in _publish
    self._sock_client.send_record_publish(record)
  File "/home/zeus/miniconda3/envs/cloudspace/lib/python3.10/site-packages/wandb/sdk/lib/sock_client.py", line 170, in send_record_publish
    self.send_server_request(server_req)
  File "/home/zeus/miniconda3/envs/cloudspace/lib/python3.10/site-packages/wandb/sdk/lib/sock_client.py", line 150, in send_server_request
    self._send_message(msg)
  File "/home/zeus/miniconda3/envs/cloudspace/lib/python3.10/site-packages/wandb/sdk/lib/sock_client.py", line 147, in _send_message
    self._sendall_with_error_handle(header + data)
  File "/home/zeus/miniconda3/envs/cloudspace/lib/python3.10/site-packages/wandb/sdk/lib/sock_client.py", line 126, in _sendall_with_error_handle
    sent = self._sock.send(data)
BrokenPipeError: [Errno 32] Broken pipe
2025-07-19 00:18:56,685 ERROR   MainThread:37156 [redirect.py:_on_write():664] [all runs] error in stderr callback
Traceback (most recent call last):
  File "/home/zeus/miniconda3/envs/cloudspace/lib/python3.10/site-packages/wandb/sdk/lib/redirect.py", line 662, in _on_write
    cb(written_data)
  File "/home/zeus/miniconda3/envs/cloudspace/lib/python3.10/site-packages/wandb/sdk/wandb_run.py", line 2385, in <lambda>
    lambda data: self._console_raw_callback("stderr", data),
  File "/home/zeus/miniconda3/envs/cloudspace/lib/python3.10/site-packages/wandb/sdk/wandb_run.py", line 398, in wrapper
    return func(self, *args, **kwargs)
  File "/home/zeus/miniconda3/envs/cloudspace/lib/python3.10/site-packages/wandb/sdk/wandb_run.py", line 456, in wrapper_fn
    return func(self, *args, **kwargs)
  File "/home/zeus/miniconda3/envs/cloudspace/lib/python3.10/site-packages/wandb/sdk/wandb_run.py", line 1566, in _console_raw_callback
    self._backend.interface.publish_output_raw(name, data)
  File "/home/zeus/miniconda3/envs/cloudspace/lib/python3.10/site-packages/wandb/sdk/interface/interface.py", line 771, in publish_output_raw
    self._publish_output_raw(o)
  File "/home/zeus/miniconda3/envs/cloudspace/lib/python3.10/site-packages/wandb/sdk/interface/interface_shared.py", line 38, in _publish_output_raw
    self._publish(rec)
  File "/home/zeus/miniconda3/envs/cloudspace/lib/python3.10/site-packages/wandb/sdk/interface/interface_sock.py", line 39, in _publish
    self._sock_client.send_record_publish(record)
  File "/home/zeus/miniconda3/envs/cloudspace/lib/python3.10/site-packages/wandb/sdk/lib/sock_client.py", line 170, in send_record_publish
    self.send_server_request(server_req)
  File "/home/zeus/miniconda3/envs/cloudspace/lib/python3.10/site-packages/wandb/sdk/lib/sock_client.py", line 150, in send_server_request
    self._send_message(msg)
  File "/home/zeus/miniconda3/envs/cloudspace/lib/python3.10/site-packages/wandb/sdk/lib/sock_client.py", line 147, in _send_message
    self._sendall_with_error_handle(header + data)
  File "/home/zeus/miniconda3/envs/cloudspace/lib/python3.10/site-packages/wandb/sdk/lib/sock_client.py", line 126, in _sendall_with_error_handle
    sent = self._sock.send(data)
BrokenPipeError: [Errno 32] Broken pipe
2025-07-19 00:18:56,685 ERROR   MainThread:37156 [redirect.py:_on_write():664] [all runs] error in stderr callback
Traceback (most recent call last):
  File "/home/zeus/miniconda3/envs/cloudspace/lib/python3.10/site-packages/wandb/sdk/lib/redirect.py", line 662, in _on_write
    cb(written_data)
  File "/home/zeus/miniconda3/envs/cloudspace/lib/python3.10/site-packages/wandb/sdk/wandb_run.py", line 2385, in <lambda>
    lambda data: self._console_raw_callback("stderr", data),
  File "/home/zeus/miniconda3/envs/cloudspace/lib/python3.10/site-packages/wandb/sdk/wandb_run.py", line 398, in wrapper
    return func(self, *args, **kwargs)
  File "/home/zeus/miniconda3/envs/cloudspace/lib/python3.10/site-packages/wandb/sdk/wandb_run.py", line 456, in wrapper_fn
    return func(self, *args, **kwargs)
  File "/home/zeus/miniconda3/envs/cloudspace/lib/python3.10/site-packages/wandb/sdk/wandb_run.py", line 1566, in _console_raw_callback
    self._backend.interface.publish_output_raw(name, data)
  File "/home/zeus/miniconda3/envs/cloudspace/lib/python3.10/site-packages/wandb/sdk/interface/interface.py", line 771, in publish_output_raw
    self._publish_output_raw(o)
  File "/home/zeus/miniconda3/envs/cloudspace/lib/python3.10/site-packages/wandb/sdk/interface/interface_shared.py", line 38, in _publish_output_raw
    self._publish(rec)
  File "/home/zeus/miniconda3/envs/cloudspace/lib/python3.10/site-packages/wandb/sdk/interface/interface_sock.py", line 39, in _publish
    self._sock_client.send_record_publish(record)
  File "/home/zeus/miniconda3/envs/cloudspace/lib/python3.10/site-packages/wandb/sdk/lib/sock_client.py", line 170, in send_record_publish
    self.send_server_request(server_req)
  File "/home/zeus/miniconda3/envs/cloudspace/lib/python3.10/site-packages/wandb/sdk/lib/sock_client.py", line 150, in send_server_request
    self._send_message(msg)
  File "/home/zeus/miniconda3/envs/cloudspace/lib/python3.10/site-packages/wandb/sdk/lib/sock_client.py", line 147, in _send_message
    self._sendall_with_error_handle(header + data)
  File "/home/zeus/miniconda3/envs/cloudspace/lib/python3.10/site-packages/wandb/sdk/lib/sock_client.py", line 126, in _sendall_with_error_handle
    sent = self._sock.send(data)
BrokenPipeError: [Errno 32] Broken pipe
2025-07-19 00:18:56,686 ERROR   MainThread:37156 [redirect.py:_on_write():664] [all runs] error in stderr callback
Traceback (most recent call last):
  File "/home/zeus/miniconda3/envs/cloudspace/lib/python3.10/site-packages/wandb/sdk/lib/redirect.py", line 662, in _on_write
    cb(written_data)
  File "/home/zeus/miniconda3/envs/cloudspace/lib/python3.10/site-packages/wandb/sdk/wandb_run.py", line 2385, in <lambda>
    lambda data: self._console_raw_callback("stderr", data),
  File "/home/zeus/miniconda3/envs/cloudspace/lib/python3.10/site-packages/wandb/sdk/wandb_run.py", line 398, in wrapper
    return func(self, *args, **kwargs)
  File "/home/zeus/miniconda3/envs/cloudspace/lib/python3.10/site-packages/wandb/sdk/wandb_run.py", line 456, in wrapper_fn
    return func(self, *args, **kwargs)
  File "/home/zeus/miniconda3/envs/cloudspace/lib/python3.10/site-packages/wandb/sdk/wandb_run.py", line 1566, in _console_raw_callback
    self._backend.interface.publish_output_raw(name, data)
  File "/home/zeus/miniconda3/envs/cloudspace/lib/python3.10/site-packages/wandb/sdk/interface/interface.py", line 771, in publish_output_raw
    self._publish_output_raw(o)
  File "/home/zeus/miniconda3/envs/cloudspace/lib/python3.10/site-packages/wandb/sdk/interface/interface_shared.py", line 38, in _publish_output_raw
    self._publish(rec)
  File "/home/zeus/miniconda3/envs/cloudspace/lib/python3.10/site-packages/wandb/sdk/interface/interface_sock.py", line 39, in _publish
    self._sock_client.send_record_publish(record)
  File "/home/zeus/miniconda3/envs/cloudspace/lib/python3.10/site-packages/wandb/sdk/lib/sock_client.py", line 170, in send_record_publish
    self.send_server_request(server_req)
  File "/home/zeus/miniconda3/envs/cloudspace/lib/python3.10/site-packages/wandb/sdk/lib/sock_client.py", line 150, in send_server_request
    self._send_message(msg)
  File "/home/zeus/miniconda3/envs/cloudspace/lib/python3.10/site-packages/wandb/sdk/lib/sock_client.py", line 147, in _send_message
    self._sendall_with_error_handle(header + data)
  File "/home/zeus/miniconda3/envs/cloudspace/lib/python3.10/site-packages/wandb/sdk/lib/sock_client.py", line 126, in _sendall_with_error_handle
    sent = self._sock.send(data)
BrokenPipeError: [Errno 32] Broken pipe
2025-07-19 00:18:56,686 ERROR   MainThread:37156 [redirect.py:_on_write():664] [all runs] error in stderr callback
Traceback (most recent call last):
  File "/home/zeus/miniconda3/envs/cloudspace/lib/python3.10/site-packages/wandb/sdk/lib/redirect.py", line 662, in _on_write
    cb(written_data)
  File "/home/zeus/miniconda3/envs/cloudspace/lib/python3.10/site-packages/wandb/sdk/wandb_run.py", line 2385, in <lambda>
    lambda data: self._console_raw_callback("stderr", data),
  File "/home/zeus/miniconda3/envs/cloudspace/lib/python3.10/site-packages/wandb/sdk/wandb_run.py", line 398, in wrapper
    return func(self, *args, **kwargs)
  File "/home/zeus/miniconda3/envs/cloudspace/lib/python3.10/site-packages/wandb/sdk/wandb_run.py", line 456, in wrapper_fn
    return func(self, *args, **kwargs)
  File "/home/zeus/miniconda3/envs/cloudspace/lib/python3.10/site-packages/wandb/sdk/wandb_run.py", line 1566, in _console_raw_callback
    self._backend.interface.publish_output_raw(name, data)
  File "/home/zeus/miniconda3/envs/cloudspace/lib/python3.10/site-packages/wandb/sdk/interface/interface.py", line 771, in publish_output_raw
    self._publish_output_raw(o)
  File "/home/zeus/miniconda3/envs/cloudspace/lib/python3.10/site-packages/wandb/sdk/interface/interface_shared.py", line 38, in _publish_output_raw
    self._publish(rec)
  File "/home/zeus/miniconda3/envs/cloudspace/lib/python3.10/site-packages/wandb/sdk/interface/interface_sock.py", line 39, in _publish
    self._sock_client.send_record_publish(record)
  File "/home/zeus/miniconda3/envs/cloudspace/lib/python3.10/site-packages/wandb/sdk/lib/sock_client.py", line 170, in send_record_publish
    self.send_server_request(server_req)
  File "/home/zeus/miniconda3/envs/cloudspace/lib/python3.10/site-packages/wandb/sdk/lib/sock_client.py", line 150, in send_server_request
    self._send_message(msg)
  File "/home/zeus/miniconda3/envs/cloudspace/lib/python3.10/site-packages/wandb/sdk/lib/sock_client.py", line 147, in _send_message
    self._sendall_with_error_handle(header + data)
  File "/home/zeus/miniconda3/envs/cloudspace/lib/python3.10/site-packages/wandb/sdk/lib/sock_client.py", line 126, in _sendall_with_error_handle
    sent = self._sock.send(data)
BrokenPipeError: [Errno 32] Broken pipe
2025-07-19 00:18:56,687 ERROR   MainThread:37156 [redirect.py:_on_write():664] [all runs] error in stderr callback
Traceback (most recent call last):
  File "/home/zeus/miniconda3/envs/cloudspace/lib/python3.10/site-packages/wandb/sdk/lib/redirect.py", line 662, in _on_write
    cb(written_data)
  File "/home/zeus/miniconda3/envs/cloudspace/lib/python3.10/site-packages/wandb/sdk/wandb_run.py", line 2385, in <lambda>
    lambda data: self._console_raw_callback("stderr", data),
  File "/home/zeus/miniconda3/envs/cloudspace/lib/python3.10/site-packages/wandb/sdk/wandb_run.py", line 398, in wrapper
    return func(self, *args, **kwargs)
  File "/home/zeus/miniconda3/envs/cloudspace/lib/python3.10/site-packages/wandb/sdk/wandb_run.py", line 456, in wrapper_fn
    return func(self, *args, **kwargs)
  File "/home/zeus/miniconda3/envs/cloudspace/lib/python3.10/site-packages/wandb/sdk/wandb_run.py", line 1566, in _console_raw_callback
    self._backend.interface.publish_output_raw(name, data)
  File "/home/zeus/miniconda3/envs/cloudspace/lib/python3.10/site-packages/wandb/sdk/interface/interface.py", line 771, in publish_output_raw
    self._publish_output_raw(o)
  File "/home/zeus/miniconda3/envs/cloudspace/lib/python3.10/site-packages/wandb/sdk/interface/interface_shared.py", line 38, in _publish_output_raw
    self._publish(rec)
  File "/home/zeus/miniconda3/envs/cloudspace/lib/python3.10/site-packages/wandb/sdk/interface/interface_sock.py", line 39, in _publish
    self._sock_client.send_record_publish(record)
  File "/home/zeus/miniconda3/envs/cloudspace/lib/python3.10/site-packages/wandb/sdk/lib/sock_client.py", line 170, in send_record_publish
    self.send_server_request(server_req)
  File "/home/zeus/miniconda3/envs/cloudspace/lib/python3.10/site-packages/wandb/sdk/lib/sock_client.py", line 150, in send_server_request
    self._send_message(msg)
  File "/home/zeus/miniconda3/envs/cloudspace/lib/python3.10/site-packages/wandb/sdk/lib/sock_client.py", line 147, in _send_message
    self._sendall_with_error_handle(header + data)
  File "/home/zeus/miniconda3/envs/cloudspace/lib/python3.10/site-packages/wandb/sdk/lib/sock_client.py", line 126, in _sendall_with_error_handle
    sent = self._sock.send(data)
BrokenPipeError: [Errno 32] Broken pipe
2025-07-19 00:18:56,687 ERROR   MainThread:37156 [redirect.py:_on_write():664] [all runs] error in stderr callback
Traceback (most recent call last):
  File "/home/zeus/miniconda3/envs/cloudspace/lib/python3.10/site-packages/wandb/sdk/lib/redirect.py", line 662, in _on_write
    cb(written_data)
  File "/home/zeus/miniconda3/envs/cloudspace/lib/python3.10/site-packages/wandb/sdk/wandb_run.py", line 2385, in <lambda>
    lambda data: self._console_raw_callback("stderr", data),
  File "/home/zeus/miniconda3/envs/cloudspace/lib/python3.10/site-packages/wandb/sdk/wandb_run.py", line 398, in wrapper
    return func(self, *args, **kwargs)
  File "/home/zeus/miniconda3/envs/cloudspace/lib/python3.10/site-packages/wandb/sdk/wandb_run.py", line 456, in wrapper_fn
    return func(self, *args, **kwargs)
  File "/home/zeus/miniconda3/envs/cloudspace/lib/python3.10/site-packages/wandb/sdk/wandb_run.py", line 1566, in _console_raw_callback
    self._backend.interface.publish_output_raw(name, data)
  File "/home/zeus/miniconda3/envs/cloudspace/lib/python3.10/site-packages/wandb/sdk/interface/interface.py", line 771, in publish_output_raw
    self._publish_output_raw(o)
  File "/home/zeus/miniconda3/envs/cloudspace/lib/python3.10/site-packages/wandb/sdk/interface/interface_shared.py", line 38, in _publish_output_raw
    self._publish(rec)
  File "/home/zeus/miniconda3/envs/cloudspace/lib/python3.10/site-packages/wandb/sdk/interface/interface_sock.py", line 39, in _publish
    self._sock_client.send_record_publish(record)
  File "/home/zeus/miniconda3/envs/cloudspace/lib/python3.10/site-packages/wandb/sdk/lib/sock_client.py", line 170, in send_record_publish
    self.send_server_request(server_req)
  File "/home/zeus/miniconda3/envs/cloudspace/lib/python3.10/site-packages/wandb/sdk/lib/sock_client.py", line 150, in send_server_request
    self._send_message(msg)
  File "/home/zeus/miniconda3/envs/cloudspace/lib/python3.10/site-packages/wandb/sdk/lib/sock_client.py", line 147, in _send_message
    self._sendall_with_error_handle(header + data)
  File "/home/zeus/miniconda3/envs/cloudspace/lib/python3.10/site-packages/wandb/sdk/lib/sock_client.py", line 126, in _sendall_with_error_handle
    sent = self._sock.send(data)
BrokenPipeError: [Errno 32] Broken pipe
2025-07-19 00:18:56,688 ERROR   MainThread:37156 [redirect.py:_on_write():664] [all runs] error in stderr callback
Traceback (most recent call last):
  File "/home/zeus/miniconda3/envs/cloudspace/lib/python3.10/site-packages/wandb/sdk/lib/redirect.py", line 662, in _on_write
    cb(written_data)
  File "/home/zeus/miniconda3/envs/cloudspace/lib/python3.10/site-packages/wandb/sdk/wandb_run.py", line 2385, in <lambda>
    lambda data: self._console_raw_callback("stderr", data),
  File "/home/zeus/miniconda3/envs/cloudspace/lib/python3.10/site-packages/wandb/sdk/wandb_run.py", line 398, in wrapper
    return func(self, *args, **kwargs)
  File "/home/zeus/miniconda3/envs/cloudspace/lib/python3.10/site-packages/wandb/sdk/wandb_run.py", line 456, in wrapper_fn
    return func(self, *args, **kwargs)
  File "/home/zeus/miniconda3/envs/cloudspace/lib/python3.10/site-packages/wandb/sdk/wandb_run.py", line 1566, in _console_raw_callback
    self._backend.interface.publish_output_raw(name, data)
  File "/home/zeus/miniconda3/envs/cloudspace/lib/python3.10/site-packages/wandb/sdk/interface/interface.py", line 771, in publish_output_raw
    self._publish_output_raw(o)
  File "/home/zeus/miniconda3/envs/cloudspace/lib/python3.10/site-packages/wandb/sdk/interface/interface_shared.py", line 38, in _publish_output_raw
    self._publish(rec)
  File "/home/zeus/miniconda3/envs/cloudspace/lib/python3.10/site-packages/wandb/sdk/interface/interface_sock.py", line 39, in _publish
    self._sock_client.send_record_publish(record)
  File "/home/zeus/miniconda3/envs/cloudspace/lib/python3.10/site-packages/wandb/sdk/lib/sock_client.py", line 170, in send_record_publish
    self.send_server_request(server_req)
  File "/home/zeus/miniconda3/envs/cloudspace/lib/python3.10/site-packages/wandb/sdk/lib/sock_client.py", line 150, in send_server_request
    self._send_message(msg)
  File "/home/zeus/miniconda3/envs/cloudspace/lib/python3.10/site-packages/wandb/sdk/lib/sock_client.py", line 147, in _send_message
    self._sendall_with_error_handle(header + data)
  File "/home/zeus/miniconda3/envs/cloudspace/lib/python3.10/site-packages/wandb/sdk/lib/sock_client.py", line 126, in _sendall_with_error_handle
    sent = self._sock.send(data)
BrokenPipeError: [Errno 32] Broken pipe
2025-07-19 00:18:56,689 ERROR   MainThread:37156 [redirect.py:_on_write():664] [all runs] error in stderr callback
Traceback (most recent call last):
  File "/home/zeus/miniconda3/envs/cloudspace/lib/python3.10/site-packages/wandb/sdk/lib/redirect.py", line 662, in _on_write
    cb(written_data)
  File "/home/zeus/miniconda3/envs/cloudspace/lib/python3.10/site-packages/wandb/sdk/wandb_run.py", line 2385, in <lambda>
    lambda data: self._console_raw_callback("stderr", data),
  File "/home/zeus/miniconda3/envs/cloudspace/lib/python3.10/site-packages/wandb/sdk/wandb_run.py", line 398, in wrapper
    return func(self, *args, **kwargs)
  File "/home/zeus/miniconda3/envs/cloudspace/lib/python3.10/site-packages/wandb/sdk/wandb_run.py", line 456, in wrapper_fn
    return func(self, *args, **kwargs)
  File "/home/zeus/miniconda3/envs/cloudspace/lib/python3.10/site-packages/wandb/sdk/wandb_run.py", line 1566, in _console_raw_callback
    self._backend.interface.publish_output_raw(name, data)
  File "/home/zeus/miniconda3/envs/cloudspace/lib/python3.10/site-packages/wandb/sdk/interface/interface.py", line 771, in publish_output_raw
    self._publish_output_raw(o)
  File "/home/zeus/miniconda3/envs/cloudspace/lib/python3.10/site-packages/wandb/sdk/interface/interface_shared.py", line 38, in _publish_output_raw
    self._publish(rec)
  File "/home/zeus/miniconda3/envs/cloudspace/lib/python3.10/site-packages/wandb/sdk/interface/interface_sock.py", line 39, in _publish
    self._sock_client.send_record_publish(record)
  File "/home/zeus/miniconda3/envs/cloudspace/lib/python3.10/site-packages/wandb/sdk/lib/sock_client.py", line 170, in send_record_publish
    self.send_server_request(server_req)
  File "/home/zeus/miniconda3/envs/cloudspace/lib/python3.10/site-packages/wandb/sdk/lib/sock_client.py", line 150, in send_server_request
    self._send_message(msg)
  File "/home/zeus/miniconda3/envs/cloudspace/lib/python3.10/site-packages/wandb/sdk/lib/sock_client.py", line 147, in _send_message
    self._sendall_with_error_handle(header + data)
  File "/home/zeus/miniconda3/envs/cloudspace/lib/python3.10/site-packages/wandb/sdk/lib/sock_client.py", line 126, in _sendall_with_error_handle
    sent = self._sock.send(data)
BrokenPipeError: [Errno 32] Broken pipe
2025-07-19 00:18:56,689 ERROR   MainThread:37156 [redirect.py:_on_write():664] [all runs] error in stderr callback
Traceback (most recent call last):
  File "/home/zeus/miniconda3/envs/cloudspace/lib/python3.10/site-packages/wandb/sdk/lib/redirect.py", line 662, in _on_write
    cb(written_data)
  File "/home/zeus/miniconda3/envs/cloudspace/lib/python3.10/site-packages/wandb/sdk/wandb_run.py", line 2385, in <lambda>
    lambda data: self._console_raw_callback("stderr", data),
  File "/home/zeus/miniconda3/envs/cloudspace/lib/python3.10/site-packages/wandb/sdk/wandb_run.py", line 398, in wrapper
    return func(self, *args, **kwargs)
  File "/home/zeus/miniconda3/envs/cloudspace/lib/python3.10/site-packages/wandb/sdk/wandb_run.py", line 456, in wrapper_fn
    return func(self, *args, **kwargs)
  File "/home/zeus/miniconda3/envs/cloudspace/lib/python3.10/site-packages/wandb/sdk/wandb_run.py", line 1566, in _console_raw_callback
    self._backend.interface.publish_output_raw(name, data)
  File "/home/zeus/miniconda3/envs/cloudspace/lib/python3.10/site-packages/wandb/sdk/interface/interface.py", line 771, in publish_output_raw
    self._publish_output_raw(o)
  File "/home/zeus/miniconda3/envs/cloudspace/lib/python3.10/site-packages/wandb/sdk/interface/interface_shared.py", line 38, in _publish_output_raw
    self._publish(rec)
  File "/home/zeus/miniconda3/envs/cloudspace/lib/python3.10/site-packages/wandb/sdk/interface/interface_sock.py", line 39, in _publish
    self._sock_client.send_record_publish(record)
  File "/home/zeus/miniconda3/envs/cloudspace/lib/python3.10/site-packages/wandb/sdk/lib/sock_client.py", line 170, in send_record_publish
    self.send_server_request(server_req)
  File "/home/zeus/miniconda3/envs/cloudspace/lib/python3.10/site-packages/wandb/sdk/lib/sock_client.py", line 150, in send_server_request
    self._send_message(msg)
  File "/home/zeus/miniconda3/envs/cloudspace/lib/python3.10/site-packages/wandb/sdk/lib/sock_client.py", line 147, in _send_message
    self._sendall_with_error_handle(header + data)
  File "/home/zeus/miniconda3/envs/cloudspace/lib/python3.10/site-packages/wandb/sdk/lib/sock_client.py", line 126, in _sendall_with_error_handle
    sent = self._sock.send(data)
BrokenPipeError: [Errno 32] Broken pipe
2025-07-19 00:18:56,690 ERROR   MainThread:37156 [redirect.py:_on_write():664] [all runs] error in stderr callback
Traceback (most recent call last):
  File "/home/zeus/miniconda3/envs/cloudspace/lib/python3.10/site-packages/wandb/sdk/lib/redirect.py", line 662, in _on_write
    cb(written_data)
  File "/home/zeus/miniconda3/envs/cloudspace/lib/python3.10/site-packages/wandb/sdk/wandb_run.py", line 2385, in <lambda>
    lambda data: self._console_raw_callback("stderr", data),
  File "/home/zeus/miniconda3/envs/cloudspace/lib/python3.10/site-packages/wandb/sdk/wandb_run.py", line 398, in wrapper
    return func(self, *args, **kwargs)
  File "/home/zeus/miniconda3/envs/cloudspace/lib/python3.10/site-packages/wandb/sdk/wandb_run.py", line 456, in wrapper_fn
    return func(self, *args, **kwargs)
  File "/home/zeus/miniconda3/envs/cloudspace/lib/python3.10/site-packages/wandb/sdk/wandb_run.py", line 1566, in _console_raw_callback
    self._backend.interface.publish_output_raw(name, data)
  File "/home/zeus/miniconda3/envs/cloudspace/lib/python3.10/site-packages/wandb/sdk/interface/interface.py", line 771, in publish_output_raw
    self._publish_output_raw(o)
  File "/home/zeus/miniconda3/envs/cloudspace/lib/python3.10/site-packages/wandb/sdk/interface/interface_shared.py", line 38, in _publish_output_raw
    self._publish(rec)
  File "/home/zeus/miniconda3/envs/cloudspace/lib/python3.10/site-packages/wandb/sdk/interface/interface_sock.py", line 39, in _publish
    self._sock_client.send_record_publish(record)
  File "/home/zeus/miniconda3/envs/cloudspace/lib/python3.10/site-packages/wandb/sdk/lib/sock_client.py", line 170, in send_record_publish
    self.send_server_request(server_req)
  File "/home/zeus/miniconda3/envs/cloudspace/lib/python3.10/site-packages/wandb/sdk/lib/sock_client.py", line 150, in send_server_request
    self._send_message(msg)
  File "/home/zeus/miniconda3/envs/cloudspace/lib/python3.10/site-packages/wandb/sdk/lib/sock_client.py", line 147, in _send_message
    self._sendall_with_error_handle(header + data)
  File "/home/zeus/miniconda3/envs/cloudspace/lib/python3.10/site-packages/wandb/sdk/lib/sock_client.py", line 126, in _sendall_with_error_handle
    sent = self._sock.send(data)
BrokenPipeError: [Errno 32] Broken pipe
2025-07-19 00:18:56,690 ERROR   MainThread:37156 [redirect.py:_on_write():664] [all runs] error in stderr callback
Traceback (most recent call last):
  File "/home/zeus/miniconda3/envs/cloudspace/lib/python3.10/site-packages/wandb/sdk/lib/redirect.py", line 662, in _on_write
    cb(written_data)
  File "/home/zeus/miniconda3/envs/cloudspace/lib/python3.10/site-packages/wandb/sdk/wandb_run.py", line 2385, in <lambda>
    lambda data: self._console_raw_callback("stderr", data),
  File "/home/zeus/miniconda3/envs/cloudspace/lib/python3.10/site-packages/wandb/sdk/wandb_run.py", line 398, in wrapper
    return func(self, *args, **kwargs)
  File "/home/zeus/miniconda3/envs/cloudspace/lib/python3.10/site-packages/wandb/sdk/wandb_run.py", line 456, in wrapper_fn
    return func(self, *args, **kwargs)
  File "/home/zeus/miniconda3/envs/cloudspace/lib/python3.10/site-packages/wandb/sdk/wandb_run.py", line 1566, in _console_raw_callback
    self._backend.interface.publish_output_raw(name, data)
  File "/home/zeus/miniconda3/envs/cloudspace/lib/python3.10/site-packages/wandb/sdk/interface/interface.py", line 771, in publish_output_raw
    self._publish_output_raw(o)
  File "/home/zeus/miniconda3/envs/cloudspace/lib/python3.10/site-packages/wandb/sdk/interface/interface_shared.py", line 38, in _publish_output_raw
    self._publish(rec)
  File "/home/zeus/miniconda3/envs/cloudspace/lib/python3.10/site-packages/wandb/sdk/interface/interface_sock.py", line 39, in _publish
    self._sock_client.send_record_publish(record)
  File "/home/zeus/miniconda3/envs/cloudspace/lib/python3.10/site-packages/wandb/sdk/lib/sock_client.py", line 170, in send_record_publish
    self.send_server_request(server_req)
  File "/home/zeus/miniconda3/envs/cloudspace/lib/python3.10/site-packages/wandb/sdk/lib/sock_client.py", line 150, in send_server_request
    self._send_message(msg)
  File "/home/zeus/miniconda3/envs/cloudspace/lib/python3.10/site-packages/wandb/sdk/lib/sock_client.py", line 147, in _send_message
    self._sendall_with_error_handle(header + data)
  File "/home/zeus/miniconda3/envs/cloudspace/lib/python3.10/site-packages/wandb/sdk/lib/sock_client.py", line 126, in _sendall_with_error_handle
    sent = self._sock.send(data)
BrokenPipeError: [Errno 32] Broken pipe
2025-07-19 00:18:56,691 ERROR   MainThread:37156 [redirect.py:_on_write():664] [all runs] error in stderr callback
Traceback (most recent call last):
  File "/home/zeus/miniconda3/envs/cloudspace/lib/python3.10/site-packages/wandb/sdk/lib/redirect.py", line 662, in _on_write
    cb(written_data)
  File "/home/zeus/miniconda3/envs/cloudspace/lib/python3.10/site-packages/wandb/sdk/wandb_run.py", line 2385, in <lambda>
    lambda data: self._console_raw_callback("stderr", data),
  File "/home/zeus/miniconda3/envs/cloudspace/lib/python3.10/site-packages/wandb/sdk/wandb_run.py", line 398, in wrapper
    return func(self, *args, **kwargs)
  File "/home/zeus/miniconda3/envs/cloudspace/lib/python3.10/site-packages/wandb/sdk/wandb_run.py", line 456, in wrapper_fn
    return func(self, *args, **kwargs)
  File "/home/zeus/miniconda3/envs/cloudspace/lib/python3.10/site-packages/wandb/sdk/wandb_run.py", line 1566, in _console_raw_callback
    self._backend.interface.publish_output_raw(name, data)
  File "/home/zeus/miniconda3/envs/cloudspace/lib/python3.10/site-packages/wandb/sdk/interface/interface.py", line 771, in publish_output_raw
    self._publish_output_raw(o)
  File "/home/zeus/miniconda3/envs/cloudspace/lib/python3.10/site-packages/wandb/sdk/interface/interface_shared.py", line 38, in _publish_output_raw
    self._publish(rec)
  File "/home/zeus/miniconda3/envs/cloudspace/lib/python3.10/site-packages/wandb/sdk/interface/interface_sock.py", line 39, in _publish
    self._sock_client.send_record_publish(record)
  File "/home/zeus/miniconda3/envs/cloudspace/lib/python3.10/site-packages/wandb/sdk/lib/sock_client.py", line 170, in send_record_publish
    self.send_server_request(server_req)
  File "/home/zeus/miniconda3/envs/cloudspace/lib/python3.10/site-packages/wandb/sdk/lib/sock_client.py", line 150, in send_server_request
    self._send_message(msg)
  File "/home/zeus/miniconda3/envs/cloudspace/lib/python3.10/site-packages/wandb/sdk/lib/sock_client.py", line 147, in _send_message
    self._sendall_with_error_handle(header + data)
  File "/home/zeus/miniconda3/envs/cloudspace/lib/python3.10/site-packages/wandb/sdk/lib/sock_client.py", line 126, in _sendall_with_error_handle
    sent = self._sock.send(data)
BrokenPipeError: [Errno 32] Broken pipe
2025-07-19 00:18:56,691 ERROR   MainThread:37156 [redirect.py:_on_write():664] [all runs] error in stderr callback
Traceback (most recent call last):
  File "/home/zeus/miniconda3/envs/cloudspace/lib/python3.10/site-packages/wandb/sdk/lib/redirect.py", line 662, in _on_write
    cb(written_data)
  File "/home/zeus/miniconda3/envs/cloudspace/lib/python3.10/site-packages/wandb/sdk/wandb_run.py", line 2385, in <lambda>
    lambda data: self._console_raw_callback("stderr", data),
  File "/home/zeus/miniconda3/envs/cloudspace/lib/python3.10/site-packages/wandb/sdk/wandb_run.py", line 398, in wrapper
    return func(self, *args, **kwargs)
  File "/home/zeus/miniconda3/envs/cloudspace/lib/python3.10/site-packages/wandb/sdk/wandb_run.py", line 456, in wrapper_fn
    return func(self, *args, **kwargs)
  File "/home/zeus/miniconda3/envs/cloudspace/lib/python3.10/site-packages/wandb/sdk/wandb_run.py", line 1566, in _console_raw_callback
    self._backend.interface.publish_output_raw(name, data)
  File "/home/zeus/miniconda3/envs/cloudspace/lib/python3.10/site-packages/wandb/sdk/interface/interface.py", line 771, in publish_output_raw
    self._publish_output_raw(o)
  File "/home/zeus/miniconda3/envs/cloudspace/lib/python3.10/site-packages/wandb/sdk/interface/interface_shared.py", line 38, in _publish_output_raw
    self._publish(rec)
  File "/home/zeus/miniconda3/envs/cloudspace/lib/python3.10/site-packages/wandb/sdk/interface/interface_sock.py", line 39, in _publish
    self._sock_client.send_record_publish(record)
  File "/home/zeus/miniconda3/envs/cloudspace/lib/python3.10/site-packages/wandb/sdk/lib/sock_client.py", line 170, in send_record_publish
    self.send_server_request(server_req)
  File "/home/zeus/miniconda3/envs/cloudspace/lib/python3.10/site-packages/wandb/sdk/lib/sock_client.py", line 150, in send_server_request
    self._send_message(msg)
  File "/home/zeus/miniconda3/envs/cloudspace/lib/python3.10/site-packages/wandb/sdk/lib/sock_client.py", line 147, in _send_message
    self._sendall_with_error_handle(header + data)
  File "/home/zeus/miniconda3/envs/cloudspace/lib/python3.10/site-packages/wandb/sdk/lib/sock_client.py", line 126, in _sendall_with_error_handle
    sent = self._sock.send(data)
BrokenPipeError: [Errno 32] Broken pipe
2025-07-19 00:18:56,692 ERROR   MainThread:37156 [redirect.py:_on_write():664] [all runs] error in stderr callback
Traceback (most recent call last):
  File "/home/zeus/miniconda3/envs/cloudspace/lib/python3.10/site-packages/wandb/sdk/lib/redirect.py", line 662, in _on_write
    cb(written_data)
  File "/home/zeus/miniconda3/envs/cloudspace/lib/python3.10/site-packages/wandb/sdk/wandb_run.py", line 2385, in <lambda>
    lambda data: self._console_raw_callback("stderr", data),
  File "/home/zeus/miniconda3/envs/cloudspace/lib/python3.10/site-packages/wandb/sdk/wandb_run.py", line 398, in wrapper
    return func(self, *args, **kwargs)
  File "/home/zeus/miniconda3/envs/cloudspace/lib/python3.10/site-packages/wandb/sdk/wandb_run.py", line 456, in wrapper_fn
    return func(self, *args, **kwargs)
  File "/home/zeus/miniconda3/envs/cloudspace/lib/python3.10/site-packages/wandb/sdk/wandb_run.py", line 1566, in _console_raw_callback
    self._backend.interface.publish_output_raw(name, data)
  File "/home/zeus/miniconda3/envs/cloudspace/lib/python3.10/site-packages/wandb/sdk/interface/interface.py", line 771, in publish_output_raw
    self._publish_output_raw(o)
  File "/home/zeus/miniconda3/envs/cloudspace/lib/python3.10/site-packages/wandb/sdk/interface/interface_shared.py", line 38, in _publish_output_raw
    self._publish(rec)
  File "/home/zeus/miniconda3/envs/cloudspace/lib/python3.10/site-packages/wandb/sdk/interface/interface_sock.py", line 39, in _publish
    self._sock_client.send_record_publish(record)
  File "/home/zeus/miniconda3/envs/cloudspace/lib/python3.10/site-packages/wandb/sdk/lib/sock_client.py", line 170, in send_record_publish
    self.send_server_request(server_req)
  File "/home/zeus/miniconda3/envs/cloudspace/lib/python3.10/site-packages/wandb/sdk/lib/sock_client.py", line 150, in send_server_request
    self._send_message(msg)
  File "/home/zeus/miniconda3/envs/cloudspace/lib/python3.10/site-packages/wandb/sdk/lib/sock_client.py", line 147, in _send_message
    self._sendall_with_error_handle(header + data)
  File "/home/zeus/miniconda3/envs/cloudspace/lib/python3.10/site-packages/wandb/sdk/lib/sock_client.py", line 126, in _sendall_with_error_handle
    sent = self._sock.send(data)
BrokenPipeError: [Errno 32] Broken pipe
2025-07-19 00:18:56,692 ERROR   MainThread:37156 [redirect.py:_on_write():664] [all runs] error in stderr callback
Traceback (most recent call last):
  File "/home/zeus/miniconda3/envs/cloudspace/lib/python3.10/site-packages/wandb/sdk/lib/redirect.py", line 662, in _on_write
    cb(written_data)
  File "/home/zeus/miniconda3/envs/cloudspace/lib/python3.10/site-packages/wandb/sdk/wandb_run.py", line 2385, in <lambda>
    lambda data: self._console_raw_callback("stderr", data),
  File "/home/zeus/miniconda3/envs/cloudspace/lib/python3.10/site-packages/wandb/sdk/wandb_run.py", line 398, in wrapper
    return func(self, *args, **kwargs)
  File "/home/zeus/miniconda3/envs/cloudspace/lib/python3.10/site-packages/wandb/sdk/wandb_run.py", line 456, in wrapper_fn
    return func(self, *args, **kwargs)
  File "/home/zeus/miniconda3/envs/cloudspace/lib/python3.10/site-packages/wandb/sdk/wandb_run.py", line 1566, in _console_raw_callback
    self._backend.interface.publish_output_raw(name, data)
  File "/home/zeus/miniconda3/envs/cloudspace/lib/python3.10/site-packages/wandb/sdk/interface/interface.py", line 771, in publish_output_raw
    self._publish_output_raw(o)
  File "/home/zeus/miniconda3/envs/cloudspace/lib/python3.10/site-packages/wandb/sdk/interface/interface_shared.py", line 38, in _publish_output_raw
    self._publish(rec)
  File "/home/zeus/miniconda3/envs/cloudspace/lib/python3.10/site-packages/wandb/sdk/interface/interface_sock.py", line 39, in _publish
    self._sock_client.send_record_publish(record)
  File "/home/zeus/miniconda3/envs/cloudspace/lib/python3.10/site-packages/wandb/sdk/lib/sock_client.py", line 170, in send_record_publish
    self.send_server_request(server_req)
  File "/home/zeus/miniconda3/envs/cloudspace/lib/python3.10/site-packages/wandb/sdk/lib/sock_client.py", line 150, in send_server_request
    self._send_message(msg)
  File "/home/zeus/miniconda3/envs/cloudspace/lib/python3.10/site-packages/wandb/sdk/lib/sock_client.py", line 147, in _send_message
    self._sendall_with_error_handle(header + data)
  File "/home/zeus/miniconda3/envs/cloudspace/lib/python3.10/site-packages/wandb/sdk/lib/sock_client.py", line 126, in _sendall_with_error_handle
    sent = self._sock.send(data)
BrokenPipeError: [Errno 32] Broken pipe
2025-07-19 00:18:56,692 ERROR   MainThread:37156 [redirect.py:_on_write():664] [all runs] error in stderr callback
Traceback (most recent call last):
  File "/home/zeus/miniconda3/envs/cloudspace/lib/python3.10/site-packages/wandb/sdk/lib/redirect.py", line 662, in _on_write
    cb(written_data)
  File "/home/zeus/miniconda3/envs/cloudspace/lib/python3.10/site-packages/wandb/sdk/wandb_run.py", line 2385, in <lambda>
    lambda data: self._console_raw_callback("stderr", data),
  File "/home/zeus/miniconda3/envs/cloudspace/lib/python3.10/site-packages/wandb/sdk/wandb_run.py", line 398, in wrapper
    return func(self, *args, **kwargs)
  File "/home/zeus/miniconda3/envs/cloudspace/lib/python3.10/site-packages/wandb/sdk/wandb_run.py", line 456, in wrapper_fn
    return func(self, *args, **kwargs)
  File "/home/zeus/miniconda3/envs/cloudspace/lib/python3.10/site-packages/wandb/sdk/wandb_run.py", line 1566, in _console_raw_callback
    self._backend.interface.publish_output_raw(name, data)
  File "/home/zeus/miniconda3/envs/cloudspace/lib/python3.10/site-packages/wandb/sdk/interface/interface.py", line 771, in publish_output_raw
    self._publish_output_raw(o)
  File "/home/zeus/miniconda3/envs/cloudspace/lib/python3.10/site-packages/wandb/sdk/interface/interface_shared.py", line 38, in _publish_output_raw
    self._publish(rec)
  File "/home/zeus/miniconda3/envs/cloudspace/lib/python3.10/site-packages/wandb/sdk/interface/interface_sock.py", line 39, in _publish
    self._sock_client.send_record_publish(record)
  File "/home/zeus/miniconda3/envs/cloudspace/lib/python3.10/site-packages/wandb/sdk/lib/sock_client.py", line 170, in send_record_publish
    self.send_server_request(server_req)
  File "/home/zeus/miniconda3/envs/cloudspace/lib/python3.10/site-packages/wandb/sdk/lib/sock_client.py", line 150, in send_server_request
    self._send_message(msg)
  File "/home/zeus/miniconda3/envs/cloudspace/lib/python3.10/site-packages/wandb/sdk/lib/sock_client.py", line 147, in _send_message
    self._sendall_with_error_handle(header + data)
  File "/home/zeus/miniconda3/envs/cloudspace/lib/python3.10/site-packages/wandb/sdk/lib/sock_client.py", line 126, in _sendall_with_error_handle
    sent = self._sock.send(data)
BrokenPipeError: [Errno 32] Broken pipe
2025-07-19 00:18:56,693 ERROR   MainThread:37156 [redirect.py:_on_write():664] [all runs] error in stderr callback
Traceback (most recent call last):
  File "/home/zeus/miniconda3/envs/cloudspace/lib/python3.10/site-packages/wandb/sdk/lib/redirect.py", line 662, in _on_write
    cb(written_data)
  File "/home/zeus/miniconda3/envs/cloudspace/lib/python3.10/site-packages/wandb/sdk/wandb_run.py", line 2385, in <lambda>
    lambda data: self._console_raw_callback("stderr", data),
  File "/home/zeus/miniconda3/envs/cloudspace/lib/python3.10/site-packages/wandb/sdk/wandb_run.py", line 398, in wrapper
    return func(self, *args, **kwargs)
  File "/home/zeus/miniconda3/envs/cloudspace/lib/python3.10/site-packages/wandb/sdk/wandb_run.py", line 456, in wrapper_fn
    return func(self, *args, **kwargs)
  File "/home/zeus/miniconda3/envs/cloudspace/lib/python3.10/site-packages/wandb/sdk/wandb_run.py", line 1566, in _console_raw_callback
    self._backend.interface.publish_output_raw(name, data)
  File "/home/zeus/miniconda3/envs/cloudspace/lib/python3.10/site-packages/wandb/sdk/interface/interface.py", line 771, in publish_output_raw
    self._publish_output_raw(o)
  File "/home/zeus/miniconda3/envs/cloudspace/lib/python3.10/site-packages/wandb/sdk/interface/interface_shared.py", line 38, in _publish_output_raw
    self._publish(rec)
  File "/home/zeus/miniconda3/envs/cloudspace/lib/python3.10/site-packages/wandb/sdk/interface/interface_sock.py", line 39, in _publish
    self._sock_client.send_record_publish(record)
  File "/home/zeus/miniconda3/envs/cloudspace/lib/python3.10/site-packages/wandb/sdk/lib/sock_client.py", line 170, in send_record_publish
    self.send_server_request(server_req)
  File "/home/zeus/miniconda3/envs/cloudspace/lib/python3.10/site-packages/wandb/sdk/lib/sock_client.py", line 150, in send_server_request
    self._send_message(msg)
  File "/home/zeus/miniconda3/envs/cloudspace/lib/python3.10/site-packages/wandb/sdk/lib/sock_client.py", line 147, in _send_message
    self._sendall_with_error_handle(header + data)
  File "/home/zeus/miniconda3/envs/cloudspace/lib/python3.10/site-packages/wandb/sdk/lib/sock_client.py", line 126, in _sendall_with_error_handle
    sent = self._sock.send(data)
BrokenPipeError: [Errno 32] Broken pipe
2025-07-19 00:18:56,693 ERROR   MainThread:37156 [redirect.py:_on_write():664] [all runs] error in stderr callback
Traceback (most recent call last):
  File "/home/zeus/miniconda3/envs/cloudspace/lib/python3.10/site-packages/wandb/sdk/lib/redirect.py", line 662, in _on_write
    cb(written_data)
  File "/home/zeus/miniconda3/envs/cloudspace/lib/python3.10/site-packages/wandb/sdk/wandb_run.py", line 2385, in <lambda>
    lambda data: self._console_raw_callback("stderr", data),
  File "/home/zeus/miniconda3/envs/cloudspace/lib/python3.10/site-packages/wandb/sdk/wandb_run.py", line 398, in wrapper
    return func(self, *args, **kwargs)
  File "/home/zeus/miniconda3/envs/cloudspace/lib/python3.10/site-packages/wandb/sdk/wandb_run.py", line 456, in wrapper_fn
    return func(self, *args, **kwargs)
  File "/home/zeus/miniconda3/envs/cloudspace/lib/python3.10/site-packages/wandb/sdk/wandb_run.py", line 1566, in _console_raw_callback
    self._backend.interface.publish_output_raw(name, data)
  File "/home/zeus/miniconda3/envs/cloudspace/lib/python3.10/site-packages/wandb/sdk/interface/interface.py", line 771, in publish_output_raw
    self._publish_output_raw(o)
  File "/home/zeus/miniconda3/envs/cloudspace/lib/python3.10/site-packages/wandb/sdk/interface/interface_shared.py", line 38, in _publish_output_raw
    self._publish(rec)
  File "/home/zeus/miniconda3/envs/cloudspace/lib/python3.10/site-packages/wandb/sdk/interface/interface_sock.py", line 39, in _publish
    self._sock_client.send_record_publish(record)
  File "/home/zeus/miniconda3/envs/cloudspace/lib/python3.10/site-packages/wandb/sdk/lib/sock_client.py", line 170, in send_record_publish
    self.send_server_request(server_req)
  File "/home/zeus/miniconda3/envs/cloudspace/lib/python3.10/site-packages/wandb/sdk/lib/sock_client.py", line 150, in send_server_request
    self._send_message(msg)
  File "/home/zeus/miniconda3/envs/cloudspace/lib/python3.10/site-packages/wandb/sdk/lib/sock_client.py", line 147, in _send_message
    self._sendall_with_error_handle(header + data)
  File "/home/zeus/miniconda3/envs/cloudspace/lib/python3.10/site-packages/wandb/sdk/lib/sock_client.py", line 126, in _sendall_with_error_handle
    sent = self._sock.send(data)
BrokenPipeError: [Errno 32] Broken pipe
