step 0: train loss 10.9204, val loss 10.9071
iter 0: loss 10.9514, time 7923.47ms, mfu -100.00%
iter 10: loss 7.7705, time 1428.40ms, mfu 20.26%
step 20: train loss 7.8636, val loss 7.5760
saving checkpoint to out
iter 20: loss 7.6448, time 7056.99ms, mfu 18.64%
iter 30: loss 7.6848, time 1465.19ms, mfu 18.75%
step 40: train loss 7.4412, val loss 7.3884
saving checkpoint to out
iter 40: loss 7.1338, time 7197.91ms, mfu 17.28%
iter 50: loss 7.1553, time 1460.98ms, mfu 17.53%
step 60: train loss 6.9926, val loss 7.0861
saving checkpoint to out
iter 60: loss 7.1756, time 7076.84ms, mfu 16.19%
Traceback (most recent call last):
  File "/teamspace/studios/this_studio/nanoGPT/train.py", line 687, in <module>
    scaler.scale(loss).backward()
  File "/home/zeus/miniconda3/envs/cloudspace/lib/python3.10/site-packages/torch/_tensor.py", line 648, in backward
    torch.autograd.backward(
  File "/home/zeus/miniconda3/envs/cloudspace/lib/python3.10/site-packages/torch/autograd/__init__.py", line 353, in backward
    _engine_run_backward(
  File "/home/zeus/miniconda3/envs/cloudspace/lib/python3.10/site-packages/torch/autograd/graph.py", line 824, in _engine_run_backward
    return Variable._execution_engine.run_backward(  # Calls into the C++ engine to run the backward pass
KeyboardInterrupt
Traceback (most recent call last):
  File "/teamspace/studios/this_studio/nanoGPT/train.py", line 687, in <module>
    scaler.scale(loss).backward()
  File "/home/zeus/miniconda3/envs/cloudspace/lib/python3.10/site-packages/torch/_tensor.py", line 648, in backward
    torch.autograd.backward(
  File "/home/zeus/miniconda3/envs/cloudspace/lib/python3.10/site-packages/torch/autograd/__init__.py", line 353, in backward
    _engine_run_backward(
  File "/home/zeus/miniconda3/envs/cloudspace/lib/python3.10/site-packages/torch/autograd/graph.py", line 824, in _engine_run_backward
    return Variable._execution_engine.run_backward(  # Calls into the C++ engine to run the backward pass
KeyboardInterrupt
Exception ignored in atexit callback: <function _start_and_connect_service.<locals>.teardown_atexit at 0x78aeec1a4430>
Traceback (most recent call last):
  File "/home/zeus/miniconda3/envs/cloudspace/lib/python3.10/site-packages/wandb/sdk/lib/service/service_connection.py", line 54, in teardown_atexit
    conn.teardown(hooks.exit_code)
  File "/home/zeus/miniconda3/envs/cloudspace/lib/python3.10/site-packages/wandb/sdk/lib/service/service_connection.py", line 182, in teardown
    self._router.join()
  File "/home/zeus/miniconda3/envs/cloudspace/lib/python3.10/site-packages/wandb/sdk/interface/router.py", line 75, in join
    self._thread.join()
  File "/home/zeus/miniconda3/envs/cloudspace/lib/python3.10/threading.py", line 1096, in join
    self._wait_for_tstate_lock()
  File "/home/zeus/miniconda3/envs/cloudspace/lib/python3.10/threading.py", line 1116, in _wait_for_tstate_lock
    if lock.acquire(block, timeout):
KeyboardInterrupt:
Exception ignored in atexit callback: <function shutdown_compile_workers at 0x78af00dd8310>
Traceback (most recent call last):
  File "/home/zeus/miniconda3/envs/cloudspace/lib/python3.10/site-packages/torch/_inductor/async_compile.py", line 113, in shutdown_compile_workers
    pool.shutdown()
  File "/home/zeus/miniconda3/envs/cloudspace/lib/python3.10/site-packages/torch/_inductor/compile_worker/subproc_pool.py", line 239, in shutdown
    self.process.wait(300)
  File "/home/zeus/miniconda3/envs/cloudspace/lib/python3.10/subprocess.py", line 1209, in wait
    return self._wait(timeout=timeout)
  File "/home/zeus/miniconda3/envs/cloudspace/lib/python3.10/subprocess.py", line 1937, in _wait
    time.sleep(delay)
KeyboardInterrupt:
