2025-07-20 14:54:25,210 INFO    MainThread:138854 [wandb_setup.py:_flush():80] Current SDK version is 0.21.0
2025-07-20 14:54:25,210 INFO    MainThread:138854 [wandb_setup.py:_flush():80] Configure stats pid to 138854
2025-07-20 14:54:25,210 INFO    MainThread:138854 [wandb_setup.py:_flush():80] Loading settings from /teamspace/studios/this_studio/.config/wandb/settings
2025-07-20 14:54:25,210 INFO    MainThread:138854 [wandb_setup.py:_flush():80] Loading settings from /teamspace/studios/this_studio/nanoGPT/wandb/settings
2025-07-20 14:54:25,210 INFO    MainThread:138854 [wandb_setup.py:_flush():80] Loading settings from environment variables
2025-07-20 14:54:25,210 INFO    MainThread:138854 [wandb_init.py:setup_run_log_directory():703] Logging user logs to /teamspace/studios/this_studio/nanoGPT/wandb/run-20250720_145425-8ipguoqh/logs/debug.log
2025-07-20 14:54:25,210 INFO    MainThread:138854 [wandb_init.py:setup_run_log_directory():704] Logging internal logs to /teamspace/studios/this_studio/nanoGPT/wandb/run-20250720_145425-8ipguoqh/logs/debug-internal.log
2025-07-20 14:54:25,210 INFO    MainThread:138854 [wandb_init.py:init():830] calling init triggers
2025-07-20 14:54:25,210 INFO    MainThread:138854 [wandb_init.py:init():835] wandb.init called with sweep_config: {}
config: {'out_dir': 'out', 'eval_interval': 100, 'log_interval': 10, 'eval_iters': 10, 'eval_only': False, 'always_save_checkpoint': True, 'init_from': 'scratch', 'log_dir': 'logs', 'file_logging': True, 'wandb_log': True, 'wandb_project': 'owt', 'wandb_run_name': 'gpt2', 'dataset': 'fineweb10B', 'gradient_accumulation_steps': 2, 'batch_size': 32, 'block_size': 1024, 'n_layer': 12, 'n_head': 12, 'n_embd': 768, 'dropout': 0.0, 'bias': False, 'use_rotary_embeddings': True, 'rotary_base': 10000.0, 'rotary_max_position_embeddings': 2048, 'learning_rate': 0.001, 'max_iters': 600000, 'weight_decay': 0.1, 'beta1': 0.9, 'beta2': 0.95, 'grad_clip': 1.0, 'decay_lr': True, 'warmup_iters': 200, 'lr_decay_iters': 600000, 'min_lr': 6e-05, 'backend': 'nccl', 'device': 'cuda', 'dtype': 'bfloat16', 'compile': True, 'embedding_mode': 'lora', 'attn_lora_rank': 48, 'embedding_rank': 48, 'lora_alpha': 1.0, 'attn_lora_rank_divisor': 16, 'vocab_lora_rank_divisor': 16, 'lora_alpha_multiplier': 1.0, 'n_layer_divisor': 4, 'n_hidden_divisor': 4, 'batch_size_multiplier': 1.0, 'grad_accum_multiplier': 1.0, 'lr_multiplier': 10, 'warmup_iters_multiplier': 1.0, 'eval_iters_multiplier': 1.0, 'eval_interval_multiplier': 1.0, '_wandb': {}}
2025-07-20 14:54:25,210 INFO    MainThread:138854 [wandb_init.py:init():871] starting backend
2025-07-20 14:54:25,419 INFO    MainThread:138854 [wandb_init.py:init():874] sending inform_init request
2025-07-20 14:54:25,424 INFO    MainThread:138854 [wandb_init.py:init():882] backend started and connected
2025-07-20 14:54:25,426 INFO    MainThread:138854 [wandb_init.py:init():953] updated telemetry
2025-07-20 14:54:25,438 INFO    MainThread:138854 [wandb_init.py:init():977] communicating run to backend with 90.0 second timeout
2025-07-20 14:54:25,656 INFO    MainThread:138854 [wandb_init.py:init():1029] starting run threads in backend
2025-07-20 14:54:25,861 INFO    MainThread:138854 [wandb_run.py:_console_start():2458] atexit reg
2025-07-20 14:54:25,862 INFO    MainThread:138854 [wandb_run.py:_redirect():2306] redirect: wrap_raw
2025-07-20 14:54:25,862 INFO    MainThread:138854 [wandb_run.py:_redirect():2375] Wrapping output streams.
2025-07-20 14:54:25,862 INFO    MainThread:138854 [wandb_run.py:_redirect():2398] Redirects installed.
2025-07-20 14:54:25,864 INFO    MainThread:138854 [wandb_init.py:init():1075] run started, returning control to user process
2025-07-20 15:08:37,195 INFO    MsgRouterThr:138854 [mailbox.py:close():129] [no run ID] Closing mailbox, abandoning 1 handles.
2025-07-20 15:08:37,442 ERROR   MainThread:138854 [redirect.py:_on_write():664] [all runs] error in stderr callback
Traceback (most recent call last):
  File "/home/zeus/miniconda3/envs/cloudspace/lib/python3.10/site-packages/wandb/sdk/lib/redirect.py", line 662, in _on_write
    cb(written_data)
  File "/home/zeus/miniconda3/envs/cloudspace/lib/python3.10/site-packages/wandb/sdk/wandb_run.py", line 2385, in <lambda>
    lambda data: self._console_raw_callback("stderr", data),
  File "/home/zeus/miniconda3/envs/cloudspace/lib/python3.10/site-packages/wandb/sdk/wandb_run.py", line 398, in wrapper
    return func(self, *args, **kwargs)
  File "/home/zeus/miniconda3/envs/cloudspace/lib/python3.10/site-packages/wandb/sdk/wandb_run.py", line 456, in wrapper_fn
    return func(self, *args, **kwargs)
  File "/home/zeus/miniconda3/envs/cloudspace/lib/python3.10/site-packages/wandb/sdk/wandb_run.py", line 1566, in _console_raw_callback
    self._backend.interface.publish_output_raw(name, data)
  File "/home/zeus/miniconda3/envs/cloudspace/lib/python3.10/site-packages/wandb/sdk/interface/interface.py", line 771, in publish_output_raw
    self._publish_output_raw(o)
  File "/home/zeus/miniconda3/envs/cloudspace/lib/python3.10/site-packages/wandb/sdk/interface/interface_shared.py", line 38, in _publish_output_raw
    self._publish(rec)
  File "/home/zeus/miniconda3/envs/cloudspace/lib/python3.10/site-packages/wandb/sdk/interface/interface_sock.py", line 39, in _publish
    self._sock_client.send_record_publish(record)
  File "/home/zeus/miniconda3/envs/cloudspace/lib/python3.10/site-packages/wandb/sdk/lib/sock_client.py", line 170, in send_record_publish
    self.send_server_request(server_req)
  File "/home/zeus/miniconda3/envs/cloudspace/lib/python3.10/site-packages/wandb/sdk/lib/sock_client.py", line 150, in send_server_request
    self._send_message(msg)
  File "/home/zeus/miniconda3/envs/cloudspace/lib/python3.10/site-packages/wandb/sdk/lib/sock_client.py", line 147, in _send_message
    self._sendall_with_error_handle(header + data)
  File "/home/zeus/miniconda3/envs/cloudspace/lib/python3.10/site-packages/wandb/sdk/lib/sock_client.py", line 126, in _sendall_with_error_handle
    sent = self._sock.send(data)
BrokenPipeError: [Errno 32] Broken pipe
2025-07-20 15:08:37,445 ERROR   MainThread:138854 [redirect.py:_on_write():664] [all runs] error in stderr callback
Traceback (most recent call last):
  File "/home/zeus/miniconda3/envs/cloudspace/lib/python3.10/site-packages/wandb/sdk/lib/redirect.py", line 662, in _on_write
    cb(written_data)
  File "/home/zeus/miniconda3/envs/cloudspace/lib/python3.10/site-packages/wandb/sdk/wandb_run.py", line 2385, in <lambda>
    lambda data: self._console_raw_callback("stderr", data),
  File "/home/zeus/miniconda3/envs/cloudspace/lib/python3.10/site-packages/wandb/sdk/wandb_run.py", line 398, in wrapper
    return func(self, *args, **kwargs)
  File "/home/zeus/miniconda3/envs/cloudspace/lib/python3.10/site-packages/wandb/sdk/wandb_run.py", line 456, in wrapper_fn
    return func(self, *args, **kwargs)
  File "/home/zeus/miniconda3/envs/cloudspace/lib/python3.10/site-packages/wandb/sdk/wandb_run.py", line 1566, in _console_raw_callback
    self._backend.interface.publish_output_raw(name, data)
  File "/home/zeus/miniconda3/envs/cloudspace/lib/python3.10/site-packages/wandb/sdk/interface/interface.py", line 771, in publish_output_raw
    self._publish_output_raw(o)
  File "/home/zeus/miniconda3/envs/cloudspace/lib/python3.10/site-packages/wandb/sdk/interface/interface_shared.py", line 38, in _publish_output_raw
    self._publish(rec)
  File "/home/zeus/miniconda3/envs/cloudspace/lib/python3.10/site-packages/wandb/sdk/interface/interface_sock.py", line 39, in _publish
    self._sock_client.send_record_publish(record)
  File "/home/zeus/miniconda3/envs/cloudspace/lib/python3.10/site-packages/wandb/sdk/lib/sock_client.py", line 170, in send_record_publish
    self.send_server_request(server_req)
  File "/home/zeus/miniconda3/envs/cloudspace/lib/python3.10/site-packages/wandb/sdk/lib/sock_client.py", line 150, in send_server_request
    self._send_message(msg)
  File "/home/zeus/miniconda3/envs/cloudspace/lib/python3.10/site-packages/wandb/sdk/lib/sock_client.py", line 147, in _send_message
    self._sendall_with_error_handle(header + data)
  File "/home/zeus/miniconda3/envs/cloudspace/lib/python3.10/site-packages/wandb/sdk/lib/sock_client.py", line 126, in _sendall_with_error_handle
    sent = self._sock.send(data)
BrokenPipeError: [Errno 32] Broken pipe
2025-07-20 15:08:37,445 ERROR   MainThread:138854 [redirect.py:_on_write():664] [all runs] error in stderr callback
Traceback (most recent call last):
  File "/home/zeus/miniconda3/envs/cloudspace/lib/python3.10/site-packages/wandb/sdk/lib/redirect.py", line 662, in _on_write
    cb(written_data)
  File "/home/zeus/miniconda3/envs/cloudspace/lib/python3.10/site-packages/wandb/sdk/wandb_run.py", line 2385, in <lambda>
    lambda data: self._console_raw_callback("stderr", data),
  File "/home/zeus/miniconda3/envs/cloudspace/lib/python3.10/site-packages/wandb/sdk/wandb_run.py", line 398, in wrapper
    return func(self, *args, **kwargs)
  File "/home/zeus/miniconda3/envs/cloudspace/lib/python3.10/site-packages/wandb/sdk/wandb_run.py", line 456, in wrapper_fn
    return func(self, *args, **kwargs)
  File "/home/zeus/miniconda3/envs/cloudspace/lib/python3.10/site-packages/wandb/sdk/wandb_run.py", line 1566, in _console_raw_callback
    self._backend.interface.publish_output_raw(name, data)
  File "/home/zeus/miniconda3/envs/cloudspace/lib/python3.10/site-packages/wandb/sdk/interface/interface.py", line 771, in publish_output_raw
    self._publish_output_raw(o)
  File "/home/zeus/miniconda3/envs/cloudspace/lib/python3.10/site-packages/wandb/sdk/interface/interface_shared.py", line 38, in _publish_output_raw
    self._publish(rec)
  File "/home/zeus/miniconda3/envs/cloudspace/lib/python3.10/site-packages/wandb/sdk/interface/interface_sock.py", line 39, in _publish
    self._sock_client.send_record_publish(record)
  File "/home/zeus/miniconda3/envs/cloudspace/lib/python3.10/site-packages/wandb/sdk/lib/sock_client.py", line 170, in send_record_publish
    self.send_server_request(server_req)
  File "/home/zeus/miniconda3/envs/cloudspace/lib/python3.10/site-packages/wandb/sdk/lib/sock_client.py", line 150, in send_server_request
    self._send_message(msg)
  File "/home/zeus/miniconda3/envs/cloudspace/lib/python3.10/site-packages/wandb/sdk/lib/sock_client.py", line 147, in _send_message
    self._sendall_with_error_handle(header + data)
  File "/home/zeus/miniconda3/envs/cloudspace/lib/python3.10/site-packages/wandb/sdk/lib/sock_client.py", line 126, in _sendall_with_error_handle
    sent = self._sock.send(data)
BrokenPipeError: [Errno 32] Broken pipe
2025-07-20 15:08:37,446 ERROR   MainThread:138854 [redirect.py:_on_write():664] [all runs] error in stderr callback
Traceback (most recent call last):
  File "/home/zeus/miniconda3/envs/cloudspace/lib/python3.10/site-packages/wandb/sdk/lib/redirect.py", line 662, in _on_write
    cb(written_data)
  File "/home/zeus/miniconda3/envs/cloudspace/lib/python3.10/site-packages/wandb/sdk/wandb_run.py", line 2385, in <lambda>
    lambda data: self._console_raw_callback("stderr", data),
  File "/home/zeus/miniconda3/envs/cloudspace/lib/python3.10/site-packages/wandb/sdk/wandb_run.py", line 398, in wrapper
    return func(self, *args, **kwargs)
  File "/home/zeus/miniconda3/envs/cloudspace/lib/python3.10/site-packages/wandb/sdk/wandb_run.py", line 456, in wrapper_fn
    return func(self, *args, **kwargs)
  File "/home/zeus/miniconda3/envs/cloudspace/lib/python3.10/site-packages/wandb/sdk/wandb_run.py", line 1566, in _console_raw_callback
    self._backend.interface.publish_output_raw(name, data)
  File "/home/zeus/miniconda3/envs/cloudspace/lib/python3.10/site-packages/wandb/sdk/interface/interface.py", line 771, in publish_output_raw
    self._publish_output_raw(o)
  File "/home/zeus/miniconda3/envs/cloudspace/lib/python3.10/site-packages/wandb/sdk/interface/interface_shared.py", line 38, in _publish_output_raw
    self._publish(rec)
  File "/home/zeus/miniconda3/envs/cloudspace/lib/python3.10/site-packages/wandb/sdk/interface/interface_sock.py", line 39, in _publish
    self._sock_client.send_record_publish(record)
  File "/home/zeus/miniconda3/envs/cloudspace/lib/python3.10/site-packages/wandb/sdk/lib/sock_client.py", line 170, in send_record_publish
    self.send_server_request(server_req)
  File "/home/zeus/miniconda3/envs/cloudspace/lib/python3.10/site-packages/wandb/sdk/lib/sock_client.py", line 150, in send_server_request
    self._send_message(msg)
  File "/home/zeus/miniconda3/envs/cloudspace/lib/python3.10/site-packages/wandb/sdk/lib/sock_client.py", line 147, in _send_message
    self._sendall_with_error_handle(header + data)
  File "/home/zeus/miniconda3/envs/cloudspace/lib/python3.10/site-packages/wandb/sdk/lib/sock_client.py", line 126, in _sendall_with_error_handle
    sent = self._sock.send(data)
BrokenPipeError: [Errno 32] Broken pipe
2025-07-20 15:08:37,446 ERROR   MainThread:138854 [redirect.py:_on_write():664] [all runs] error in stderr callback
Traceback (most recent call last):
  File "/home/zeus/miniconda3/envs/cloudspace/lib/python3.10/site-packages/wandb/sdk/lib/redirect.py", line 662, in _on_write
    cb(written_data)
  File "/home/zeus/miniconda3/envs/cloudspace/lib/python3.10/site-packages/wandb/sdk/wandb_run.py", line 2385, in <lambda>
    lambda data: self._console_raw_callback("stderr", data),
  File "/home/zeus/miniconda3/envs/cloudspace/lib/python3.10/site-packages/wandb/sdk/wandb_run.py", line 398, in wrapper
    return func(self, *args, **kwargs)
  File "/home/zeus/miniconda3/envs/cloudspace/lib/python3.10/site-packages/wandb/sdk/wandb_run.py", line 456, in wrapper_fn
    return func(self, *args, **kwargs)
  File "/home/zeus/miniconda3/envs/cloudspace/lib/python3.10/site-packages/wandb/sdk/wandb_run.py", line 1566, in _console_raw_callback
    self._backend.interface.publish_output_raw(name, data)
  File "/home/zeus/miniconda3/envs/cloudspace/lib/python3.10/site-packages/wandb/sdk/interface/interface.py", line 771, in publish_output_raw
    self._publish_output_raw(o)
  File "/home/zeus/miniconda3/envs/cloudspace/lib/python3.10/site-packages/wandb/sdk/interface/interface_shared.py", line 38, in _publish_output_raw
    self._publish(rec)
  File "/home/zeus/miniconda3/envs/cloudspace/lib/python3.10/site-packages/wandb/sdk/interface/interface_sock.py", line 39, in _publish
    self._sock_client.send_record_publish(record)
  File "/home/zeus/miniconda3/envs/cloudspace/lib/python3.10/site-packages/wandb/sdk/lib/sock_client.py", line 170, in send_record_publish
    self.send_server_request(server_req)
  File "/home/zeus/miniconda3/envs/cloudspace/lib/python3.10/site-packages/wandb/sdk/lib/sock_client.py", line 150, in send_server_request
    self._send_message(msg)
  File "/home/zeus/miniconda3/envs/cloudspace/lib/python3.10/site-packages/wandb/sdk/lib/sock_client.py", line 147, in _send_message
    self._sendall_with_error_handle(header + data)
  File "/home/zeus/miniconda3/envs/cloudspace/lib/python3.10/site-packages/wandb/sdk/lib/sock_client.py", line 126, in _sendall_with_error_handle
    sent = self._sock.send(data)
BrokenPipeError: [Errno 32] Broken pipe
2025-07-20 15:08:37,446 ERROR   MainThread:138854 [redirect.py:_on_write():664] [all runs] error in stderr callback
Traceback (most recent call last):
  File "/home/zeus/miniconda3/envs/cloudspace/lib/python3.10/site-packages/wandb/sdk/lib/redirect.py", line 662, in _on_write
    cb(written_data)
  File "/home/zeus/miniconda3/envs/cloudspace/lib/python3.10/site-packages/wandb/sdk/wandb_run.py", line 2385, in <lambda>
    lambda data: self._console_raw_callback("stderr", data),
  File "/home/zeus/miniconda3/envs/cloudspace/lib/python3.10/site-packages/wandb/sdk/wandb_run.py", line 398, in wrapper
    return func(self, *args, **kwargs)
  File "/home/zeus/miniconda3/envs/cloudspace/lib/python3.10/site-packages/wandb/sdk/wandb_run.py", line 456, in wrapper_fn
    return func(self, *args, **kwargs)
  File "/home/zeus/miniconda3/envs/cloudspace/lib/python3.10/site-packages/wandb/sdk/wandb_run.py", line 1566, in _console_raw_callback
    self._backend.interface.publish_output_raw(name, data)
  File "/home/zeus/miniconda3/envs/cloudspace/lib/python3.10/site-packages/wandb/sdk/interface/interface.py", line 771, in publish_output_raw
    self._publish_output_raw(o)
  File "/home/zeus/miniconda3/envs/cloudspace/lib/python3.10/site-packages/wandb/sdk/interface/interface_shared.py", line 38, in _publish_output_raw
    self._publish(rec)
  File "/home/zeus/miniconda3/envs/cloudspace/lib/python3.10/site-packages/wandb/sdk/interface/interface_sock.py", line 39, in _publish
    self._sock_client.send_record_publish(record)
  File "/home/zeus/miniconda3/envs/cloudspace/lib/python3.10/site-packages/wandb/sdk/lib/sock_client.py", line 170, in send_record_publish
    self.send_server_request(server_req)
  File "/home/zeus/miniconda3/envs/cloudspace/lib/python3.10/site-packages/wandb/sdk/lib/sock_client.py", line 150, in send_server_request
    self._send_message(msg)
  File "/home/zeus/miniconda3/envs/cloudspace/lib/python3.10/site-packages/wandb/sdk/lib/sock_client.py", line 147, in _send_message
    self._sendall_with_error_handle(header + data)
  File "/home/zeus/miniconda3/envs/cloudspace/lib/python3.10/site-packages/wandb/sdk/lib/sock_client.py", line 126, in _sendall_with_error_handle
    sent = self._sock.send(data)
BrokenPipeError: [Errno 32] Broken pipe
2025-07-20 15:08:37,447 ERROR   MainThread:138854 [redirect.py:_on_write():664] [all runs] error in stderr callback
Traceback (most recent call last):
  File "/home/zeus/miniconda3/envs/cloudspace/lib/python3.10/site-packages/wandb/sdk/lib/redirect.py", line 662, in _on_write
    cb(written_data)
  File "/home/zeus/miniconda3/envs/cloudspace/lib/python3.10/site-packages/wandb/sdk/wandb_run.py", line 2385, in <lambda>
    lambda data: self._console_raw_callback("stderr", data),
  File "/home/zeus/miniconda3/envs/cloudspace/lib/python3.10/site-packages/wandb/sdk/wandb_run.py", line 398, in wrapper
    return func(self, *args, **kwargs)
  File "/home/zeus/miniconda3/envs/cloudspace/lib/python3.10/site-packages/wandb/sdk/wandb_run.py", line 456, in wrapper_fn
    return func(self, *args, **kwargs)
  File "/home/zeus/miniconda3/envs/cloudspace/lib/python3.10/site-packages/wandb/sdk/wandb_run.py", line 1566, in _console_raw_callback
    self._backend.interface.publish_output_raw(name, data)
  File "/home/zeus/miniconda3/envs/cloudspace/lib/python3.10/site-packages/wandb/sdk/interface/interface.py", line 771, in publish_output_raw
    self._publish_output_raw(o)
  File "/home/zeus/miniconda3/envs/cloudspace/lib/python3.10/site-packages/wandb/sdk/interface/interface_shared.py", line 38, in _publish_output_raw
    self._publish(rec)
  File "/home/zeus/miniconda3/envs/cloudspace/lib/python3.10/site-packages/wandb/sdk/interface/interface_sock.py", line 39, in _publish
    self._sock_client.send_record_publish(record)
  File "/home/zeus/miniconda3/envs/cloudspace/lib/python3.10/site-packages/wandb/sdk/lib/sock_client.py", line 170, in send_record_publish
    self.send_server_request(server_req)
  File "/home/zeus/miniconda3/envs/cloudspace/lib/python3.10/site-packages/wandb/sdk/lib/sock_client.py", line 150, in send_server_request
    self._send_message(msg)
  File "/home/zeus/miniconda3/envs/cloudspace/lib/python3.10/site-packages/wandb/sdk/lib/sock_client.py", line 147, in _send_message
    self._sendall_with_error_handle(header + data)
  File "/home/zeus/miniconda3/envs/cloudspace/lib/python3.10/site-packages/wandb/sdk/lib/sock_client.py", line 126, in _sendall_with_error_handle
    sent = self._sock.send(data)
BrokenPipeError: [Errno 32] Broken pipe
2025-07-20 15:08:37,447 ERROR   MainThread:138854 [redirect.py:_on_write():664] [all runs] error in stderr callback
Traceback (most recent call last):
  File "/home/zeus/miniconda3/envs/cloudspace/lib/python3.10/site-packages/wandb/sdk/lib/redirect.py", line 662, in _on_write
    cb(written_data)
  File "/home/zeus/miniconda3/envs/cloudspace/lib/python3.10/site-packages/wandb/sdk/wandb_run.py", line 2385, in <lambda>
    lambda data: self._console_raw_callback("stderr", data),
  File "/home/zeus/miniconda3/envs/cloudspace/lib/python3.10/site-packages/wandb/sdk/wandb_run.py", line 398, in wrapper
    return func(self, *args, **kwargs)
  File "/home/zeus/miniconda3/envs/cloudspace/lib/python3.10/site-packages/wandb/sdk/wandb_run.py", line 456, in wrapper_fn
    return func(self, *args, **kwargs)
  File "/home/zeus/miniconda3/envs/cloudspace/lib/python3.10/site-packages/wandb/sdk/wandb_run.py", line 1566, in _console_raw_callback
    self._backend.interface.publish_output_raw(name, data)
  File "/home/zeus/miniconda3/envs/cloudspace/lib/python3.10/site-packages/wandb/sdk/interface/interface.py", line 771, in publish_output_raw
    self._publish_output_raw(o)
  File "/home/zeus/miniconda3/envs/cloudspace/lib/python3.10/site-packages/wandb/sdk/interface/interface_shared.py", line 38, in _publish_output_raw
    self._publish(rec)
  File "/home/zeus/miniconda3/envs/cloudspace/lib/python3.10/site-packages/wandb/sdk/interface/interface_sock.py", line 39, in _publish
    self._sock_client.send_record_publish(record)
  File "/home/zeus/miniconda3/envs/cloudspace/lib/python3.10/site-packages/wandb/sdk/lib/sock_client.py", line 170, in send_record_publish
    self.send_server_request(server_req)
  File "/home/zeus/miniconda3/envs/cloudspace/lib/python3.10/site-packages/wandb/sdk/lib/sock_client.py", line 150, in send_server_request
    self._send_message(msg)
  File "/home/zeus/miniconda3/envs/cloudspace/lib/python3.10/site-packages/wandb/sdk/lib/sock_client.py", line 147, in _send_message
    self._sendall_with_error_handle(header + data)
  File "/home/zeus/miniconda3/envs/cloudspace/lib/python3.10/site-packages/wandb/sdk/lib/sock_client.py", line 126, in _sendall_with_error_handle
    sent = self._sock.send(data)
BrokenPipeError: [Errno 32] Broken pipe
2025-07-20 15:08:37,448 ERROR   MainThread:138854 [redirect.py:_on_write():664] [all runs] error in stderr callback
Traceback (most recent call last):
  File "/home/zeus/miniconda3/envs/cloudspace/lib/python3.10/site-packages/wandb/sdk/lib/redirect.py", line 662, in _on_write
    cb(written_data)
  File "/home/zeus/miniconda3/envs/cloudspace/lib/python3.10/site-packages/wandb/sdk/wandb_run.py", line 2385, in <lambda>
    lambda data: self._console_raw_callback("stderr", data),
  File "/home/zeus/miniconda3/envs/cloudspace/lib/python3.10/site-packages/wandb/sdk/wandb_run.py", line 398, in wrapper
    return func(self, *args, **kwargs)
  File "/home/zeus/miniconda3/envs/cloudspace/lib/python3.10/site-packages/wandb/sdk/wandb_run.py", line 456, in wrapper_fn
    return func(self, *args, **kwargs)
  File "/home/zeus/miniconda3/envs/cloudspace/lib/python3.10/site-packages/wandb/sdk/wandb_run.py", line 1566, in _console_raw_callback
    self._backend.interface.publish_output_raw(name, data)
  File "/home/zeus/miniconda3/envs/cloudspace/lib/python3.10/site-packages/wandb/sdk/interface/interface.py", line 771, in publish_output_raw
    self._publish_output_raw(o)
  File "/home/zeus/miniconda3/envs/cloudspace/lib/python3.10/site-packages/wandb/sdk/interface/interface_shared.py", line 38, in _publish_output_raw
    self._publish(rec)
  File "/home/zeus/miniconda3/envs/cloudspace/lib/python3.10/site-packages/wandb/sdk/interface/interface_sock.py", line 39, in _publish
    self._sock_client.send_record_publish(record)
  File "/home/zeus/miniconda3/envs/cloudspace/lib/python3.10/site-packages/wandb/sdk/lib/sock_client.py", line 170, in send_record_publish
    self.send_server_request(server_req)
  File "/home/zeus/miniconda3/envs/cloudspace/lib/python3.10/site-packages/wandb/sdk/lib/sock_client.py", line 150, in send_server_request
    self._send_message(msg)
  File "/home/zeus/miniconda3/envs/cloudspace/lib/python3.10/site-packages/wandb/sdk/lib/sock_client.py", line 147, in _send_message
    self._sendall_with_error_handle(header + data)
  File "/home/zeus/miniconda3/envs/cloudspace/lib/python3.10/site-packages/wandb/sdk/lib/sock_client.py", line 126, in _sendall_with_error_handle
    sent = self._sock.send(data)
BrokenPipeError: [Errno 32] Broken pipe
2025-07-20 15:08:37,448 ERROR   MainThread:138854 [redirect.py:_on_write():664] [all runs] error in stderr callback
Traceback (most recent call last):
  File "/home/zeus/miniconda3/envs/cloudspace/lib/python3.10/site-packages/wandb/sdk/lib/redirect.py", line 662, in _on_write
    cb(written_data)
  File "/home/zeus/miniconda3/envs/cloudspace/lib/python3.10/site-packages/wandb/sdk/wandb_run.py", line 2385, in <lambda>
    lambda data: self._console_raw_callback("stderr", data),
  File "/home/zeus/miniconda3/envs/cloudspace/lib/python3.10/site-packages/wandb/sdk/wandb_run.py", line 398, in wrapper
    return func(self, *args, **kwargs)
  File "/home/zeus/miniconda3/envs/cloudspace/lib/python3.10/site-packages/wandb/sdk/wandb_run.py", line 456, in wrapper_fn
    return func(self, *args, **kwargs)
  File "/home/zeus/miniconda3/envs/cloudspace/lib/python3.10/site-packages/wandb/sdk/wandb_run.py", line 1566, in _console_raw_callback
    self._backend.interface.publish_output_raw(name, data)
  File "/home/zeus/miniconda3/envs/cloudspace/lib/python3.10/site-packages/wandb/sdk/interface/interface.py", line 771, in publish_output_raw
    self._publish_output_raw(o)
  File "/home/zeus/miniconda3/envs/cloudspace/lib/python3.10/site-packages/wandb/sdk/interface/interface_shared.py", line 38, in _publish_output_raw
    self._publish(rec)
  File "/home/zeus/miniconda3/envs/cloudspace/lib/python3.10/site-packages/wandb/sdk/interface/interface_sock.py", line 39, in _publish
    self._sock_client.send_record_publish(record)
  File "/home/zeus/miniconda3/envs/cloudspace/lib/python3.10/site-packages/wandb/sdk/lib/sock_client.py", line 170, in send_record_publish
    self.send_server_request(server_req)
  File "/home/zeus/miniconda3/envs/cloudspace/lib/python3.10/site-packages/wandb/sdk/lib/sock_client.py", line 150, in send_server_request
    self._send_message(msg)
  File "/home/zeus/miniconda3/envs/cloudspace/lib/python3.10/site-packages/wandb/sdk/lib/sock_client.py", line 147, in _send_message
    self._sendall_with_error_handle(header + data)
  File "/home/zeus/miniconda3/envs/cloudspace/lib/python3.10/site-packages/wandb/sdk/lib/sock_client.py", line 126, in _sendall_with_error_handle
    sent = self._sock.send(data)
BrokenPipeError: [Errno 32] Broken pipe
2025-07-20 15:08:37,449 ERROR   MainThread:138854 [redirect.py:_on_write():664] [all runs] error in stderr callback
Traceback (most recent call last):
  File "/home/zeus/miniconda3/envs/cloudspace/lib/python3.10/site-packages/wandb/sdk/lib/redirect.py", line 662, in _on_write
    cb(written_data)
  File "/home/zeus/miniconda3/envs/cloudspace/lib/python3.10/site-packages/wandb/sdk/wandb_run.py", line 2385, in <lambda>
    lambda data: self._console_raw_callback("stderr", data),
  File "/home/zeus/miniconda3/envs/cloudspace/lib/python3.10/site-packages/wandb/sdk/wandb_run.py", line 398, in wrapper
    return func(self, *args, **kwargs)
  File "/home/zeus/miniconda3/envs/cloudspace/lib/python3.10/site-packages/wandb/sdk/wandb_run.py", line 456, in wrapper_fn
    return func(self, *args, **kwargs)
  File "/home/zeus/miniconda3/envs/cloudspace/lib/python3.10/site-packages/wandb/sdk/wandb_run.py", line 1566, in _console_raw_callback
    self._backend.interface.publish_output_raw(name, data)
  File "/home/zeus/miniconda3/envs/cloudspace/lib/python3.10/site-packages/wandb/sdk/interface/interface.py", line 771, in publish_output_raw
    self._publish_output_raw(o)
  File "/home/zeus/miniconda3/envs/cloudspace/lib/python3.10/site-packages/wandb/sdk/interface/interface_shared.py", line 38, in _publish_output_raw
    self._publish(rec)
  File "/home/zeus/miniconda3/envs/cloudspace/lib/python3.10/site-packages/wandb/sdk/interface/interface_sock.py", line 39, in _publish
    self._sock_client.send_record_publish(record)
  File "/home/zeus/miniconda3/envs/cloudspace/lib/python3.10/site-packages/wandb/sdk/lib/sock_client.py", line 170, in send_record_publish
    self.send_server_request(server_req)
  File "/home/zeus/miniconda3/envs/cloudspace/lib/python3.10/site-packages/wandb/sdk/lib/sock_client.py", line 150, in send_server_request
    self._send_message(msg)
  File "/home/zeus/miniconda3/envs/cloudspace/lib/python3.10/site-packages/wandb/sdk/lib/sock_client.py", line 147, in _send_message
    self._sendall_with_error_handle(header + data)
  File "/home/zeus/miniconda3/envs/cloudspace/lib/python3.10/site-packages/wandb/sdk/lib/sock_client.py", line 126, in _sendall_with_error_handle
    sent = self._sock.send(data)
BrokenPipeError: [Errno 32] Broken pipe
2025-07-20 15:08:37,450 ERROR   MainThread:138854 [redirect.py:_on_write():664] [all runs] error in stderr callback
Traceback (most recent call last):
  File "/home/zeus/miniconda3/envs/cloudspace/lib/python3.10/site-packages/wandb/sdk/lib/redirect.py", line 662, in _on_write
    cb(written_data)
  File "/home/zeus/miniconda3/envs/cloudspace/lib/python3.10/site-packages/wandb/sdk/wandb_run.py", line 2385, in <lambda>
    lambda data: self._console_raw_callback("stderr", data),
  File "/home/zeus/miniconda3/envs/cloudspace/lib/python3.10/site-packages/wandb/sdk/wandb_run.py", line 398, in wrapper
    return func(self, *args, **kwargs)
  File "/home/zeus/miniconda3/envs/cloudspace/lib/python3.10/site-packages/wandb/sdk/wandb_run.py", line 456, in wrapper_fn
    return func(self, *args, **kwargs)
  File "/home/zeus/miniconda3/envs/cloudspace/lib/python3.10/site-packages/wandb/sdk/wandb_run.py", line 1566, in _console_raw_callback
    self._backend.interface.publish_output_raw(name, data)
  File "/home/zeus/miniconda3/envs/cloudspace/lib/python3.10/site-packages/wandb/sdk/interface/interface.py", line 771, in publish_output_raw
    self._publish_output_raw(o)
  File "/home/zeus/miniconda3/envs/cloudspace/lib/python3.10/site-packages/wandb/sdk/interface/interface_shared.py", line 38, in _publish_output_raw
    self._publish(rec)
  File "/home/zeus/miniconda3/envs/cloudspace/lib/python3.10/site-packages/wandb/sdk/interface/interface_sock.py", line 39, in _publish
    self._sock_client.send_record_publish(record)
  File "/home/zeus/miniconda3/envs/cloudspace/lib/python3.10/site-packages/wandb/sdk/lib/sock_client.py", line 170, in send_record_publish
    self.send_server_request(server_req)
  File "/home/zeus/miniconda3/envs/cloudspace/lib/python3.10/site-packages/wandb/sdk/lib/sock_client.py", line 150, in send_server_request
    self._send_message(msg)
  File "/home/zeus/miniconda3/envs/cloudspace/lib/python3.10/site-packages/wandb/sdk/lib/sock_client.py", line 147, in _send_message
    self._sendall_with_error_handle(header + data)
  File "/home/zeus/miniconda3/envs/cloudspace/lib/python3.10/site-packages/wandb/sdk/lib/sock_client.py", line 126, in _sendall_with_error_handle
    sent = self._sock.send(data)
BrokenPipeError: [Errno 32] Broken pipe
2025-07-20 15:08:37,450 ERROR   MainThread:138854 [redirect.py:_on_write():664] [all runs] error in stderr callback
Traceback (most recent call last):
  File "/home/zeus/miniconda3/envs/cloudspace/lib/python3.10/site-packages/wandb/sdk/lib/redirect.py", line 662, in _on_write
    cb(written_data)
  File "/home/zeus/miniconda3/envs/cloudspace/lib/python3.10/site-packages/wandb/sdk/wandb_run.py", line 2385, in <lambda>
    lambda data: self._console_raw_callback("stderr", data),
  File "/home/zeus/miniconda3/envs/cloudspace/lib/python3.10/site-packages/wandb/sdk/wandb_run.py", line 398, in wrapper
    return func(self, *args, **kwargs)
  File "/home/zeus/miniconda3/envs/cloudspace/lib/python3.10/site-packages/wandb/sdk/wandb_run.py", line 456, in wrapper_fn
    return func(self, *args, **kwargs)
  File "/home/zeus/miniconda3/envs/cloudspace/lib/python3.10/site-packages/wandb/sdk/wandb_run.py", line 1566, in _console_raw_callback
    self._backend.interface.publish_output_raw(name, data)
  File "/home/zeus/miniconda3/envs/cloudspace/lib/python3.10/site-packages/wandb/sdk/interface/interface.py", line 771, in publish_output_raw
    self._publish_output_raw(o)
  File "/home/zeus/miniconda3/envs/cloudspace/lib/python3.10/site-packages/wandb/sdk/interface/interface_shared.py", line 38, in _publish_output_raw
    self._publish(rec)
  File "/home/zeus/miniconda3/envs/cloudspace/lib/python3.10/site-packages/wandb/sdk/interface/interface_sock.py", line 39, in _publish
    self._sock_client.send_record_publish(record)
  File "/home/zeus/miniconda3/envs/cloudspace/lib/python3.10/site-packages/wandb/sdk/lib/sock_client.py", line 170, in send_record_publish
    self.send_server_request(server_req)
  File "/home/zeus/miniconda3/envs/cloudspace/lib/python3.10/site-packages/wandb/sdk/lib/sock_client.py", line 150, in send_server_request
    self._send_message(msg)
  File "/home/zeus/miniconda3/envs/cloudspace/lib/python3.10/site-packages/wandb/sdk/lib/sock_client.py", line 147, in _send_message
    self._sendall_with_error_handle(header + data)
  File "/home/zeus/miniconda3/envs/cloudspace/lib/python3.10/site-packages/wandb/sdk/lib/sock_client.py", line 126, in _sendall_with_error_handle
    sent = self._sock.send(data)
BrokenPipeError: [Errno 32] Broken pipe
2025-07-20 15:08:37,450 ERROR   MainThread:138854 [redirect.py:_on_write():664] [all runs] error in stderr callback
Traceback (most recent call last):
  File "/home/zeus/miniconda3/envs/cloudspace/lib/python3.10/site-packages/wandb/sdk/lib/redirect.py", line 662, in _on_write
    cb(written_data)
  File "/home/zeus/miniconda3/envs/cloudspace/lib/python3.10/site-packages/wandb/sdk/wandb_run.py", line 2385, in <lambda>
    lambda data: self._console_raw_callback("stderr", data),
  File "/home/zeus/miniconda3/envs/cloudspace/lib/python3.10/site-packages/wandb/sdk/wandb_run.py", line 398, in wrapper
    return func(self, *args, **kwargs)
  File "/home/zeus/miniconda3/envs/cloudspace/lib/python3.10/site-packages/wandb/sdk/wandb_run.py", line 456, in wrapper_fn
    return func(self, *args, **kwargs)
  File "/home/zeus/miniconda3/envs/cloudspace/lib/python3.10/site-packages/wandb/sdk/wandb_run.py", line 1566, in _console_raw_callback
    self._backend.interface.publish_output_raw(name, data)
  File "/home/zeus/miniconda3/envs/cloudspace/lib/python3.10/site-packages/wandb/sdk/interface/interface.py", line 771, in publish_output_raw
    self._publish_output_raw(o)
  File "/home/zeus/miniconda3/envs/cloudspace/lib/python3.10/site-packages/wandb/sdk/interface/interface_shared.py", line 38, in _publish_output_raw
    self._publish(rec)
  File "/home/zeus/miniconda3/envs/cloudspace/lib/python3.10/site-packages/wandb/sdk/interface/interface_sock.py", line 39, in _publish
    self._sock_client.send_record_publish(record)
  File "/home/zeus/miniconda3/envs/cloudspace/lib/python3.10/site-packages/wandb/sdk/lib/sock_client.py", line 170, in send_record_publish
    self.send_server_request(server_req)
  File "/home/zeus/miniconda3/envs/cloudspace/lib/python3.10/site-packages/wandb/sdk/lib/sock_client.py", line 150, in send_server_request
    self._send_message(msg)
  File "/home/zeus/miniconda3/envs/cloudspace/lib/python3.10/site-packages/wandb/sdk/lib/sock_client.py", line 147, in _send_message
    self._sendall_with_error_handle(header + data)
  File "/home/zeus/miniconda3/envs/cloudspace/lib/python3.10/site-packages/wandb/sdk/lib/sock_client.py", line 126, in _sendall_with_error_handle
    sent = self._sock.send(data)
BrokenPipeError: [Errno 32] Broken pipe
2025-07-20 15:08:37,451 ERROR   MainThread:138854 [redirect.py:_on_write():664] [all runs] error in stderr callback
Traceback (most recent call last):
  File "/home/zeus/miniconda3/envs/cloudspace/lib/python3.10/site-packages/wandb/sdk/lib/redirect.py", line 662, in _on_write
    cb(written_data)
  File "/home/zeus/miniconda3/envs/cloudspace/lib/python3.10/site-packages/wandb/sdk/wandb_run.py", line 2385, in <lambda>
    lambda data: self._console_raw_callback("stderr", data),
  File "/home/zeus/miniconda3/envs/cloudspace/lib/python3.10/site-packages/wandb/sdk/wandb_run.py", line 398, in wrapper
    return func(self, *args, **kwargs)
  File "/home/zeus/miniconda3/envs/cloudspace/lib/python3.10/site-packages/wandb/sdk/wandb_run.py", line 456, in wrapper_fn
    return func(self, *args, **kwargs)
  File "/home/zeus/miniconda3/envs/cloudspace/lib/python3.10/site-packages/wandb/sdk/wandb_run.py", line 1566, in _console_raw_callback
    self._backend.interface.publish_output_raw(name, data)
  File "/home/zeus/miniconda3/envs/cloudspace/lib/python3.10/site-packages/wandb/sdk/interface/interface.py", line 771, in publish_output_raw
    self._publish_output_raw(o)
  File "/home/zeus/miniconda3/envs/cloudspace/lib/python3.10/site-packages/wandb/sdk/interface/interface_shared.py", line 38, in _publish_output_raw
    self._publish(rec)
  File "/home/zeus/miniconda3/envs/cloudspace/lib/python3.10/site-packages/wandb/sdk/interface/interface_sock.py", line 39, in _publish
    self._sock_client.send_record_publish(record)
  File "/home/zeus/miniconda3/envs/cloudspace/lib/python3.10/site-packages/wandb/sdk/lib/sock_client.py", line 170, in send_record_publish
    self.send_server_request(server_req)
  File "/home/zeus/miniconda3/envs/cloudspace/lib/python3.10/site-packages/wandb/sdk/lib/sock_client.py", line 150, in send_server_request
    self._send_message(msg)
  File "/home/zeus/miniconda3/envs/cloudspace/lib/python3.10/site-packages/wandb/sdk/lib/sock_client.py", line 147, in _send_message
    self._sendall_with_error_handle(header + data)
  File "/home/zeus/miniconda3/envs/cloudspace/lib/python3.10/site-packages/wandb/sdk/lib/sock_client.py", line 126, in _sendall_with_error_handle
    sent = self._sock.send(data)
BrokenPipeError: [Errno 32] Broken pipe
2025-07-20 15:08:37,451 ERROR   MainThread:138854 [redirect.py:_on_write():664] [all runs] error in stderr callback
Traceback (most recent call last):
  File "/home/zeus/miniconda3/envs/cloudspace/lib/python3.10/site-packages/wandb/sdk/lib/redirect.py", line 662, in _on_write
    cb(written_data)
  File "/home/zeus/miniconda3/envs/cloudspace/lib/python3.10/site-packages/wandb/sdk/wandb_run.py", line 2385, in <lambda>
    lambda data: self._console_raw_callback("stderr", data),
  File "/home/zeus/miniconda3/envs/cloudspace/lib/python3.10/site-packages/wandb/sdk/wandb_run.py", line 398, in wrapper
    return func(self, *args, **kwargs)
  File "/home/zeus/miniconda3/envs/cloudspace/lib/python3.10/site-packages/wandb/sdk/wandb_run.py", line 456, in wrapper_fn
    return func(self, *args, **kwargs)
  File "/home/zeus/miniconda3/envs/cloudspace/lib/python3.10/site-packages/wandb/sdk/wandb_run.py", line 1566, in _console_raw_callback
    self._backend.interface.publish_output_raw(name, data)
  File "/home/zeus/miniconda3/envs/cloudspace/lib/python3.10/site-packages/wandb/sdk/interface/interface.py", line 771, in publish_output_raw
    self._publish_output_raw(o)
  File "/home/zeus/miniconda3/envs/cloudspace/lib/python3.10/site-packages/wandb/sdk/interface/interface_shared.py", line 38, in _publish_output_raw
    self._publish(rec)
  File "/home/zeus/miniconda3/envs/cloudspace/lib/python3.10/site-packages/wandb/sdk/interface/interface_sock.py", line 39, in _publish
    self._sock_client.send_record_publish(record)
  File "/home/zeus/miniconda3/envs/cloudspace/lib/python3.10/site-packages/wandb/sdk/lib/sock_client.py", line 170, in send_record_publish
    self.send_server_request(server_req)
  File "/home/zeus/miniconda3/envs/cloudspace/lib/python3.10/site-packages/wandb/sdk/lib/sock_client.py", line 150, in send_server_request
    self._send_message(msg)
  File "/home/zeus/miniconda3/envs/cloudspace/lib/python3.10/site-packages/wandb/sdk/lib/sock_client.py", line 147, in _send_message
    self._sendall_with_error_handle(header + data)
  File "/home/zeus/miniconda3/envs/cloudspace/lib/python3.10/site-packages/wandb/sdk/lib/sock_client.py", line 126, in _sendall_with_error_handle
    sent = self._sock.send(data)
BrokenPipeError: [Errno 32] Broken pipe
2025-07-20 15:08:37,452 ERROR   MainThread:138854 [redirect.py:_on_write():664] [all runs] error in stderr callback
Traceback (most recent call last):
  File "/home/zeus/miniconda3/envs/cloudspace/lib/python3.10/site-packages/wandb/sdk/lib/redirect.py", line 662, in _on_write
    cb(written_data)
  File "/home/zeus/miniconda3/envs/cloudspace/lib/python3.10/site-packages/wandb/sdk/wandb_run.py", line 2385, in <lambda>
    lambda data: self._console_raw_callback("stderr", data),
  File "/home/zeus/miniconda3/envs/cloudspace/lib/python3.10/site-packages/wandb/sdk/wandb_run.py", line 398, in wrapper
    return func(self, *args, **kwargs)
  File "/home/zeus/miniconda3/envs/cloudspace/lib/python3.10/site-packages/wandb/sdk/wandb_run.py", line 456, in wrapper_fn
    return func(self, *args, **kwargs)
  File "/home/zeus/miniconda3/envs/cloudspace/lib/python3.10/site-packages/wandb/sdk/wandb_run.py", line 1566, in _console_raw_callback
    self._backend.interface.publish_output_raw(name, data)
  File "/home/zeus/miniconda3/envs/cloudspace/lib/python3.10/site-packages/wandb/sdk/interface/interface.py", line 771, in publish_output_raw
    self._publish_output_raw(o)
  File "/home/zeus/miniconda3/envs/cloudspace/lib/python3.10/site-packages/wandb/sdk/interface/interface_shared.py", line 38, in _publish_output_raw
    self._publish(rec)
  File "/home/zeus/miniconda3/envs/cloudspace/lib/python3.10/site-packages/wandb/sdk/interface/interface_sock.py", line 39, in _publish
    self._sock_client.send_record_publish(record)
  File "/home/zeus/miniconda3/envs/cloudspace/lib/python3.10/site-packages/wandb/sdk/lib/sock_client.py", line 170, in send_record_publish
    self.send_server_request(server_req)
  File "/home/zeus/miniconda3/envs/cloudspace/lib/python3.10/site-packages/wandb/sdk/lib/sock_client.py", line 150, in send_server_request
    self._send_message(msg)
  File "/home/zeus/miniconda3/envs/cloudspace/lib/python3.10/site-packages/wandb/sdk/lib/sock_client.py", line 147, in _send_message
    self._sendall_with_error_handle(header + data)
  File "/home/zeus/miniconda3/envs/cloudspace/lib/python3.10/site-packages/wandb/sdk/lib/sock_client.py", line 126, in _sendall_with_error_handle
    sent = self._sock.send(data)
BrokenPipeError: [Errno 32] Broken pipe
2025-07-20 15:08:37,452 ERROR   MainThread:138854 [redirect.py:_on_write():664] [all runs] error in stderr callback
Traceback (most recent call last):
  File "/home/zeus/miniconda3/envs/cloudspace/lib/python3.10/site-packages/wandb/sdk/lib/redirect.py", line 662, in _on_write
    cb(written_data)
  File "/home/zeus/miniconda3/envs/cloudspace/lib/python3.10/site-packages/wandb/sdk/wandb_run.py", line 2385, in <lambda>
    lambda data: self._console_raw_callback("stderr", data),
  File "/home/zeus/miniconda3/envs/cloudspace/lib/python3.10/site-packages/wandb/sdk/wandb_run.py", line 398, in wrapper
    return func(self, *args, **kwargs)
  File "/home/zeus/miniconda3/envs/cloudspace/lib/python3.10/site-packages/wandb/sdk/wandb_run.py", line 456, in wrapper_fn
    return func(self, *args, **kwargs)
  File "/home/zeus/miniconda3/envs/cloudspace/lib/python3.10/site-packages/wandb/sdk/wandb_run.py", line 1566, in _console_raw_callback
    self._backend.interface.publish_output_raw(name, data)
  File "/home/zeus/miniconda3/envs/cloudspace/lib/python3.10/site-packages/wandb/sdk/interface/interface.py", line 771, in publish_output_raw
    self._publish_output_raw(o)
  File "/home/zeus/miniconda3/envs/cloudspace/lib/python3.10/site-packages/wandb/sdk/interface/interface_shared.py", line 38, in _publish_output_raw
    self._publish(rec)
  File "/home/zeus/miniconda3/envs/cloudspace/lib/python3.10/site-packages/wandb/sdk/interface/interface_sock.py", line 39, in _publish
    self._sock_client.send_record_publish(record)
  File "/home/zeus/miniconda3/envs/cloudspace/lib/python3.10/site-packages/wandb/sdk/lib/sock_client.py", line 170, in send_record_publish
    self.send_server_request(server_req)
  File "/home/zeus/miniconda3/envs/cloudspace/lib/python3.10/site-packages/wandb/sdk/lib/sock_client.py", line 150, in send_server_request
    self._send_message(msg)
  File "/home/zeus/miniconda3/envs/cloudspace/lib/python3.10/site-packages/wandb/sdk/lib/sock_client.py", line 147, in _send_message
    self._sendall_with_error_handle(header + data)
  File "/home/zeus/miniconda3/envs/cloudspace/lib/python3.10/site-packages/wandb/sdk/lib/sock_client.py", line 126, in _sendall_with_error_handle
    sent = self._sock.send(data)
BrokenPipeError: [Errno 32] Broken pipe
2025-07-20 15:08:37,453 ERROR   MainThread:138854 [redirect.py:_on_write():664] [all runs] error in stderr callback
Traceback (most recent call last):
  File "/home/zeus/miniconda3/envs/cloudspace/lib/python3.10/site-packages/wandb/sdk/lib/redirect.py", line 662, in _on_write
    cb(written_data)
  File "/home/zeus/miniconda3/envs/cloudspace/lib/python3.10/site-packages/wandb/sdk/wandb_run.py", line 2385, in <lambda>
    lambda data: self._console_raw_callback("stderr", data),
  File "/home/zeus/miniconda3/envs/cloudspace/lib/python3.10/site-packages/wandb/sdk/wandb_run.py", line 398, in wrapper
    return func(self, *args, **kwargs)
  File "/home/zeus/miniconda3/envs/cloudspace/lib/python3.10/site-packages/wandb/sdk/wandb_run.py", line 456, in wrapper_fn
    return func(self, *args, **kwargs)
  File "/home/zeus/miniconda3/envs/cloudspace/lib/python3.10/site-packages/wandb/sdk/wandb_run.py", line 1566, in _console_raw_callback
    self._backend.interface.publish_output_raw(name, data)
  File "/home/zeus/miniconda3/envs/cloudspace/lib/python3.10/site-packages/wandb/sdk/interface/interface.py", line 771, in publish_output_raw
    self._publish_output_raw(o)
  File "/home/zeus/miniconda3/envs/cloudspace/lib/python3.10/site-packages/wandb/sdk/interface/interface_shared.py", line 38, in _publish_output_raw
    self._publish(rec)
  File "/home/zeus/miniconda3/envs/cloudspace/lib/python3.10/site-packages/wandb/sdk/interface/interface_sock.py", line 39, in _publish
    self._sock_client.send_record_publish(record)
  File "/home/zeus/miniconda3/envs/cloudspace/lib/python3.10/site-packages/wandb/sdk/lib/sock_client.py", line 170, in send_record_publish
    self.send_server_request(server_req)
  File "/home/zeus/miniconda3/envs/cloudspace/lib/python3.10/site-packages/wandb/sdk/lib/sock_client.py", line 150, in send_server_request
    self._send_message(msg)
  File "/home/zeus/miniconda3/envs/cloudspace/lib/python3.10/site-packages/wandb/sdk/lib/sock_client.py", line 147, in _send_message
    self._sendall_with_error_handle(header + data)
  File "/home/zeus/miniconda3/envs/cloudspace/lib/python3.10/site-packages/wandb/sdk/lib/sock_client.py", line 126, in _sendall_with_error_handle
    sent = self._sock.send(data)
BrokenPipeError: [Errno 32] Broken pipe
2025-07-20 15:08:37,453 ERROR   MainThread:138854 [redirect.py:_on_write():664] [all runs] error in stderr callback
Traceback (most recent call last):
  File "/home/zeus/miniconda3/envs/cloudspace/lib/python3.10/site-packages/wandb/sdk/lib/redirect.py", line 662, in _on_write
    cb(written_data)
  File "/home/zeus/miniconda3/envs/cloudspace/lib/python3.10/site-packages/wandb/sdk/wandb_run.py", line 2385, in <lambda>
    lambda data: self._console_raw_callback("stderr", data),
  File "/home/zeus/miniconda3/envs/cloudspace/lib/python3.10/site-packages/wandb/sdk/wandb_run.py", line 398, in wrapper
    return func(self, *args, **kwargs)
  File "/home/zeus/miniconda3/envs/cloudspace/lib/python3.10/site-packages/wandb/sdk/wandb_run.py", line 456, in wrapper_fn
    return func(self, *args, **kwargs)
  File "/home/zeus/miniconda3/envs/cloudspace/lib/python3.10/site-packages/wandb/sdk/wandb_run.py", line 1566, in _console_raw_callback
    self._backend.interface.publish_output_raw(name, data)
  File "/home/zeus/miniconda3/envs/cloudspace/lib/python3.10/site-packages/wandb/sdk/interface/interface.py", line 771, in publish_output_raw
    self._publish_output_raw(o)
  File "/home/zeus/miniconda3/envs/cloudspace/lib/python3.10/site-packages/wandb/sdk/interface/interface_shared.py", line 38, in _publish_output_raw
    self._publish(rec)
  File "/home/zeus/miniconda3/envs/cloudspace/lib/python3.10/site-packages/wandb/sdk/interface/interface_sock.py", line 39, in _publish
    self._sock_client.send_record_publish(record)
  File "/home/zeus/miniconda3/envs/cloudspace/lib/python3.10/site-packages/wandb/sdk/lib/sock_client.py", line 170, in send_record_publish
    self.send_server_request(server_req)
  File "/home/zeus/miniconda3/envs/cloudspace/lib/python3.10/site-packages/wandb/sdk/lib/sock_client.py", line 150, in send_server_request
    self._send_message(msg)
  File "/home/zeus/miniconda3/envs/cloudspace/lib/python3.10/site-packages/wandb/sdk/lib/sock_client.py", line 147, in _send_message
    self._sendall_with_error_handle(header + data)
  File "/home/zeus/miniconda3/envs/cloudspace/lib/python3.10/site-packages/wandb/sdk/lib/sock_client.py", line 126, in _sendall_with_error_handle
    sent = self._sock.send(data)
BrokenPipeError: [Errno 32] Broken pipe
2025-07-20 15:08:37,454 ERROR   MainThread:138854 [redirect.py:_on_write():664] [all runs] error in stderr callback
Traceback (most recent call last):
  File "/home/zeus/miniconda3/envs/cloudspace/lib/python3.10/site-packages/wandb/sdk/lib/redirect.py", line 662, in _on_write
    cb(written_data)
  File "/home/zeus/miniconda3/envs/cloudspace/lib/python3.10/site-packages/wandb/sdk/wandb_run.py", line 2385, in <lambda>
    lambda data: self._console_raw_callback("stderr", data),
  File "/home/zeus/miniconda3/envs/cloudspace/lib/python3.10/site-packages/wandb/sdk/wandb_run.py", line 398, in wrapper
    return func(self, *args, **kwargs)
  File "/home/zeus/miniconda3/envs/cloudspace/lib/python3.10/site-packages/wandb/sdk/wandb_run.py", line 456, in wrapper_fn
    return func(self, *args, **kwargs)
  File "/home/zeus/miniconda3/envs/cloudspace/lib/python3.10/site-packages/wandb/sdk/wandb_run.py", line 1566, in _console_raw_callback
    self._backend.interface.publish_output_raw(name, data)
  File "/home/zeus/miniconda3/envs/cloudspace/lib/python3.10/site-packages/wandb/sdk/interface/interface.py", line 771, in publish_output_raw
    self._publish_output_raw(o)
  File "/home/zeus/miniconda3/envs/cloudspace/lib/python3.10/site-packages/wandb/sdk/interface/interface_shared.py", line 38, in _publish_output_raw
    self._publish(rec)
  File "/home/zeus/miniconda3/envs/cloudspace/lib/python3.10/site-packages/wandb/sdk/interface/interface_sock.py", line 39, in _publish
    self._sock_client.send_record_publish(record)
  File "/home/zeus/miniconda3/envs/cloudspace/lib/python3.10/site-packages/wandb/sdk/lib/sock_client.py", line 170, in send_record_publish
    self.send_server_request(server_req)
  File "/home/zeus/miniconda3/envs/cloudspace/lib/python3.10/site-packages/wandb/sdk/lib/sock_client.py", line 150, in send_server_request
    self._send_message(msg)
  File "/home/zeus/miniconda3/envs/cloudspace/lib/python3.10/site-packages/wandb/sdk/lib/sock_client.py", line 147, in _send_message
    self._sendall_with_error_handle(header + data)
  File "/home/zeus/miniconda3/envs/cloudspace/lib/python3.10/site-packages/wandb/sdk/lib/sock_client.py", line 126, in _sendall_with_error_handle
    sent = self._sock.send(data)
BrokenPipeError: [Errno 32] Broken pipe
2025-07-20 15:08:37,454 ERROR   MainThread:138854 [redirect.py:_on_write():664] [all runs] error in stderr callback
Traceback (most recent call last):
  File "/home/zeus/miniconda3/envs/cloudspace/lib/python3.10/site-packages/wandb/sdk/lib/redirect.py", line 662, in _on_write
    cb(written_data)
  File "/home/zeus/miniconda3/envs/cloudspace/lib/python3.10/site-packages/wandb/sdk/wandb_run.py", line 2385, in <lambda>
    lambda data: self._console_raw_callback("stderr", data),
  File "/home/zeus/miniconda3/envs/cloudspace/lib/python3.10/site-packages/wandb/sdk/wandb_run.py", line 398, in wrapper
    return func(self, *args, **kwargs)
  File "/home/zeus/miniconda3/envs/cloudspace/lib/python3.10/site-packages/wandb/sdk/wandb_run.py", line 456, in wrapper_fn
    return func(self, *args, **kwargs)
  File "/home/zeus/miniconda3/envs/cloudspace/lib/python3.10/site-packages/wandb/sdk/wandb_run.py", line 1566, in _console_raw_callback
    self._backend.interface.publish_output_raw(name, data)
  File "/home/zeus/miniconda3/envs/cloudspace/lib/python3.10/site-packages/wandb/sdk/interface/interface.py", line 771, in publish_output_raw
    self._publish_output_raw(o)
  File "/home/zeus/miniconda3/envs/cloudspace/lib/python3.10/site-packages/wandb/sdk/interface/interface_shared.py", line 38, in _publish_output_raw
    self._publish(rec)
  File "/home/zeus/miniconda3/envs/cloudspace/lib/python3.10/site-packages/wandb/sdk/interface/interface_sock.py", line 39, in _publish
    self._sock_client.send_record_publish(record)
  File "/home/zeus/miniconda3/envs/cloudspace/lib/python3.10/site-packages/wandb/sdk/lib/sock_client.py", line 170, in send_record_publish
    self.send_server_request(server_req)
  File "/home/zeus/miniconda3/envs/cloudspace/lib/python3.10/site-packages/wandb/sdk/lib/sock_client.py", line 150, in send_server_request
    self._send_message(msg)
  File "/home/zeus/miniconda3/envs/cloudspace/lib/python3.10/site-packages/wandb/sdk/lib/sock_client.py", line 147, in _send_message
    self._sendall_with_error_handle(header + data)
  File "/home/zeus/miniconda3/envs/cloudspace/lib/python3.10/site-packages/wandb/sdk/lib/sock_client.py", line 126, in _sendall_with_error_handle
    sent = self._sock.send(data)
BrokenPipeError: [Errno 32] Broken pipe
2025-07-20 15:08:37,455 ERROR   MainThread:138854 [redirect.py:_on_write():664] [all runs] error in stderr callback
Traceback (most recent call last):
  File "/home/zeus/miniconda3/envs/cloudspace/lib/python3.10/site-packages/wandb/sdk/lib/redirect.py", line 662, in _on_write
    cb(written_data)
  File "/home/zeus/miniconda3/envs/cloudspace/lib/python3.10/site-packages/wandb/sdk/wandb_run.py", line 2385, in <lambda>
    lambda data: self._console_raw_callback("stderr", data),
  File "/home/zeus/miniconda3/envs/cloudspace/lib/python3.10/site-packages/wandb/sdk/wandb_run.py", line 398, in wrapper
    return func(self, *args, **kwargs)
  File "/home/zeus/miniconda3/envs/cloudspace/lib/python3.10/site-packages/wandb/sdk/wandb_run.py", line 456, in wrapper_fn
    return func(self, *args, **kwargs)
  File "/home/zeus/miniconda3/envs/cloudspace/lib/python3.10/site-packages/wandb/sdk/wandb_run.py", line 1566, in _console_raw_callback
    self._backend.interface.publish_output_raw(name, data)
  File "/home/zeus/miniconda3/envs/cloudspace/lib/python3.10/site-packages/wandb/sdk/interface/interface.py", line 771, in publish_output_raw
    self._publish_output_raw(o)
  File "/home/zeus/miniconda3/envs/cloudspace/lib/python3.10/site-packages/wandb/sdk/interface/interface_shared.py", line 38, in _publish_output_raw
    self._publish(rec)
  File "/home/zeus/miniconda3/envs/cloudspace/lib/python3.10/site-packages/wandb/sdk/interface/interface_sock.py", line 39, in _publish
    self._sock_client.send_record_publish(record)
  File "/home/zeus/miniconda3/envs/cloudspace/lib/python3.10/site-packages/wandb/sdk/lib/sock_client.py", line 170, in send_record_publish
    self.send_server_request(server_req)
  File "/home/zeus/miniconda3/envs/cloudspace/lib/python3.10/site-packages/wandb/sdk/lib/sock_client.py", line 150, in send_server_request
    self._send_message(msg)
  File "/home/zeus/miniconda3/envs/cloudspace/lib/python3.10/site-packages/wandb/sdk/lib/sock_client.py", line 147, in _send_message
    self._sendall_with_error_handle(header + data)
  File "/home/zeus/miniconda3/envs/cloudspace/lib/python3.10/site-packages/wandb/sdk/lib/sock_client.py", line 126, in _sendall_with_error_handle
    sent = self._sock.send(data)
BrokenPipeError: [Errno 32] Broken pipe
2025-07-20 15:08:37,455 ERROR   MainThread:138854 [redirect.py:_on_write():664] [all runs] error in stderr callback
Traceback (most recent call last):
  File "/home/zeus/miniconda3/envs/cloudspace/lib/python3.10/site-packages/wandb/sdk/lib/redirect.py", line 662, in _on_write
    cb(written_data)
  File "/home/zeus/miniconda3/envs/cloudspace/lib/python3.10/site-packages/wandb/sdk/wandb_run.py", line 2385, in <lambda>
    lambda data: self._console_raw_callback("stderr", data),
  File "/home/zeus/miniconda3/envs/cloudspace/lib/python3.10/site-packages/wandb/sdk/wandb_run.py", line 398, in wrapper
    return func(self, *args, **kwargs)
  File "/home/zeus/miniconda3/envs/cloudspace/lib/python3.10/site-packages/wandb/sdk/wandb_run.py", line 456, in wrapper_fn
    return func(self, *args, **kwargs)
  File "/home/zeus/miniconda3/envs/cloudspace/lib/python3.10/site-packages/wandb/sdk/wandb_run.py", line 1566, in _console_raw_callback
    self._backend.interface.publish_output_raw(name, data)
  File "/home/zeus/miniconda3/envs/cloudspace/lib/python3.10/site-packages/wandb/sdk/interface/interface.py", line 771, in publish_output_raw
    self._publish_output_raw(o)
  File "/home/zeus/miniconda3/envs/cloudspace/lib/python3.10/site-packages/wandb/sdk/interface/interface_shared.py", line 38, in _publish_output_raw
    self._publish(rec)
  File "/home/zeus/miniconda3/envs/cloudspace/lib/python3.10/site-packages/wandb/sdk/interface/interface_sock.py", line 39, in _publish
    self._sock_client.send_record_publish(record)
  File "/home/zeus/miniconda3/envs/cloudspace/lib/python3.10/site-packages/wandb/sdk/lib/sock_client.py", line 170, in send_record_publish
    self.send_server_request(server_req)
  File "/home/zeus/miniconda3/envs/cloudspace/lib/python3.10/site-packages/wandb/sdk/lib/sock_client.py", line 150, in send_server_request
    self._send_message(msg)
  File "/home/zeus/miniconda3/envs/cloudspace/lib/python3.10/site-packages/wandb/sdk/lib/sock_client.py", line 147, in _send_message
    self._sendall_with_error_handle(header + data)
  File "/home/zeus/miniconda3/envs/cloudspace/lib/python3.10/site-packages/wandb/sdk/lib/sock_client.py", line 126, in _sendall_with_error_handle
    sent = self._sock.send(data)
BrokenPipeError: [Errno 32] Broken pipe
2025-07-20 15:08:37,456 ERROR   MainThread:138854 [redirect.py:_on_write():664] [all runs] error in stderr callback
Traceback (most recent call last):
  File "/home/zeus/miniconda3/envs/cloudspace/lib/python3.10/site-packages/wandb/sdk/lib/redirect.py", line 662, in _on_write
    cb(written_data)
  File "/home/zeus/miniconda3/envs/cloudspace/lib/python3.10/site-packages/wandb/sdk/wandb_run.py", line 2385, in <lambda>
    lambda data: self._console_raw_callback("stderr", data),
  File "/home/zeus/miniconda3/envs/cloudspace/lib/python3.10/site-packages/wandb/sdk/wandb_run.py", line 398, in wrapper
    return func(self, *args, **kwargs)
  File "/home/zeus/miniconda3/envs/cloudspace/lib/python3.10/site-packages/wandb/sdk/wandb_run.py", line 456, in wrapper_fn
    return func(self, *args, **kwargs)
  File "/home/zeus/miniconda3/envs/cloudspace/lib/python3.10/site-packages/wandb/sdk/wandb_run.py", line 1566, in _console_raw_callback
    self._backend.interface.publish_output_raw(name, data)
  File "/home/zeus/miniconda3/envs/cloudspace/lib/python3.10/site-packages/wandb/sdk/interface/interface.py", line 771, in publish_output_raw
    self._publish_output_raw(o)
  File "/home/zeus/miniconda3/envs/cloudspace/lib/python3.10/site-packages/wandb/sdk/interface/interface_shared.py", line 38, in _publish_output_raw
    self._publish(rec)
  File "/home/zeus/miniconda3/envs/cloudspace/lib/python3.10/site-packages/wandb/sdk/interface/interface_sock.py", line 39, in _publish
    self._sock_client.send_record_publish(record)
  File "/home/zeus/miniconda3/envs/cloudspace/lib/python3.10/site-packages/wandb/sdk/lib/sock_client.py", line 170, in send_record_publish
    self.send_server_request(server_req)
  File "/home/zeus/miniconda3/envs/cloudspace/lib/python3.10/site-packages/wandb/sdk/lib/sock_client.py", line 150, in send_server_request
    self._send_message(msg)
  File "/home/zeus/miniconda3/envs/cloudspace/lib/python3.10/site-packages/wandb/sdk/lib/sock_client.py", line 147, in _send_message
    self._sendall_with_error_handle(header + data)
  File "/home/zeus/miniconda3/envs/cloudspace/lib/python3.10/site-packages/wandb/sdk/lib/sock_client.py", line 126, in _sendall_with_error_handle
    sent = self._sock.send(data)
BrokenPipeError: [Errno 32] Broken pipe
2025-07-20 15:08:37,456 ERROR   MainThread:138854 [redirect.py:_on_write():664] [all runs] error in stderr callback
Traceback (most recent call last):
  File "/home/zeus/miniconda3/envs/cloudspace/lib/python3.10/site-packages/wandb/sdk/lib/redirect.py", line 662, in _on_write
    cb(written_data)
  File "/home/zeus/miniconda3/envs/cloudspace/lib/python3.10/site-packages/wandb/sdk/wandb_run.py", line 2385, in <lambda>
    lambda data: self._console_raw_callback("stderr", data),
  File "/home/zeus/miniconda3/envs/cloudspace/lib/python3.10/site-packages/wandb/sdk/wandb_run.py", line 398, in wrapper
    return func(self, *args, **kwargs)
  File "/home/zeus/miniconda3/envs/cloudspace/lib/python3.10/site-packages/wandb/sdk/wandb_run.py", line 456, in wrapper_fn
    return func(self, *args, **kwargs)
  File "/home/zeus/miniconda3/envs/cloudspace/lib/python3.10/site-packages/wandb/sdk/wandb_run.py", line 1566, in _console_raw_callback
    self._backend.interface.publish_output_raw(name, data)
  File "/home/zeus/miniconda3/envs/cloudspace/lib/python3.10/site-packages/wandb/sdk/interface/interface.py", line 771, in publish_output_raw
    self._publish_output_raw(o)
  File "/home/zeus/miniconda3/envs/cloudspace/lib/python3.10/site-packages/wandb/sdk/interface/interface_shared.py", line 38, in _publish_output_raw
    self._publish(rec)
  File "/home/zeus/miniconda3/envs/cloudspace/lib/python3.10/site-packages/wandb/sdk/interface/interface_sock.py", line 39, in _publish
    self._sock_client.send_record_publish(record)
  File "/home/zeus/miniconda3/envs/cloudspace/lib/python3.10/site-packages/wandb/sdk/lib/sock_client.py", line 170, in send_record_publish
    self.send_server_request(server_req)
  File "/home/zeus/miniconda3/envs/cloudspace/lib/python3.10/site-packages/wandb/sdk/lib/sock_client.py", line 150, in send_server_request
    self._send_message(msg)
  File "/home/zeus/miniconda3/envs/cloudspace/lib/python3.10/site-packages/wandb/sdk/lib/sock_client.py", line 147, in _send_message
    self._sendall_with_error_handle(header + data)
  File "/home/zeus/miniconda3/envs/cloudspace/lib/python3.10/site-packages/wandb/sdk/lib/sock_client.py", line 126, in _sendall_with_error_handle
    sent = self._sock.send(data)
BrokenPipeError: [Errno 32] Broken pipe
2025-07-20 15:08:37,457 ERROR   MainThread:138854 [redirect.py:_on_write():664] [all runs] error in stderr callback
Traceback (most recent call last):
  File "/home/zeus/miniconda3/envs/cloudspace/lib/python3.10/site-packages/wandb/sdk/lib/redirect.py", line 662, in _on_write
    cb(written_data)
  File "/home/zeus/miniconda3/envs/cloudspace/lib/python3.10/site-packages/wandb/sdk/wandb_run.py", line 2385, in <lambda>
    lambda data: self._console_raw_callback("stderr", data),
  File "/home/zeus/miniconda3/envs/cloudspace/lib/python3.10/site-packages/wandb/sdk/wandb_run.py", line 398, in wrapper
    return func(self, *args, **kwargs)
  File "/home/zeus/miniconda3/envs/cloudspace/lib/python3.10/site-packages/wandb/sdk/wandb_run.py", line 456, in wrapper_fn
    return func(self, *args, **kwargs)
  File "/home/zeus/miniconda3/envs/cloudspace/lib/python3.10/site-packages/wandb/sdk/wandb_run.py", line 1566, in _console_raw_callback
    self._backend.interface.publish_output_raw(name, data)
  File "/home/zeus/miniconda3/envs/cloudspace/lib/python3.10/site-packages/wandb/sdk/interface/interface.py", line 771, in publish_output_raw
    self._publish_output_raw(o)
  File "/home/zeus/miniconda3/envs/cloudspace/lib/python3.10/site-packages/wandb/sdk/interface/interface_shared.py", line 38, in _publish_output_raw
    self._publish(rec)
  File "/home/zeus/miniconda3/envs/cloudspace/lib/python3.10/site-packages/wandb/sdk/interface/interface_sock.py", line 39, in _publish
    self._sock_client.send_record_publish(record)
  File "/home/zeus/miniconda3/envs/cloudspace/lib/python3.10/site-packages/wandb/sdk/lib/sock_client.py", line 170, in send_record_publish
    self.send_server_request(server_req)
  File "/home/zeus/miniconda3/envs/cloudspace/lib/python3.10/site-packages/wandb/sdk/lib/sock_client.py", line 150, in send_server_request
    self._send_message(msg)
  File "/home/zeus/miniconda3/envs/cloudspace/lib/python3.10/site-packages/wandb/sdk/lib/sock_client.py", line 147, in _send_message
    self._sendall_with_error_handle(header + data)
  File "/home/zeus/miniconda3/envs/cloudspace/lib/python3.10/site-packages/wandb/sdk/lib/sock_client.py", line 126, in _sendall_with_error_handle
    sent = self._sock.send(data)
BrokenPipeError: [Errno 32] Broken pipe
2025-07-20 15:08:37,457 ERROR   MainThread:138854 [redirect.py:_on_write():664] [all runs] error in stderr callback
Traceback (most recent call last):
  File "/home/zeus/miniconda3/envs/cloudspace/lib/python3.10/site-packages/wandb/sdk/lib/redirect.py", line 662, in _on_write
    cb(written_data)
  File "/home/zeus/miniconda3/envs/cloudspace/lib/python3.10/site-packages/wandb/sdk/wandb_run.py", line 2385, in <lambda>
    lambda data: self._console_raw_callback("stderr", data),
  File "/home/zeus/miniconda3/envs/cloudspace/lib/python3.10/site-packages/wandb/sdk/wandb_run.py", line 398, in wrapper
    return func(self, *args, **kwargs)
  File "/home/zeus/miniconda3/envs/cloudspace/lib/python3.10/site-packages/wandb/sdk/wandb_run.py", line 456, in wrapper_fn
    return func(self, *args, **kwargs)
  File "/home/zeus/miniconda3/envs/cloudspace/lib/python3.10/site-packages/wandb/sdk/wandb_run.py", line 1566, in _console_raw_callback
    self._backend.interface.publish_output_raw(name, data)
  File "/home/zeus/miniconda3/envs/cloudspace/lib/python3.10/site-packages/wandb/sdk/interface/interface.py", line 771, in publish_output_raw
    self._publish_output_raw(o)
  File "/home/zeus/miniconda3/envs/cloudspace/lib/python3.10/site-packages/wandb/sdk/interface/interface_shared.py", line 38, in _publish_output_raw
    self._publish(rec)
  File "/home/zeus/miniconda3/envs/cloudspace/lib/python3.10/site-packages/wandb/sdk/interface/interface_sock.py", line 39, in _publish
    self._sock_client.send_record_publish(record)
  File "/home/zeus/miniconda3/envs/cloudspace/lib/python3.10/site-packages/wandb/sdk/lib/sock_client.py", line 170, in send_record_publish
    self.send_server_request(server_req)
  File "/home/zeus/miniconda3/envs/cloudspace/lib/python3.10/site-packages/wandb/sdk/lib/sock_client.py", line 150, in send_server_request
    self._send_message(msg)
  File "/home/zeus/miniconda3/envs/cloudspace/lib/python3.10/site-packages/wandb/sdk/lib/sock_client.py", line 147, in _send_message
    self._sendall_with_error_handle(header + data)
  File "/home/zeus/miniconda3/envs/cloudspace/lib/python3.10/site-packages/wandb/sdk/lib/sock_client.py", line 126, in _sendall_with_error_handle
    sent = self._sock.send(data)
BrokenPipeError: [Errno 32] Broken pipe
2025-07-20 15:08:37,457 ERROR   MainThread:138854 [redirect.py:_on_write():664] [all runs] error in stderr callback
Traceback (most recent call last):
  File "/home/zeus/miniconda3/envs/cloudspace/lib/python3.10/site-packages/wandb/sdk/lib/redirect.py", line 662, in _on_write
    cb(written_data)
  File "/home/zeus/miniconda3/envs/cloudspace/lib/python3.10/site-packages/wandb/sdk/wandb_run.py", line 2385, in <lambda>
    lambda data: self._console_raw_callback("stderr", data),
  File "/home/zeus/miniconda3/envs/cloudspace/lib/python3.10/site-packages/wandb/sdk/wandb_run.py", line 398, in wrapper
    return func(self, *args, **kwargs)
  File "/home/zeus/miniconda3/envs/cloudspace/lib/python3.10/site-packages/wandb/sdk/wandb_run.py", line 456, in wrapper_fn
    return func(self, *args, **kwargs)
  File "/home/zeus/miniconda3/envs/cloudspace/lib/python3.10/site-packages/wandb/sdk/wandb_run.py", line 1566, in _console_raw_callback
    self._backend.interface.publish_output_raw(name, data)
  File "/home/zeus/miniconda3/envs/cloudspace/lib/python3.10/site-packages/wandb/sdk/interface/interface.py", line 771, in publish_output_raw
    self._publish_output_raw(o)
  File "/home/zeus/miniconda3/envs/cloudspace/lib/python3.10/site-packages/wandb/sdk/interface/interface_shared.py", line 38, in _publish_output_raw
    self._publish(rec)
  File "/home/zeus/miniconda3/envs/cloudspace/lib/python3.10/site-packages/wandb/sdk/interface/interface_sock.py", line 39, in _publish
    self._sock_client.send_record_publish(record)
  File "/home/zeus/miniconda3/envs/cloudspace/lib/python3.10/site-packages/wandb/sdk/lib/sock_client.py", line 170, in send_record_publish
    self.send_server_request(server_req)
  File "/home/zeus/miniconda3/envs/cloudspace/lib/python3.10/site-packages/wandb/sdk/lib/sock_client.py", line 150, in send_server_request
    self._send_message(msg)
  File "/home/zeus/miniconda3/envs/cloudspace/lib/python3.10/site-packages/wandb/sdk/lib/sock_client.py", line 147, in _send_message
    self._sendall_with_error_handle(header + data)
  File "/home/zeus/miniconda3/envs/cloudspace/lib/python3.10/site-packages/wandb/sdk/lib/sock_client.py", line 126, in _sendall_with_error_handle
    sent = self._sock.send(data)
BrokenPipeError: [Errno 32] Broken pipe
