step 0: train loss 10.9361, val loss 10.9071
iter 0: loss 10.9490, time 7890.62ms, mfu -100.00%
iter 10: loss 8.0807, time 1435.07ms, mfu 20.16%
iter 20: loss 7.5191, time 1455.01ms, mfu 20.14%
iter 30: loss 7.6581, time 1465.19ms, mfu 20.10%
step 40: train loss 7.1175, val loss 7.5350
saving checkpoint to out
iter 40: loss 6.1333, time 7301.90ms, mfu 18.48%
Traceback (most recent call last):
  File "/teamspace/studios/this_studio/nanoGPT/train.py", line 440, in <module>
    scaler.scale(loss).backward()
  File "/home/zeus/miniconda3/envs/cloudspace/lib/python3.10/site-packages/torch/_tensor.py", line 648, in backward
    torch.autograd.backward(
  File "/home/zeus/miniconda3/envs/cloudspace/lib/python3.10/site-packages/torch/autograd/__init__.py", line 353, in backward
    _engine_run_backward(
  File "/home/zeus/miniconda3/envs/cloudspace/lib/python3.10/site-packages/torch/autograd/graph.py", line 824, in _engine_run_backward
    return Variable._execution_engine.run_backward(  # Calls into the C++ engine to run the backward pass
KeyboardInterrupt
Traceback (most recent call last):
  File "/teamspace/studios/this_studio/nanoGPT/train.py", line 440, in <module>
    scaler.scale(loss).backward()
  File "/home/zeus/miniconda3/envs/cloudspace/lib/python3.10/site-packages/torch/_tensor.py", line 648, in backward
    torch.autograd.backward(
  File "/home/zeus/miniconda3/envs/cloudspace/lib/python3.10/site-packages/torch/autograd/__init__.py", line 353, in backward
    _engine_run_backward(
  File "/home/zeus/miniconda3/envs/cloudspace/lib/python3.10/site-packages/torch/autograd/graph.py", line 824, in _engine_run_backward
    return Variable._execution_engine.run_backward(  # Calls into the C++ engine to run the backward pass
KeyboardInterrupt
Exception ignored in atexit callback: <function _start_and_connect_service.<locals>.teardown_atexit at 0x712cdcb97400>
Traceback (most recent call last):
  File "/home/zeus/miniconda3/envs/cloudspace/lib/python3.10/site-packages/wandb/sdk/lib/service/service_connection.py", line 54, in teardown_atexit
    conn.teardown(hooks.exit_code)
  File "/home/zeus/miniconda3/envs/cloudspace/lib/python3.10/site-packages/wandb/sdk/lib/service/service_connection.py", line 182, in teardown
    self._router.join()
  File "/home/zeus/miniconda3/envs/cloudspace/lib/python3.10/site-packages/wandb/sdk/interface/router.py", line 75, in join
    self._thread.join()
  File "/home/zeus/miniconda3/envs/cloudspace/lib/python3.10/threading.py", line 1096, in join
    self._wait_for_tstate_lock()
  File "/home/zeus/miniconda3/envs/cloudspace/lib/python3.10/threading.py", line 1116, in _wait_for_tstate_lock
    if lock.acquire(block, timeout):
KeyboardInterrupt:
Exception ignored in atexit callback: <function shutdown_compile_workers at 0x712ce6c4b2e0>
Traceback (most recent call last):
  File "/home/zeus/miniconda3/envs/cloudspace/lib/python3.10/site-packages/torch/_inductor/async_compile.py", line 113, in shutdown_compile_workers
    pool.shutdown()
  File "/home/zeus/miniconda3/envs/cloudspace/lib/python3.10/site-packages/torch/_inductor/compile_worker/subproc_pool.py", line 239, in shutdown
    self.process.wait(300)
  File "/home/zeus/miniconda3/envs/cloudspace/lib/python3.10/subprocess.py", line 1209, in wait
    return self._wait(timeout=timeout)
  File "/home/zeus/miniconda3/envs/cloudspace/lib/python3.10/subprocess.py", line 1937, in _wait
    time.sleep(delay)
KeyboardInterrupt:
